File: data/materialdata/DragonSkinFXProSlacker.csv
PARAMETER;INFO;URL;;
Specimen Thickness (mm);3;;;
Specimen Width (mm);6;;;
Specimen Length (mm);33;;;
Specimen Cross-section (cm^2);0.18;;;
Standard;ASTM D412;;;
Type of test;Pull-to-failure;;;
Speed (mm/min);450;;;
Machine;Instron  5569;;;
Load Cell;1 kN - Instron  2525-806;;;
Grippers;Instron 2710-010 ;;;
Strain Measurement;Global;;;
Strain calculation;Derived from the machine crosshead displacement readings;;;
Lab;Univ. Savoie Mont Blanc - SYMME Lab. 7400 Annecy. France;;;
Material supplier;Smooth-On;https://www.smooth-on.com/products/slacker/;;
Material;Dragon Skin FX Pro & Slacker;;;
;;;;
Time (s);True Strain;True Stress (MPa);Engineering Strain;Engineering Stress (MPa)
0.5;0.08695;0.00106015;0.0908421362478899;0.000971863814911422
0.6;0.10762;0.00120528;0.113624487667281;0.0010823037867322
0.7;0.12783;0.00120936;0.136359805108862;0.00106424038809094
0.8;0.14763;0.00150707;0.15908395595019;0.00130022505467651
0.9;0.16705;0.00156192;0.181813354498845;0.00132163001378703
1;0.1861;0.0021887;0.204542708625979;0.00181703810444102
1.1;0.20479;0.00152047;0.227267311764568;0.00123890694832723
1.2;0.22315;0.0028003;0.250008060883229;0.00224022555344273
1.3;0.24116;0.00193633;0.272724654963016;0.00152140527210598
1.4;0.25886;0.00290363;0.295452428791991;0.0022414022587519
1.5;0.27625;0.00212113;0.318177367179488;0.0016091385369016
1.6;0.29335;0.00314747;0.340912027520033;0.00234726062217603
1.7;0.31015;0.00306377;0.363629643238597;0.00224677573943289
1.8;0.32668;0.00339742;0.386357771704267;0.00245060839946352
1.9;0.34295;0.00366213;0.409098305249786;0.00259891732631871
2;0.35895;0.00360056;0.431825208521421;0.00251466448458337
2.1;0.37469;0.00395029;0.454540437184783;0.00271583374309322
2.2;0.39019;0.0040446;0.477261446894672;0.00273790398341613
2.3;0.40546;0.00462581;0.499992337857323;0.00308388908613212
2.4;0.4205;0.00440872;0.522722726673349;0.0028952874497589
2.5;0.43532;0.0048021;0.54545752624075;0.00310723518340933
2.6;0.44992;0.00480354;0.568186725533795;0.00306311737102922
2.7;0.46431;0.00477515;0.590916077988597;0.00300150967487691
2.8;0.47849;0.0055396;0.61363597132421;0.00343299238393527
2.9;0.49247;0.00572436;0.636353024419838;0.00349824268637237
3;0.50627;0.00590922;0.659091228913679;0.00356172095724306
3.1;0.51988;0.00634226;0.681825818491037;0.00377105639018575
3.2;0.5333;0.00590636;0.704548046107568;0.00346505926511576
3.3;0.54654;0.00638582;0.727266325376107;0.00369706738687765
3.4;0.55961;0.00692955;0.749989871142323;0.00395976577594513
3.5;0.57252;0.00645392;0.772728703724128;0.00364066988165853
3.6;0.58526;0.00750729;0.79545774397212;0.00418126799430629
3.7;0.59784;0.00739982;0.818187271361595;0.00406988879339061
3.8;0.61026;0.00751556;0.840909973157294;0.00408252446321982
3.9;0.62253;0.00781593;0.863637084218972;0.00419391203694337
4;0.63465;0.0080562;0.88636179927585;0.00427076078570541
4.1;0.64663;0.00829554;0.90909632151439;0.00434527053795775
4.2;0.65846;0.00854792;0.931815047306527;0.00442481282663064
4.3;0.67016;0.00923384;0.954550023622813;0.00472427918876429
4.4;0.68172;0.00921021;0.977275723364541;0.00465803018323002
4.5;0.69315;0.00992737;1.00000563888806;0.00496367100520742
4.6;0.70445;0.00974251;1.02273387529634;0.00481650607575486
4.7;0.71562;0.0101957;1.04545447097545;0.00498456462594243
4.8;0.72667;0.0103153;1.06818208167112;0.0049876169469881
4.9;0.7376;0.0106444;1.09091130072772;0.00509079461969301
5;0.74841;0.0113534;1.11363666116242;0.00537150031914949
5.1;0.75911;0.0110813;1.13637400127369;0.00518696632396453
5.2;0.76969;0.0111462;1.15909683001229;0.00516243636925564
5.3;0.78016;0.0116448;1.18182132898502;0.00533719230135915
5.4;0.79052;0.0119399;1.20454249034843;0.00541604439572988
5.5;0.80078;0.0120655;1.2272775276023;0.00541715158999009
5.6;0.81093;0.0128944;1.24999951351331;0.00573084568354672
5.7;0.82098;0.0127595;1.27272601802346;0.00561418309942025
5.8;0.83093;0.0128659;1.29545251874583;0.00560495148339185
5.9;0.84078;0.0135363;1.31817444784506;0.00583920680024023
6;0.85054;0.0145036;1.34091060240795;0.00619570862085935
6.1;0.8602;0.0137928;1.3636333731109;0.00583542276772247
6.2;0.86977;0.0142835;1.38636192715692;0.00598547095369443
6.3;0.87925;0.0153057;1.40909220953345;0.0063533060044074
6.4;0.88864;0.0152136;1.43182012595146;0.00625605481163934
6.5;0.89794;0.0157227;1.45454154395213;0.00640555464980415
6.6;0.90716;0.016082;1.47727706668821;0.00649180514212709
6.7;0.91629;0.0163528;1.49999817031528;0.00654112478727842
6.8;0.92534;0.0171048;1.52272584134718;0.00678028492817347
6.9;0.93431;0.0174782;1.54545648667789;0.00686643047778476
7;0.9432;0.0174141;1.56818647996489;0.00678069919604828
7.1;0.95201;0.0181676;1.59091216249521;0.0070120478273966
7.2;0.96074;0.0180552;1.61362984407236;0.00690809375357748
7.3;0.9694;0.0184213;1.63636216741359;0.00698739354846389
7.4;0.97798;0.0192653;1.65907947268594;0.00724510124571046
7.5;0.98649;0.0200375;1.68180479811081;0.0074716474570093
7.6;0.99493;0.0199822;1.70453501720198;0.00738840498381599
7.7;1.0033;0.0197256;1.72726697583211;0.00723273525283736
7.8;1.0116;0.0203665;1.74999749288532;0.0074060067518939
7.9;1.01983;0.0209664;1.77272336092482;0.0075616631271166
8;1.02799;0.020932;1.79544134687522;0.0074879052724172
8.1;1.03609;0.0221932;1.81817637434253;0.00787502166367342
8.2;1.04412;0.0211994;1.84089743359199;0.00746221942028925
8.3;1.05209;0.0229023;1.86362985450319;0.00799764675032463
8.4;1.06;0.0231974;1.88637098926796;0.00803687401455047
8.5;1.06784;0.0230801;1.90908907636027;0.00793378937329649
8.6;1.07562;0.0237333;1.93181005939307;0.00809510149675698
8.7;1.08335;0.0247859;1.95456076936124;0.00838903036181536
8.8;1.09101;0.0244388;1.97727960691571;0.00820843294100859
8.9;1.09861;0.0250542;1.99999313400353;0.00835141911360472
9;1.10616;0.0253471;2.02272880131028;0.00838550252639688
9.1;1.11365;0.0267018;2.0454540398097;0.00876775667961435
9.2;1.12108;0.0266822;2.06816603389918;0.00869646547976771
9.3;1.12847;0.0275111;2.09092376714349;0.00890060773819235
9.4;1.13579;0.0275362;2.11363234110143;0.00884375449101971
9.5;1.14306;0.0272991;2.13635093023087;0.00870409613186701
9.6;1.15028;0.0281812;2.1590773275172;0.00892070597782687
9.7;1.15745;0.0285107;2.18180930872269;0.00896053070240258
9.8;1.16457;0.0290004;2.20454463270813;0.00904977253366948
9.9;1.17164;0.0302974;2.22728104176103;0.00938790257431922
10;1.17866;0.031234;2.25001626193033;0.00961041345111568
10.1;1.18562;0.0316819;2.2727152760512;0.00968061604131563
10.2;1.19254;0.0314545;2.29544100609974;0.00954485300807356
10.3;1.19942;0.032557;2.31819181325708;0.00981166907528551
10.4;1.20624;0.0324491;2.34089922568525;0.00971268446247264
10.5;1.21302;0.0342249;2.36362748416658;0.0101749971306588
10.6;1.21976;0.033816;2.38637490610847;0.00998589965304829
10.7;1.22645;0.0346347;2.40910570397076;0.0101594679096219
10.8;1.23309;0.0351176;2.4318174855138;0.0102329451225878
10.9;1.23969;0.0361862;2.45454239061367;0.010474961922112
11;1.24625;0.0365476;2.47727868219717;0.0105104029156808
11.1;1.25276;0.0377486;2.49998961028163;0.0107853463019173
11.2;1.25924;0.0379362;2.52274318491883;0.0107689371630632
11.3;1.26567;0.0378328;2.54546740366697;0.0106707510442405
11.4;1.27206;0.0389003;2.56819547924167;0.0109019531654884
11.5;1.2784;0.0386373;2.5908897032529;0.0107598125236204
11.6;1.28471;0.0397509;2.61361985549195;0.011000299309178
11.7;1.29098;0.0397972;2.63634843161155;0.0109442757613749
11.8;1.29722;0.0416242;2.65911018864946;0.0113754978270723
11.9;1.30341;0.0424307;2.68183032699985;0.0115243496390489
12;1.30956;0.0421523;2.70454335448183;0.0113785414196876
12.1;1.31568;0.0421821;2.72728467727884;0.0113171124967025
12.2;1.32175;0.0438102;2.74997810013025;0.0116827882270775
12.3;1.3278;0.0451141;2.77273423553472;0.0119579321477453
12.4;1.3338;0.0456376;2.79543868618658;0.0120243280878432
12.5;1.33977;0.0453898;2.81816522636606;0.0118878564202943
12.6;1.34571;0.0459448;2.84091262068768;0.0119619487703352
12.7;1.35161;0.0471957;2.86364098790186;0.0122153430268969
12.8;1.35747;0.0485362;2.88634839180417;0.0124888957722774
12.9;1.3633;0.0489312;2.90907197781918;0.0125173443409702
13;1.3691;0.0502711;2.93181047318354;0.0127857383622299
13.1;1.37487;0.0497628;2.95456259636555;0.012583642005246
13.2;1.3806;0.0506685;2.97728728409666;0.0127394619449794
13.3;1.38629;0.0517202;2.99998255555848;0.0129301063896212
13.4;1.39196;0.0518582;3.02272687586285;0.0128913052266012
13.5;1.39759;0.0527609;3.04543870197328;0.0130420713022457
13.6;1.4032;0.0541853;3.06819739152693;0.0133192406329287
13.7;1.40877;0.0556511;3.09092047603969;0.0136035643630683
13.8;1.41431;0.0561409;3.113647070016;0.0136474760825269
13.9;1.41982;0.055749;3.13637582558948;0.0134777405029571
14;1.4253;0.0558157;3.15910538723115;0.0134201215894552
14.1;1.43075;0.0578649;3.18183439187021;0.0138372050582619
14.2;1.43617;0.0577693;3.20456146901659;0.0137396730730902
14.3;1.44156;0.0602147;3.22728524088537;0.0142442954683107
14.4;1.44692;0.0600099;3.25000432252282;0.0141199621096804
14.5;1.45225;0.0605497;3.27271732193438;0.0141712393865053
14.6;1.45756;0.0617969;3.29546579465743;0.0143865422178105
14.7;1.46283;0.0634293;3.31816265308747;0.0146889557193146
14.8;1.46808;0.0636494;3.34089262097401;0.0146627446374655
14.9;1.47331;0.0650345;3.36365496101627;0.0149036760653628
15;1.4785;0.0652202;3.38636120199116;0.0148688621380277
15.1;1.48367;0.0667803;3.40909741186518;0.0151460250844741
15.2;1.48881;0.0671335;3.4318185157757;0.0151480706533962
15.3;1.49392;0.0679281;3.45452306911983;0.0152492419381323
15.4;1.49901;0.0693608;3.47725439368558;0.0154918157203267
15.5;1.50408;0.0704251;3.50001171452201;0.0156499814817661
15.6;1.50912;0.0718126;3.52274902345139;0.0158780864530923
15.7;1.51413;0.0738164;3.54546485169452;0.0162395711788381
15.8;1.51912;0.0736597;3.56820340681684;0.0161244352407956
15.9;1.52408;0.0740316;3.59091798129146;0.0161256638218517
16;1.52902;0.0750689;3.61365322593818;0.0162710321568945
16.1;1.53393;0.0770603;3.63636196761633;0.0166208550018839
16.2;1.53882;0.0777424;3.65908930067914;0.0166861794189409
16.3;1.54369;0.0783907;3.68183440494875;0.0167435866414114
16.4;1.54853;0.0794342;3.70454940943686;0.0168845500571559
16.5;1.55335;0.0805033;3.7272800744858;0.0170295177631836
16.6;1.55814;0.0795533;3.74997806432954;0.0167481405014086
16.7;1.56292;0.0828383;3.77273731074161;0.0173565596861077
16.8;1.56767;0.0834903;3.79546174076229;0.0174102734029379
16.9;1.5724;0.085115;3.8181980036682;0.0176653180162376
17;1.5771;0.0857652;3.84089683475374;0.0177167997847578
17.1;1.58179;0.0868786;3.86365396466439;0.0178628250757957
17.2;1.58645;0.0879132;3.88637148284672;0.0179915097140308
17.3;1.59109;0.0890617;3.90909692878925;0.0181421759015798
17.4;1.59571;0.0899199;3.93182942823971;0.0182325648744293
17.5;1.60031;0.0905353;3.95456810246448;0.0182730962876393
17.6;1.60488;0.0933098;3.97726229542651;0.0187472137214348
17.7;1.60944;0.0934601;4.00001043784039;0.0186919809792172
17.8;1.61397;0.0949437;4.02271186503528;0.0189028760859116
17.9;1.61849;0.096084;4.04546590806298;0.0190436327884907
18;1.62298;0.0980806;4.06817098474262;0.019352267375206
18.1;1.62746;0.0992766;4.09092732689997;0.0195006908614531
18.2;1.63191;0.100987;4.11363243490183;0.0197485840614469
18.3;1.63635;0.100923;4.13638744164586;0.0196486345990405
18.4;1.64076;0.102267;4.15908893025417;0.0198226860173472
18.5;1.64516;0.102851;4.18183893485408;0.0198483591043719
18.6;1.64953;0.104222;4.20453312168191;0.0200252352253874
18.7;1.65389;0.106729;4.22727442611085;0.0204177151034727
18.8;1.65823;0.107509;4.25001009784117;0.020477865374813
18.9;1.66255;0.109029;4.27273920097833;0.0206778670145055
19;1.66685;0.110005;4.29546079596157;0.0207734518748382
19.1;1.67113;0.111296;4.31817393962336;0.0209274839942302
19.2;1.6754;0.112962;4.34093109429337;0.0211502447804834
19.3;1.67964;0.114193;4.36362471861868;0.0212902665623871
19.4;1.68387;0.11614;4.38636090430983;0.0215618674766245
19.5;1.68808;0.117715;4.40908528497418;0.0217624596023655
19.6;1.69227;0.11855;4.43179689992427;0.021825190113727
19.7;1.69645;0.120436;4.45454933041739;0.0220799176438622
19.8;1.70061;0.12098;4.47728751827118;0.0220875752087934
19.9;1.70475;0.124054;4.50001049269867;0.0225552296972312
20;1.70887;0.124968;4.5227172797905;0.0226279915608392
20.1;1.71298;0.126358;4.54546235692628;0.0227858367557358
20.2;1.71707;0.126183;4.56818974379009;0.0226614044790275
20.3;1.72114;0.128973;4.59089845693127;0.0230683853397671
20.4;1.7252;0.12968;4.613643646157;0.0231008607197175
20.5;1.72924;0.132777;4.63636864006616;0.0235571887644385
20.6;1.73326;0.133818;4.65907244607409;0.0236466313649747
20.7;1.73727;0.133739;4.68181088668659;0.0235380942215751
20.8;1.74126;0.13681;4.70452659983584;0.023982708749914
20.9;1.74524;0.137396;4.72727585669456;0.0239897646696027
21;1.7492;0.139115;4.75000083484682;0.0241939095307464
21.1;1.75314;0.139654;4.77270052716491;0.0241921435804304
21.2;1.75707;0.142978;4.79543187808428;0.0246708102187653
21.3;1.76099;0.143929;4.81819455674819;0.0247377427131695
21.4;1.76489;0.145163;4.84092982046682;0.0248527211354849
21.5;1.76877;0.147602;4.86363665093487;0.0251724328751624
21.6;1.77264;0.149543;4.88637289102203;0.0254049484748214
21.7;1.77649;0.150557;4.90907910807339;0.0254789278069232
21.8;1.78033;0.15449;4.93181359412548;0.0260443113305175
21.9;1.78415;0.156012;4.95451645691554;0.0262006161421905
22;1.78796;0.156689;4.97724643773396;0.0262142445743633
22.1;1.79176;0.157296;5.00000318463252;0.0262159860852864
22.2;1.79554;0.158459;5.02272611595444;0.0263101786382475
22.3;1.79931;0.161282;5.04547464744991;0.026678136855314
22.4;1.80306;0.162919;5.06818773780537;0.0268480487155992
22.5;1.8068;0.165779;5.09092525259381;0.0272173755423124
22.6;1.81052;0.166657;5.11362569117108;0.0272599286280604
22.7;1.81423;0.167495;5.13634936884316;0.0272955449457364
22.8;1.81793;0.169384;5.15909591667135;0.0275014388948732
22.9;1.82161;0.171708;5.18180314531955;0.0277763616801686
23;1.82528;0.172749;5.20453204488248;0.0278423898450946
23.1;1.82894;0.173938;5.22728223962709;0.027931606968631
23.2;1.83258;0.176219;5.24999085157976;0.0281950812704724
23.3;1.83621;0.178253;5.27271954599355;0.0284171799317653
23.4;1.83983;0.1805;5.29546794050211;0.0286714191392743
23.5;1.84343;0.181453;5.31817246871781;0.0287192223539956
23.6;1.84702;0.184471;5.3408954712654;0.0290922632041412
23.7;1.8506;0.186236;5.3636365593119;0.0292656562429671
23.8;1.85417;0.188335;5.38639534208436;0.0294900315298257
23.9;1.85772;0.188165;5.40910733548472;0.0293590027675467
24;1.86126;0.192311;5.43183578106571;0.029899861648541
24.1;1.86478;0.192811;5.4545157363185;0.0298722642994089
24.2;1.8683;0.19549;5.47727566568564;0.0301808985891458
24.3;1.8718;0.19929;5.49998585015506;0.0306600667438754
24.4;1.87529;0.201944;5.52271043210196;0.0309601356831846
24.5;1.87877;0.202484;5.5454490065775;0.0309350817333577
24.6;1.88224;0.204346;5.5682011667986;0.0311114100817957
24.7;1.88569;0.205935;5.59090059482241;0.0312453506220039
24.8;1.88913;0.20879;5.61361233466433;0.0315697366937666
24.9;1.89256;0.212077;5.63633597373479;0.0319569414266179
25;1.89598;0.213058;5.65907109766697;0.0319951532090783
25.1;1.89939;0.214907;5.68181729032725;0.0321629566721473
25.2;1.90279;0.21454;5.70457413382589;0.0319990495619407
25.3;1.90617;0.218351;5.727273935452;0.0324575752518883
25.4;1.90954;0.221198;5.74998309205122;0.0327701561594255
25.5;1.9129;0.223239;5.77270118025552;0.0329615900744019
25.6;1.91625;0.227682;5.79542777500148;0.0335051754707157
25.7;1.91959;0.22849;5.81816244954156;0.033511961865233
25.8;1.92292;0.229879;5.84090477545557;0.033603595949001
25.9;1.92624;0.231215;5.86365432266223;0.0336868654991235
26;1.92954;0.234983;5.8863417956686;0.0341230521185865
26.1;1.93284;0.238266;5.90910426100517;0.0344858017767611
26.2;1.93612;0.240947;5.93180332910248;0.0347596416921421
26.3;1.9394;0.242719;5.95457697237959;0.034900613073084
26.4;1.94266;0.243555;5.97728588873143;0.0349068396915411
26.5;1.94591;0.245241;5.99999895661288;0.0350344337934967
26.6;1.94915;0.249074;6.02271573453992;0.0354669061677915
26.7;1.95238;0.251741;6.04543577948207;0.0357310758169321
26.8;1.9556;0.254659;6.06815864687519;0.0360290441574318
26.9;1.95881;0.25709;6.0908838906343;0.0362564109023935
27;1.96201;0.258357;6.11361106316653;0.0363186850821439
27.1;1.9652;0.260735;6.13633971538424;0.0365362371185774
27.2;1.96838;0.264333;6.15906939671818;0.0369228157113792
27.3;1.97155;0.267992;6.18179965513086;0.0373154380334934
27.4;1.97471;0.269937;6.20453003712992;0.0374676763937173
27.5;1.97786;0.272083;6.22726008778175;0.0376467702414609
27.6;1.981;0.273333;6.24998935072509;0.0377011588262075
27.7;1.98413;0.275238;6.27271736818485;0.0378452765405202
27.8;1.98725;0.279974;6.29544368098597;0.0383765555931427
27.9;1.99036;0.282573;6.31816782856748;0.0386125334399872
28;1.99346;0.286533;6.34088934899655;0.0390324641031631
28.1;1.99655;0.2893;6.3636077789828;0.0392878068310102
28.2;1.99964;0.289117;6.38639651748842;0.0391418196024911
28.3;2.00271;0.293718;6.40910759846894;0.0396428309477778
28.4;2.00577;0.296283;6.43181419108902;0.039866847095727
28.5;2.00882;0.297772;6.45451582676775;0.039945183150696
28.6;2.01187;0.301862;6.47728680813373;0.0403705257997643
28.7;2.0149;0.30445;6.49997734596723;0.0405934559473975
28.8;2.01793;0.307157;6.52273674039543;0.0408304863774689
28.9;2.02094;0.309348;6.5454142905753;0.0409981464352985
29;2.02395;0.312012;6.5681602030148;0.0412269285573142
29.1;2.02695;0.315997;6.59089877442704;0.0416284038807844
29.2;2.02994;0.318485;6.61362952730353;0.0418309032318776
29.3;2.03292;0.324294;6.63635198293842;0.0424671362352805
29.4;2.03589;0.324698;6.65906566144407;0.0423939439029147
29.5;2.03886;0.327585;6.68184689985168;0.0426440417611454
29.6;2.04181;0.32955;6.70454180673536;0.0427734715790503
29.7;2.04476;0.333125;6.72730376244274;0.0431101209737733
29.8;2.04769;0.336191;6.7499779639506;0.0433796072148604
29.9;2.05062;0.341392;6.77271869829187;0.0439218262298652
30;2.05354;0.343762;6.79544820582181;0.0440977851335438
30.1;2.05645;0.344365;6.81816599845766;0.044046775173095
30.2;2.05935;0.344909;6.8408715870438;0.0439886046048662
30.3;2.06225;0.352104;6.86364311740621;0.0447761927573514
30.4;2.06514;0.352948;6.8864019166401;0.0447539960213401
30.5;2.06801;0.360556;6.90906840098743;0.0455876699656543
30.6;2.07088;0.362396;6.93180003158499;0.0456889985321003
30.7;2.07374;0.363866;6.95451745009886;0.0457433153277548
30.8;2.0766;0.368412;6.977299933428;0.0461825433510667
30.9;2.07944;0.369698;6.99998766657082;0.0462123212445489
31;2.08228;0.374485;7.02273992445753;0.0466779433866942
31.1;2.08511;0.377908;7.04547643543224;0.0469714880197393
31.2;2.08793;0.380218;7.06819669949577;0.0471255243471893
31.3;2.09074;0.383611;7.09090021572255;0.0474126475141236
31.4;2.09355;0.386473;7.11366761854856;0.0476323431239022
31.5;2.09634;0.390108;7.13633635939315;0.0479463953760506
31.6;2.09913;0.392882;7.15906843433467;0.0481528011637565
31.7;2.10191;0.395186;7.18178220209088;0.0483007235146163
31.8;2.10469;0.399741;7.20455920197339;0.048721813099216
31.9;2.10745;0.402591;7.22723506366533;0.048933936721706
32;2.11021;0.405982;7.24997359718288;0.0492100968830531
32.1;2.11296;0.408568;7.27269224840309;0.0493875497518801
32.2;2.11571;0.41266;7.29547346189784;0.0497452016326012
32.3;2.11844;0.417302;7.31815104526564;0.0501676391459027
32.4;2.12117;0.42358;7.34089062301987;0.0507835456840747
32.5;2.12389;0.424462;7.36360872813096;0.0507510589982915
32.6;2.12661;0.424421;7.38638871060303;0.0506083148117614
32.7;2.12931;0.42876;7.40906255603863;0.0509878475921318
32.8;2.13201;0.432335;7.43179770357752;0.0512743563352528
32.9;2.1347;0.438112;7.45450977343854;0.0518199176227122
33;2.13739;0.443679;7.47728302101462;0.052337405616888
33.1;2.14007;0.447402;7.50003261034425;0.0526353274757472
33.2;2.14274;0.447054;7.52275802233829;0.0524541467478326
33.3;2.1454;0.451893;7.54545873724343;0.0528810698050097
33.4;2.14806;0.457396;7.56821991643207;0.0533828501673736
33.5;2.1507;0.459145;7.59086990183708;0.0534456935381848
33.6;2.15335;0.462245;7.61366589843203;0.0536641431709284
33.7;2.15598;0.469055;7.63634965581075;0.0543117194988056
33.8;2.15861;0.472378;7.65909314999085;0.0545528257772004
33.9;2.16123;0.47405;7.68180971975558;0.0546026710216065
34;2.16385;0.480641;7.70458588496905;0.0552169863508342
34.1;2.16645;0.484876;7.72724725528547;0.0555588704910755
34.2;2.16905;0.486911;7.74996762182658;0.0556471773433095
34.3;2.17165;0.492073;7.77274713818213;0.0560910957821094
34.4;2.17424;0.495916;7.79549800292194;0.0563829358877976
34.5;2.17682;0.499279;7.81821968613711;0.0566190249019202
34.6;2.17939;0.501743;7.84091165742374;0.0567524051186152
34.7;2.18196;0.504603;7.86366202207991;0.0569294044315999
34.8;2.18452;0.510702;7.88638206610461;0.0574701826008555
34.9;2.18707;0.51756;7.90907125679661;0.0580935975346656
35;2.18962;0.517953;7.93181837875584;0.0579896475763481
35.1;2.19216;0.524406;7.95453403410749;0.0585631812892281
35.2;2.1947;0.524435;7.97730746056197;0.0584178499292672
35.3;2.19722;0.528477;7.99995880406831;0.0587199354469388
35.4;2.19975;0.53444;8.02275752806743;0.05923244621586
35.5;2.20226;0.540183;8.04543309539502;0.0597188652332197
35.6;2.20477;0.543144;8.06816564988556;0.05989568573958
35.7;2.20728;0.548162;8.09095533475652;0.0602975132772095
35.8;2.20977;0.549527;8.11362001936212;0.0602973350691071
35.9;2.21226;0.555172;8.1363412093524;0.06076524368767
36;2.21475;0.560133;8.15911904560108;0.0611557724286834
36.1;2.21722;0.564019;8.18177003209609;0.0614281340121128
36.2;2.2197;0.566441;8.20456908091094;0.0615391111762878
36.3;2.22216;0.57286;8.22724019488714;0.0620835686403205
36.4;2.22462;0.575645;8.24996714845825;0.0622321129103628
36.5;2.22708;0.580889;8.27275007915879;0.0626447380810567
36.6;2.22953;0.586332;8.29549616943553;0.0630769987220171
36.7;2.23197;0.591133;8.3182048734413;0.0634385064536244
36.8;2.2344;0.597265;8.34087564511563;0.0639410075341611
36.9;2.23683;0.601743;8.36360157375369;0.0642640543022136
37;2.23926;0.603995;8.3863827935499;0.0643480042615619
37.1;2.24168;0.610195;8.40912534730121;0.0648514051494723
37.2;2.24409;0.613228;8.43182868592263;0.065016872169791
37.3;2.2465;0.61847;8.45458680557477;0.0654148100512787
37.4;2.2489;0.623584;8.47730506491459;0.0657976076246122
37.5;2.25129;0.627829;8.49998291325366;0.0660873820229824
37.6;2.25368;0.631354;8.52271502647096;0.0662997893190105
37.7;2.25606;0.638585;8.54540607987658;0.0668997206254275
37.8;2.25844;0.641124;8.56815120230592;0.0670060481324218
37.9;2.26082;0.647032;8.59095052259652;0.0674627607008895
38;2.26318;0.651275;8.61361189573225;0.0677450896773895
38.1;2.26554;0.65701;8.63632681286565;0.068180543557615
38.2;2.2679;0.662632;8.65909540050977;0.0686018692770162
38.3;2.27025;0.665523;8.68182096678284;0.0687394450159044
38.4;2.27259;0.669072;8.70450295542203;0.0689444892822853
38.5;2.27493;0.676599;8.72723808206185;0.0695571542807949
38.6;2.27727;0.680296;8.75002647119082;0.0697737592826158
38.7;2.2796;0.687739;8.77277051939525;0.0703729816058914
38.8;2.28192;0.692689;8.79546966783111;0.0707152411767279
38.9;2.28424;0.694917;8.81822153942656;0.0707782969868275
39;2.28655;0.701793;8.84092784687081;0.0713137024191428
39.1;2.28885;0.707547;8.86358803014;0.0717332270810541
39.2;2.29116;0.711098;8.88639925531112;0.0719268948821774
39.3;2.29345;0.720059;8.90906505203789;0.0726666942056166
39.4;2.29574;0.721887;8.93178281291541;0.0726845334415941
39.5;2.29803;0.72473;8.95455265707794;0.0728038742639729
39.6;2.30031;0.730361;8.97727493068471;0.0732024530820339
39.7;2.30258;0.737518;8.99994907018923;0.0737521756184348
39.8;2.30486;0.74065;9.02277496570198;0.0738967005180213
39.9;2.30712;0.746817;9.04545205258051;0.0743437922047674
40;2.30938;0.752401;9.06818044763179;0.0747305835362712
40.1;2.31163;0.756908;9.09085935784529;0.0750092705842274
40.2;2.31388;0.761362;9.11358935305584;0.0752810870029989
40.3;2.31613;0.767823;9.13637054833408;0.0757493026067592
40.4;2.31837;0.771071;9.15910146748725;0.0758995273812062
40.5;2.3206;0.778204;9.18178154264474;0.0764310250362983
40.6;2.32283;0.781165;9.20451225080464;0.076550939506041
40.7;2.32506;0.787144;9.22729370500454;0.0769650332438214
40.8;2.32728;0.789208;9.2500235177867;0.0769957257786287
40.9;2.32949;0.795996;9.27270111928069;0.077486533556983
41;2.3317;0.8033;9.29542889369464;0.0780249184657062
41.1;2.33391;0.807148;9.31820695203331;0.0782256068086465
41.2;2.33611;0.808183;9.34093199571006;0.0781537873312846
41.3;2.3383;0.81163;9.36360345296514;0.078315424136359
41.4;2.34049;0.813914;9.38632461511861;0.0783640055708681
41.5;2.34268;0.819411;9.40909559114348;0.0787206720146937
41.6;2.34486;0.825564;9.43181217160836;0.0791390782750947
41.7;2.34704;0.830729;9.45457832823703;0.0794607849229331
41.8;2.34921;0.841763;9.47728939580561;0.0803416769548224
41.9;2.35138;0.843291;9.50004979990158;0.0803130476588696
42;2.35354;0.848342;9.52275441963112;0.0806197660963505
42.1;2.35569;0.852308;9.5454026797887;0.0808227078548202
42.2;2.35785;0.856224;9.56820536761421;0.0810188646242492
42.3;2.36;0.864276;9.59095145243378;0.0816051328232074
42.4;2.36214;0.871914;9.61364035701105;0.0821503245513723
42.5;2.36428;0.876607;9.63637786783424;0.0824159324624007
42.6;2.36641;0.883848;9.65905749792417;0.0829199017053926
42.7;2.36854;0.886232;9.68178548711035;0.0829666539427712
42.8;2.37067;0.891989;9.70456193850742;0.0833279311310495
42.9;2.37279;0.898952;9.72727968211674;0.0838005558388328
43;2.37491;0.905717;9.7500456384299;0.0842523864979874
43.1;2.37702;0.910629;9.77275218170583;0.0845307665710922
43.2;2.37913;0.915245;9.79550668636954;0.0847801799942927
43.3;2.38123;0.921732;9.81820107117478;0.0852019660141062
43.4;2.38333;0.928086;9.84094316426427;0.0856093409897501
43.5;2.38542;0.93354;9.86362442914321;0.0859326467045056
43.6;2.38751;0.941794;9.88635314743729;0.0865114319960953
43.7;2.3896;0.945408;9.90912941842788;0.0866620940808532
43.8;2.39168;0.953568;9.93184402261719;0.0872284674046883
43.9;2.39375;0.96022;9.95449637684204;0.0876553304659371
44;2.39583;0.965082;9.97730544251074;0.0879161106570489
44.1;2.39789;0.969966;9.99994199937083;0.0881791922226026
44.2;2.39996;0.977821;10.0227354624048;0.0887094681111644
44.3;2.40202;0.986289;10.0454657015655;0.0892935641328558
44.4;2.40407;0.991789;10.0681321314063;0.0896076219749629
44.5;2.40613;0.99681;10.090955984094;0.089875931473316
44.6;2.40817;1.00071;10.1136046280639;0.0900436927073169
44.7;2.41022;1.0092;10.1364108859788;0.090621656324716
44.8;2.41225;1.01415;10.1590407616299;0.0908814674722879
44.9;2.41429;1.02495;10.1818284403131;0.0916621110287131
45;2.41632;1.03103;10.2045506072434;0.0920188623480778
45.1;2.41835;1.03517;10.2273189470221;0.0922009969507959
45.2;2.42037;1.03909;10.2500210527024;0.0923633827112172
45.3;2.42239;1.04569;10.2727690629841;0.0927624786915651
45.4;2.4244;1.057;10.2954501156225;0.093577501487797
45.5;2.42641;1.06314;10.3181768030242;0.0939320898146712
45.6;2.42842;1.0717;10.3409492170075;0.0944982628431865
45.7;2.43042;1.07318;10.3636538124687;0.0944396949881082
45.8;2.43242;1.0804;10.3864038625604;0.0948850939278958
45.9;2.43441;1.08559;10.4090853668586;0.0951513609630312
46;2.4364;1.09369;10.4318120522907;0.0956707471219186
46.1;2.43839;1.10487;10.4545840088566;0.096456580103278
46.2;2.44037;1.10791;10.4772865532962;0.0965306559921882
46.3;2.44235;1.11127;10.5000340933047;0.0966318874347495
46.4;2.44432;1.12046;10.5227114903705;0.0972392653357989
46.5;2.44629;1.12892;10.5454336059419;0.0977806497816589
46.6;2.44826;1.13489;10.568200528201;0.0981042814077574
46.7;2.45022;1.14145;10.5908964359602;0.0984781467340791
46.8;2.45218;1.14972;10.6136368713213;0.0989974125021175
46.9;2.45414;1.15838;10.6364219216442;0.0995477826259779
47;2.45609;1.16211;10.659135082526;0.0996737744073055
47.1;2.45803;1.16919;10.6817757589414;0.10008666696971
47.2;2.45998;1.17486;10.704577446091;0.100376113995672
47.3;2.46192;1.18191;10.7273063662604;0.100782734166506
47.4;2.46385;1.19012;10.7499619231272;0.101287136740206
47.5;2.46579;1.19798;10.7727789746419;0.101758472029451
47.6;2.46771;1.20439;10.7954044237538;0.102106715186007
47.7;2.46964;1.21199;10.8181915367824;0.102552915666315
47.8;2.47156;1.21952;10.8409042617717;0.102992134134318
47.9;2.47348;1.22393;10.8636606370838;0.103166302327816
48;2.47539;1.23225;10.8863418825948;0.103669405791229
48.1;2.4773;1.24122;10.9090664906828;0.10422479385526
48.2;2.47921;1.25041;10.9318345442495;0.104796122956853
48.3;2.48111;1.2542;10.9545265804915;0.104914234081567
48.4;2.48301;1.26499;10.9772617725874;0.105615959976362
48.5;2.48491;1.27203;11.0000402026113;0.106002144869747
48.6;2.4868;1.27615;11.022741724775;0.106144673919948
48.7;2.48869;1.28296;11.0454861933872;0.106509606951716
48.8;2.49057;1.29236;11.06815300756;0.107088466577314
48.9;2.49245;1.29473;11.0908624754253;0.107083345181664
49;2.49433;1.30494;11.1136146772476;0.107725070903156
49.1;2.49621;1.31163;11.1364096934421;0.108073971885502
49.2;2.49808;1.31656;11.1591260127076;0.108277519175642
49.3;2.49994;1.33337;11.1817630329939;0.109456241792638
49.4;2.50181;1.33326;11.2045642423519;0.109242736858508
49.5;2.50367;1.34575;11.2272858563931;0.110061220110951
49.6;2.50553;1.35106;11.2500497719646;0.110290164134029
49.7;2.50738;1.35826;11.2727333398735;0.110672982324734
49.8;2.50923;1.36388;11.2954589112242;0.110925505899983
49.9;2.51108;1.37527;11.3182265637951;0.111645129506069
50;2.51292;1.38549;11.3409129657617;0.112268031047935
50.1;2.51476;1.38778;11.363641149135;0.112246868318164
50.2;2.5166;1.39803;11.3864111908637;0.112868043734185
50.3;2.51843;1.40702;11.4090990764266;0.113386152478458
50.4;2.52026;1.41702;11.4318285188331;0.113983232462815
50.5;2.52209;1.42258;11.4545995942016;0.11422125530734
50.6;2.52391;1.4311;11.4772876052905;0.11469640239704
50.7;2.52573;1.43809;11.5000169461583;0.115047044031566
50.8;2.52754;1.4445;11.5226624648428;0.115350869198576
50.9;2.52936;1.45429;11.5454744631504;0.115921482624803
51;2.53117;1.46387;11.5682023344474;0.116474095582291
51.1;2.53298;1.47248;11.5909713804432;0.116947291476424
51.2;2.53478;1.4826;11.6136555385456;0.11753928077942
51.3;2.53658;1.48883;11.6363805649029;0.117820921295705
51.4;2.53838;1.49681;11.6591465331443;0.118239408642678
51.5;2.54017;1.50646;11.6818266981305;0.118788880802327
51.6;2.54196;1.51736;11.7045474969685;0.119434399403998
51.7;2.54375;1.52424;11.727309002458;0.119761372942672
51.8;2.54553;1.53267;11.7499837870538;0.120209564623624
51.9;2.54731;1.542;11.7726989687088;0.120726246173786
52;2.54909;1.54875;11.795454619394;0.121039075677121
52.1;2.55086;1.55577;11.8181226293411;0.121372688106353
52.2;2.55264;1.56851;11.840959206145;0.122148974606927
52.3;2.5544;1.57863;11.8635791940983;0.122720898762318
52.4;2.55617;1.5896;11.8863678913193;0.123355162091159
52.5;2.55793;1.59781;11.9090678689287;0.123774234996922
52.6;2.55969;1.60409;11.9318078336771;0.124042208222629
52.7;2.56145;1.61217;11.9545878560037;0.124447803196831
52.8;2.5632;1.62345;11.9772782330408;0.125099421530981
52.9;2.56495;1.62912;12.0000083530027;0.125316842556006
53;2.5667;1.6416;12.0227782855003;0.126056050714445
53.1;2.56844;1.65062;12.0454576450379;0.126528332306368
53.2;2.57018;1.65724;12.068176501013;0.126814938554858
53.3;2.57192;1.66732;12.0909349222092;0.127364470903551
53.4;2.57365;1.67375;12.113601840856;0.127634651433854
53.5;2.57538;1.68452;12.1363080072114;0.128233899439268
53.6;2.57711;1.6936;12.159053489233;0.128702265811576
53.7;2.57884;1.7058;12.1818383549955;0.129405319202201
53.8;2.58056;1.71677;12.2045306267254;0.130013708819406
53.9;2.58228;1.723;12.2272619627483;0.130261274393178
54;2.584;1.73067;12.2500324303126;0.130616284080987
54.1;2.58571;1.74505;12.2727093690253;0.131476547212919
54.2;2.58742;1.74757;12.2954251184768;0.131441453313996
54.3;2.58913;1.76221;12.3181797450904;0.132316129811179
54.4;2.59084;1.77149;12.3409733154029;0.1327856639931
54.5;2.59254;1.78056;12.3636722586742;0.133238825790887
54.6;2.59424;1.79047;12.3864098229677;0.13375281525656
54.7;2.59593;1.79954;12.4090519828045;0.13420337264019
54.8;2.59763;1.81357;12.4318667582398;0.135019951630138
54.9;2.59932;1.81991;12.4545858052487;0.135263175421576
55;2.60101;1.82948;12.4773432799092;0.135744854308729
55.1;2.60269;1.83594;12.5000042465015;0.135995512777396
55.2;2.60437;1.85001;12.5227033155148;0.136807704556933
55.3;2.60605;1.86209;12.5454405510149;0.13746987357015
55.4;2.60773;1.86966;12.5682160171753;0.137797039613262
55.5;2.6094;1.88199;12.5908938686595;0.138474335697658
55.6;2.61107;1.89637;12.6136096237964;0.139299572442945
55.7;2.61274;1.90046;12.6363633459379;0.13936706963489
55.8;2.61441;1.91078;12.6591550985421;0.139890058075697
55.9;2.61607;1.91816;12.6818481260074;0.140197434026024
56;2.61773;1.92964;12.704578855182;0.140802575576436
56.1;2.61938;1.94021;12.7272100759157;0.141340446403168
56.2;2.62104;1.95213;12.7500161684615;0.141972923964818
56.3;2.62269;1.96185;12.7727224226477;0.142444604617454
56.4;2.62434;1.96968;12.7954661730792;0.14277734259127
56.5;2.62599;1.97956;12.8182474816759;0.143256950827162
56.6;2.62763;1.99528;12.8409280004878;0.14415796396959
56.7;2.62927;2.00173;12.863645745868;0.144386984253158
56.8;2.63091;2.01502;12.8864007789181;0.145107435114442
56.9;2.63254;2.027;12.9090540696041;0.145732412129282
57;2.63418;2.03399;12.9318836334037;0.145995333690788
57.1;2.63581;2.04705;12.9546111215969;0.146693446500409
57.2;2.63743;2.05689;12.9772359127467;0.147159997358576
57.3;2.63906;2.06904;13.0000373854363;0.147788176776752
57.4;2.64068;2.0808;13.022735826774;0.148387591815505
57.5;2.6423;2.09128;13.0454710693877;0.148893546515358
57.6;2.64392;2.10125;13.0682431729438;0.149361222589694
57.7;2.64553;2.10732;13.0909112873878;0.149551718623491
57.8;2.64714;2.11838;13.1136159268909;0.150094774505222
57.9;2.64875;2.1357;13.1363571503058;0.151078525909612
58;2.65036;2.14639;13.1591350165799;0.151590474805604
58.1;2.65196;2.15267;13.1818077659691;0.151790944816329
58.2;2.65356;2.16783;13.2045168207939;0.152615539644863
58.3;2.65516;2.17123;13.2272622391895;0.152610527837131
58.4;2.65676;2.18455;13.2500440793843;0.153301280180629
58.5;2.65835;2.19924;13.2727196717893;0.154086961039871
58.6;2.65994;2.20677;13.2954313470645;0.154368899155544
58.7;2.66153;2.21486;13.3181791626273;0.154688663610324
58.8;2.66312;2.23071;13.3409631759865;0.155548129691544
58.9;2.6647;2.24019;13.363639807626;0.155962557541343
59;2.66628;2.25007;13.3863522966635;0.156403093265125
59.1;2.66786;2.26369;13.4091006997982;0.15710140744812
59.2;2.66944;2.27417;13.4318850738195;0.157579553077617
59.3;2.67101;2.28627;13.4545609292741;0.15816945330866
59.4;2.67258;2.29956;13.4772724137833;0.158839312701657
59.5;2.67415;2.30383;13.5000195833286;0.158884613000719
59.6;2.67571;2.3213;13.5226572666806;0.159839894130516
59.7;2.67728;2.32806;13.5454757464088;0.160053891710952
59.8;2.67884;2.34321;13.5681843967151;0.160844339705664
59.9;2.6804;2.35687;13.5909285001622;0.161529816280972
60;2.68196;2.36671;13.6137081121001;0.161951366610394
60.1;2.68351;2.37683;13.6363769234641;0.162391964379492
60.2;2.68506;2.3829;13.6590808987308;0.162554529609446
60.3;2.68661;2.39984;13.6818200924464;0.163456573155714
60.4;2.68816;2.41482;13.7045945592418;0.16422214092821
60.5;2.6897;2.42609;13.7272570805256;0.164734681192475
60.6;2.69124;2.43468;13.7499545289791;0.165063559702276
60.7;2.69278;2.4463;13.7726869584317;0.165596144214221
60.8;2.69432;2.46155;13.7954544227957;0.166372044390028
60.9;2.69585;2.47046;13.8181087942374;0.166718981099716
61;2.69739;2.48014;13.8409462621173;0.167114680977637
61.1;2.69892;2.49531;13.8636702893463;0.167879800306694
61.2;2.70045;2.50794;13.8864291109479;0.168471564356263
61.3;2.70197;2.51919;13.9090736887158;0.168970256140507
61.4;2.70349;2.52992;13.9317527124142;0.169432219293093
61.5;2.70502;2.54394;13.9546157798507;0.170110689398493
61.6;2.70653;2.55446;13.9772143072726;0.170556416406461
61.7;2.70805;2.56576;13.9999969834672;0.171050701065337
61.8;2.70956;2.5815;14.0226640882694;0.17184035966136
61.9;2.71108;2.58923;14.0455159006612;0.172093135063997
62;2.71259;2.59732;14.0682517909484;0.172370360943944
62.1;2.71409;2.61438;14.0908711288971;0.173242483993769
62.2;2.7156;2.6249;14.1136755573122;0.173677143593971
62.3;2.7171;2.63873;14.1363630820378;0.174330516894865
62.4;2.7186;2.65206;14.1590846635867;0.174948557835451
62.5;2.7201;2.66863;14.1818403530825;0.175777767249289
62.6;2.72159;2.67765;14.2044781561838;0.176109299674385
62.7;2.72309;2.68947;14.2273019870117;0.176621571063214
62.8;2.72458;2.7027;14.2500075784372;0.17722614143625
62.9;2.72607;2.71666;14.2727470264108;0.177876317554539
63;2.72756;2.72616;14.2955203814164;0.178232576075816
63.1;2.72904;2.74095;14.318174511502;0.178934506715659
63.2;2.73052;2.75144;14.3408621945232;0.179353674201068
63.3;2.732;2.76312;14.3635834801751;0.17984866639775
63.4;2.73348;2.77629;14.3863384182264;0.180438641380151
63.5;2.73496;2.78683;14.4091270585195;0.180855799904589
63.6;2.73643;2.8026;14.4317951322478;0.181612053295304
63.7;2.7379;2.81344;14.4544965525481;0.182046693687742
63.8;2.73937;2.82792;14.4772313684761;0.182714849489159
63.9;2.74084;2.83903;14.4999996291594;0.183163230188669
64;2.7423;2.85113;14.5226461565602;0.183675513262605
64.1;2.74377;2.85812;14.5454812260744;0.183855356964189
64.2;2.74523;2.87956;14.5681942051046;0.184964290788191
64.3;2.74669;2.89525;14.5909403693034;0.185700793628868
64.4;2.74814;2.90599;14.6135636307397;0.186119586068023
64.5;2.7496;2.917;14.6363760826782;0.186552177088617
64.6;2.75105;2.92745;14.6590652736862;0.186949217519346
64.7;2.7525;2.94573;14.6817873878848;0.187844021037791
64.8;2.75395;2.95634;14.7045424730471;0.188247445290038
64.9;2.7554;2.96513;14.7273305770157;0.188533583972179
65;2.75684;2.98646;14.7499942469727;0.189616577198054
65.1;2.75828;2.99629;14.7726905761234;0.189966954942727
65.2;2.75972;3.0106;14.7954196115309;0.190599558229033
65.3;2.76116;3.02041;14.8181814003262;0.190945464814161
65.4;2.7626;3.03326;14.8409759897081;0.191481888614105
65.5;2.76403;3.05203;14.8636447897025;0.192391473741341
65.6;2.76546;3.06635;14.8863460292696;0.193017953552721
65.7;2.76689;3.073;14.9090797548312;0.19316013542938
65.8;2.76832;3.08909;14.9318460128755;0.193894040747288
65.9;2.76974;3.1003;14.9544853043066;0.194321530332485
66;2.77117;3.11544;14.9773165387337;0.194991442552149
66.1;2.77259;3.1276;15.0000204441766;0.195474750229981
66.2;2.77401;3.14159;15.0227566120661;0.196070506222019
66.3;2.77543;3.15447;15.0455250882474;0.196594999705588
66.4;2.77684;3.16358;15.0681652361752;0.196884955656147
66.5;2.77825;3.17745;15.0908373292276;0.197469524735573
66.6;2.77967;3.19006;15.1137025486988;0.197971880786492
66.7;2.78108;3.20601;15.1364388946496;0.198681383230288
66.8;2.78248;3.22096;15.1590457301945;0.199328602306098
66.9;2.78389;3.23377;15.1818460551257;0.199839374876248
67;2.78529;3.24864;15.2045165052151;0.200477440900781
67.1;2.78669;3.26281;15.2272187161621;0.201070193054728
67.2;2.78809;3.27627;15.2499527324629;0.201617201842989
67.3;2.78949;3.29068;15.2727185986762;0.202220666451375
67.4;2.79089;3.30598;15.2955163594233;0.202876664174452
67.5;2.79228;3.32017;15.3181828767429;0.203464443625766
67.6;2.79367;3.32963;15.3408809224288;0.203760740672793
67.7;2.79506;3.34089;15.3636105403357;0.204165822192164
67.8;2.79645;3.35523;15.3863717743797;0.20475734629956
67.9;2.79784;3.37199;15.4091646685377;0.20549431175283
68;2.79922;3.38192;15.4318249477768;0.205815240288181
68.1;2.8006;3.40312;15.4545165197882;0.206819811199399
68.2;2.80198;3.41707;15.4772394277859;0.207381219103834
68.3;2.80336;3.42877;15.4999937150434;0.207804321578251
68.4;2.80474;3.44056;15.5227794248938;0.208231309728454
68.5;2.80611;3.45572;15.5454311455917;0.208862493191707
68.6;2.80748;3.46821;15.5681139204141;0.209330405178268
68.7;2.80885;3.48194;15.5908277919345;0.209871384578696
68.8;2.81022;3.49547;15.6135728027843;0.210398452006313
68.9;2.81159;3.51045;15.6363489956539;0.211010841436248
69;2.81296;3.52167;15.6591564132917;0.211395458007117
69.1;2.81432;3.53968;15.6818282793883;0.212187773469264
69.2;2.81568;3.55385;15.7045310001991;0.21274766708252
69.3;2.81704;3.56959;15.7272646177153;0.213399505632234
69.4;2.8184;3.58132;15.7500291739849;0.213809776854734
69.5;2.81975;3.59079;15.7726569837047;0.214085937814658
69.6;2.82111;3.60892;15.79548331559;0.214874435715114
69.7;2.82246;3.62268;15.8181725298397;0.215402713557163
69.8;2.82381;3.63886;15.8408923952135;0.216072872779249
69.9;2.82516;3.65071;15.8636429531184;0.21648406635204
70;2.82651;3.66454;15.8864242450172;0.217011011142949
70.1;2.82785;3.67956;15.9090672209113;0.217608691947804
70.2;2.82919;3.69268;15.9317405587309;0.218092167618045
70.3;2.83054;3.70774;15.9546138444792;0.218686195628532
70.4;2.83188;3.72332;15.9773482556845;0.219311045749051
70.5;2.83321;3.73562;15.9999431511394;0.219743087773186
70.6;2.83455;3.75183;16.0227383443304;0.220401084955264
70.7;2.83588;3.76545;16.0453936487663;0.220907189214286
70.8;2.83722;3.77812;16.0682497864478;0.221353685777427
70.9;2.83855;3.80059;16.0909656613721;0.222374210755677
71;2.83988;3.80576;16.11371176851;0.222380746589572
71.1;2.8412;3.82398;16.1363167840725;0.223150636638221
71.2;2.84253;3.84255;16.1591232483321;0.223936266695531
71.3;2.84385;3.8532;16.1817882466279;0.224260708180724
71.4;2.84517;3.87035;16.2044831824758;0.224961712534456
71.5;2.84649;3.87775;16.2272080954195;0.225094512037098
71.6;2.84781;3.90059;16.249963025055;0.226121644106397
71.7;2.84913;3.91037;16.2727480110305;0.226389570293205
71.8;2.85044;3.9277;16.2953901382802;0.227095195228163
71.9;2.85176;3.9427;16.3182351276387;0.227661766394876
72;2.85307;3.95167;16.3409368820585;0.227880997830546
72.1;2.85438;3.96903;16.3636683952643;0.228582457902876
72.2;2.85569;3.98812;16.3864297062658;0.229381193688245
72.3;2.85699;3.99958;16.4090467627854;0.229741470311271
72.4;2.8583;4.01668;16.4318675584022;0.230421668048066
72.5;2.8596;4.03409;16.4545437225413;0.23111976251721
72.6;2.8609;4.04373;16.4772493848634;0.231371076246253
72.7;2.8622;4.0557;16.4999845837411;0.231754489873555
72.8;2.8635;4.07633;16.5227493575969;0.232630731445846
72.9;2.86479;4.08957;16.5453682903432;0.2330854463882
73;2.86609;4.10821;16.5681921013834;0.233843640614363
73.1;2.86738;4.11887;16.5908696930961;0.234148172993206
73.2;2.86867;4.13559;16.613576557779;0.234795584328586
73.3;2.86996;4.15127;16.6363127332188;0.235381968033539
73.4;2.87125;4.17069;16.6590782572506;0.236178238707763
73.5;2.87254;4.18057;16.6818731677586;0.236432529536684
73.6;2.87382;4.1987;16.7045204565861;0.237154121756406
73.7;2.8751;4.21201;16.7271967525039;0.237601582405017
73.8;2.87639;4.22738;16.7500795925732;0.238161185585263
73.9;2.87767;4.24563;16.7728142415229;0.23888338348132
74;2.87894;4.25745;16.7954000545652;0.239244410743539
74.1;2.88022;4.27496;16.8181927508487;0.23992107728189
74.2;2.88149;4.28653;16.8408362312089;0.240265083118783
74.3;2.88277;4.30693;16.8636871230357;0.241099722041487
74.4;2.88404;4.32209;16.886388417953;0.24164129163503
74.5;2.88531;4.33245;16.90911856183;0.241913078247961
74.6;2.88658;4.34942;16.9318775913283;0.242552402995621
74.7;2.88784;4.36465;16.9544859973981;0.243095235398692
74.8;2.88911;4.37843;16.9773026801416;0.243553222521896
74.9;2.89037;4.39701;16.9999683578968;0.244278762749656
75;2.89163;4.41269;17.0226626124057;0.244841181067362
75.1;2.89289;4.4273;17.0453854796975;0.245342500717487
75.2;2.89415;4.43935;17.068136995847;0.245700483731133
75.3;2.89541;4.45434;17.0909171969747;0.246219688670339
75.4;2.89666;4.47242;17.1135449828908;0.246910254410412
75.5;2.89792;4.50026;17.1363824341421;0.248134379407889
75.6;2.89917;4.50613;17.1590670871392;0.248147659699511
75.7;2.90042;4.51906;17.1817801136823;0.248548820398465
75.8;2.90167;4.52837;17.2045215492605;0.248749739878989
75.9;2.90292;4.55081;17.2272914294073;0.249670117890246
76;2.90416;4.56263;17.2499072897154;0.250008393334209
76.1;2.90541;4.58165;17.2727339375101;0.250736973222974
76.2;2.90665;4.60082;17.2954061814788;0.251474056075212
76.3;2.90789;4.61491;17.3181065564677;0.251931605800742
76.4;2.90913;4.626;17.3408350973808;0.252224065885671
76.5;2.91037;4.6404;17.3635918391656;0.252695662190827
76.6;2.91161;4.6526;17.3863768168128;0.253046048514876
76.7;2.91284;4.66788;17.4090059743764;0.253565021734322
76.8;2.91408;4.68707;17.43184730048;0.254291928724796
76.9;2.91531;4.70165;17.4545324211488;0.254769391751802
77;2.91654;4.71723;17.4772454616832;0.255299417317492
77.1;2.91777;4.72794;17.4999864564458;0.255564511419017
77.2;2.919;4.74613;17.5227554398414;0.256232395628965
77.3;2.92022;4.76023;17.5453669917201;0.256680280423962
77.4;2.92145;4.77639;17.5681918275163;0.257235063293662
77.5;2.92267;4.78701;17.5908588456154;0.257492676360619
77.6;2.92389;4.79763;17.6135535343523;0.257749278833068
77.7;2.92511;4.81276;17.6362759275057;0.258246873931328
77.8;2.92633;4.8198;17.6590260588956;0.258309302146142
77.9;2.92755;4.83188;17.6818039623834;0.258640975450187
78;2.92877;4.83901;17.7046096718716;0.258706815319274
78.1;2.92998;4.84614;17.7272559478085;0.258774697879168
78.2;2.93119;4.8553;17.7499296423241;0.258950305020887
78.3;2.93241;4.87888;17.7728185158616;0.259890649658052
78.4;2.93362;4.88669;17.7955473744522;0.259991896093552
78.5;2.93482;4.9165;17.8181155695104;0.261264204794546
78.6;2.93603;4.92974;17.8408992707089;0.261650992830477
78.7;2.93724;4.95113;17.8637105568714;0.2624685098445
78.8;2.93844;4.96528;17.8863605968456;0.26290295446489
78.9;2.93964;4.9725;17.9090378331824;0.262969488128795
79;2.94084;4.98793;17.9317422985369;0.263469147284214
79.1;2.94204;5.00479;17.9544740256036;0.264042673684301
79.2;2.94324;5.01286;17.9772330471161;0.264151258908726
79.3;2.94444;5.04623;18.0000193958475;0.265590781507458
79.4;2.94563;5.0579;18.0226428772303;0.265888395878693
79.5;2.94683;5.0701;18.045483750466;0.266210092976817
79.6;2.94802;5.08365;18.0681613666345;0.266604100010155
79.7;2.94921;5.10048;18.0908659852295;0.267168603244411
79.8;2.9504;5.12428;18.1135976384031;0.268096048527478
79.9;2.95159;5.14332;18.1363563583454;0.268772168728818
80;2.95278;5.16088;18.1591421772852;0.269369053804437
80.1;2.95396;5.1698;18.1817633088972;0.269516410808909
80.2;2.95413;5.17967;18.1850244858519;0.269985060682084