File: data/materialdata/DragonSkinFXPro.csv
PARAMETER;INFO;URL;;
Specimen Thickness (mm);3;;;
Specimen Width (mm);6;;;
Specimen Length (mm);33;;;
Specimen Cross-section (cm^2);0.18;;;
Standard;ASTM D412;;;
Type of test;Pull-to-failure;;;
Speed (mm/min);450;;;
Machine;Instron  5569;;;
Load Cell;1 kN - Instron  2525-806;;;
Grippers;Instron 2710-010 ;;;
Strain Measurement;Global;;;
Strain calculation;Derived from the machine crosshead displacement readings;;;
Lab;Univ. Savoie Mont Blanc - SYMME Lab, 7400 Annecy, France;;;
Material supplier;Smooth-On;https://www.smooth-on.com/products/dragon-skin-fx-pro/;;
Material;DragonSkinFXPro;;;
;;;;
Time (s);True Strain;True Stress (MPa);Engineering Strain;Engineering Stress (MPa)
0.2;0.0436233333333333;0.0000927762333333334;0.04459;0.00009
0.3;0.0657366666666667;0.00380371740333333;0.0679466666666667;0.00356333333333333
0.4;0.08695;0.00743450565;0.09084;0.00681333333333333
0.5;0.107616666666667;0.00871455454333333;0.11362;0.00782666666666667
0.6;0.12783;0.0105337104033333;0.13636;0.00926666666666667
0.7;0.147633333333333;0.01289290762;0.15909;0.0111233333333333
0.8;0.16705;0.0154435106;0.181813333333333;0.0130666666666667
0.9;0.1861;0.0171637920033333;0.204543333333333;0.01425
1;0.204793333333333;0.0195635846233333;0.22727;0.01594
1.1;0.223146666666667;0.0212446202333333;0.250003333333333;0.0169966666666667
1.2;0.241163333333333;0.0239032442766667;0.272726666666667;0.01878
1.3;0.25886;0.0260820867933333;0.295456666666667;0.02013
1.4;0.27625;0.02831450733;0.31818;0.02148
1.5;0.29335;0.0308644219366667;0.34091;0.0230166666666667
1.6;0.310153333333333;0.0329397509766667;0.363636666666667;0.0241566666666667
1.7;0.326686666666667;0.0354679360733333;0.386366666666667;0.0255833333333333
1.8;0.342946666666667;0.0375792260233333;0.40909;0.02667
1.9;0.358946666666667;0.0406442296466667;0.431816666666667;0.0283866666666667
2;0.37469;0.0430692393566667;0.454546666666667;0.02961
2.1;0.3902;0.0460361216133333;0.47727;0.0311633333333333
2.2;0.405466666666667;0.0486688213833333;0.5;0.0324433333333333
2.3;0.4205;0.0516798620966667;0.522726666666667;0.03394
2.4;0.43532;0.0542626317;0.545456666666667;0.03511
2.5;0.449916666666667;0.0570964401533333;0.56818;0.03641
2.6;0.46431;0.06078397841;0.59091;0.0382066666666667
2.7;0.47849;0.0631095551933333;0.61364;0.03911
2.8;0.492476666666667;0.06646476059;0.63636;0.0406166666666667
2.9;0.50627;0.06970404397;0.65909;0.04201
3;0.519876666666667;0.0728515750333333;0.681816666666667;0.0433166666666667
3.1;0.5333;0.07570035173;0.704546666666667;0.04441
3.2;0.546543333333333;0.0792301244033333;0.727273333333333;0.04587
3.3;0.559616666666667;0.08264371343;0.75;0.0472266666666667
3.4;0.57252;0.0865714656866667;0.77273;0.0488366666666667
3.5;0.58526;0.0900432112433333;0.795453333333333;0.05015
3.6;0.597836666666667;0.09294461979;0.81818;0.0511166666666667
3.7;0.61026;0.0970310297366667;0.84091;0.0527066666666667
3.8;0.62253;0.100826708913333;0.863636666666667;0.0541033333333333
3.9;0.63465;0.104843240616667;0.88636;0.05558
4;0.64663;0.10860715168;0.90909;0.05689
4.1;0.65846;0.112526038143333;0.93182;0.05825
4.2;0.67016;0.116661234816667;0.954546666666667;0.0596866666666667
4.3;0.68172;0.12066972735;0.977273333333333;0.0610266666666667
4.4;0.69315;0.12468011194;1;0.06234
4.5;0.70445;0.12918464093;1.02273;0.0638666666666667
4.6;0.71562;0.13344263705;1.04545;0.06524
4.7;0.72667;0.138100509473333;1.06818;0.0667733333333333
4.8;0.7376;0.142766811983333;1.09090666666667;0.0682766666666667
4.9;0.74841;0.14691542552;1.11363666666667;0.0695066666666667
5;0.759106666666666;0.15116364366;1.13636666666667;0.07076
5.1;0.76969;0.15639821218;1.15909;0.0724366666666667
5.2;0.78016;0.161178538143333;1.18182;0.07387
5.3;0.79052;0.166400692013333;1.20454666666667;0.07548
5.4;0.80078;0.17114167384;1.22727;0.07684
5.5;0.81093;0.175702231783333;1.25;0.0780866666666667
5.6;0.82098;0.18061012221;1.27272666666667;0.07947
5.7;0.83093;0.186903082256667;1.29545;0.0814233333333333
5.8;0.84078;0.19181731431;1.31818333333333;0.0827466666666667
5.9;0.85054;0.197007437436667;1.34091;0.0841566666666667
6;0.8602;0.20257443673;1.36364;0.0857033333333333
6.1;0.86977;0.20774254304;1.38636333333333;0.0870566666666667
6.2;0.87925;0.214330255033333;1.40909;0.0889666666666667
6.3;0.88864;0.219630665916667;1.43181666666667;0.0903133333333333
6.4;0.89794;0.225912632953333;1.45455;0.0920366666666667
6.5;0.90716;0.232015130416667;1.47727333333333;0.0936566666666667
6.6;0.91629;0.237685255933333;1.5;0.0950733333333333
6.7;0.92534;0.24407154317;1.52272666666667;0.0967466666666667
6.8;0.93431;0.25018270105;1.54545666666667;0.0982866666666667
6.9;0.9432;0.256791917636667;1.56818;0.0999933333333333
7;0.95201;0.263536426666667;1.59091;0.101716666666667
7.1;0.96074;0.26938213641;1.61363333333333;0.10307
7.2;0.9694;0.276238456776667;1.63636666666667;0.10478
7.3;0.97798;0.282965286523333;1.65909;0.106413333333333
7.4;0.986496666666667;0.290131295606667;1.68181666666667;0.108186666666667
7.5;0.99493;0.296184699216667;1.70454333333333;0.109516666666667
7.6;1.0033;0.304089013503333;1.72727;0.1115
7.7;1.0116;0.311400818526667;1.75;0.113236666666667
7.8;1.01983;0.31823964994;1.77273;0.114773333333333
7.9;1.028;0.326217708446667;1.79546;0.116696666666667
8;1.03609;0.333399435513333;1.81818;0.118303333333333
8.1;1.04412333333333;0.34041966811;1.84091;0.119826666666667
8.2;1.05209;0.348470946233333;1.86363333333333;0.121686666666667
8.3;1.06;0.356995278603333;1.88636;0.123683333333333
8.4;1.06784;0.363863733173333;1.90909;0.12508
8.5;1.07562;0.3720110499;1.93182;0.126886666666667
8.6;1.08334666666667;0.37982214823;1.95454666666667;0.128553333333333
8.7;1.09101;0.388473952523333;1.97727333333333;0.130476666666667
8.8;1.09861;0.39734226756;2;0.132446666666667
8.9;1.10616;0.405412272063333;2.02272333333333;0.13412
9;1.11365;0.414582710363333;2.04545;0.13613
9.1;1.12108666666667;0.422100709573333;2.06818;0.137576666666667
9.2;1.12847;0.431915667163333;2.09091;0.139736666666667
9.3;1.13579;0.439981204836667;2.11363666666667;0.141306666666667
9.4;1.14306;0.448882407193333;2.13636333333333;0.14312
9.5;1.15028;0.458160558693333;2.15909;0.14503
9.6;1.15745;0.466940435473333;2.18182;0.146753333333333
9.7;1.16457;0.476741499356667;2.20454666666667;0.14877
9.8;1.17164;0.485622081193333;2.22727666666667;0.150476666666667
9.9;1.17865666666667;0.495258593096667;2.25000666666667;0.152386666666667
10;1.18562;0.505072829646667;2.27272666666667;0.15433
10.1;1.19254;0.514687846363333;2.29545;0.156183333333333
10.2;1.19942;0.525281232463333;2.31818;0.158306666666667
10.3;1.20624;0.5352697134;2.34091;0.160216666666667
10.4;1.21302;0.546203503973333;2.36364;0.162383333333333
10.5;1.21976;0.555004816593333;2.38636666666667;0.163893333333333
10.6;1.22644666666667;0.56592172091;2.40909;0.166003333333333
10.7;1.23309;0.576560069116667;2.43182;0.168006666666667
10.8;1.23969;0.586503139013333;2.45454333333333;0.169776666666667
10.9;1.24625;0.597862374906667;2.47727;0.171933333333333
11;1.25276;0.609356988666667;2.5;0.1741
11.1;1.25924;0.618634053196667;2.52273;0.17561
11.2;1.26567;0.63062350618;2.54545666666667;0.17787
11.3;1.27206;0.64090117868;2.56818;0.179616666666667
11.4;1.27840333333333;0.65362942983;2.59091;0.182023333333333
11.5;1.28471;0.663774125506667;2.61363333333333;0.183686666666667
11.6;1.29098;0.676045899186667;2.63636;0.185913333333333
11.7;1.29721666666667;0.688764533343333;2.65909333333333;0.188236666666667
11.8;1.30341;0.69998933143;2.68181666666667;0.19012
11.9;1.30956;0.711469219056667;2.70454666666667;0.19205
12;1.31568;0.724164336996667;2.72727;0.194286666666667
12.1;1.32176;0.736949041283333;2.75;0.19652
12.2;1.3278;0.748904777576667;2.77272666666667;0.198506666666667
12.3;1.3338;0.761054117646667;2.79545333333333;0.20052
12.4;1.33977333333333;0.773683853156667;2.81818333333333;0.20263
12.5;1.34571;0.78643778939;2.84091;0.204753333333333
12.6;1.35161;0.79824200643;2.86364;0.206606666666667
12.7;1.35747;0.81249674948;2.88636;0.20906
12.8;1.3633;0.82497919175;2.90909;0.211043333333333
12.9;1.3691;0.83931931056;2.93182;0.21347
13;1.37486666666667;0.852909435953333;2.95454666666667;0.215676666666667
13.1;1.3806;0.865095659263333;2.97727;0.21751
13.2;1.38629333333333;0.879161251523333;3;0.219793333333333
13.3;1.39196;0.893818227956667;3.02272666666667;0.22219
13.4;1.39759;0.90765562796;3.04545;0.224363333333333
13.5;1.4032;0.92068945038;3.06818;0.226316666666667
13.6;1.40877;0.935125050406667;3.09091;0.228583333333333
13.7;1.41431;0.950570290123333;3.11363666666667;0.23108
13.8;1.41982;0.963591665733333;3.13636666666667;0.232956666666667
13.9;1.4253;0.97923910686;3.15909;0.235446666666667
14;1.43075;0.993158356593333;3.18182;0.237493333333333
14.1;1.43617;1.00862714788667;3.20454666666667;0.239886666666667
14.2;1.44156;1.02449314934667;3.22727;0.242353333333333
14.3;1.44692;1.03855856745;3.25;0.244366666666667
14.4;1.45225;1.05377586126667;3.27273;0.246626666666667
14.5;1.45756;1.06952194228333;3.29545333333333;0.24899
14.6;1.46283;1.08492506680667;3.31818;0.251246666666667
14.7;1.46808;1.1013710059;3.34091;0.25372
14.8;1.47330666666667;1.11788362712667;3.36363666666667;0.25618
14.9;1.4785;1.13324307857;3.38636666666667;0.258356666666667
15;1.48367;1.14880549263333;3.40909;0.260556666666667
15.1;1.48881;1.16525457353667;3.43182;0.26293
15.2;1.49392666666667;1.18241801227;3.45455;0.26544
15.3;1.49901;1.19866181401667;3.47727;0.267723333333333
15.4;1.50408;1.21588468449333;3.5;0.270196666666667
15.5;1.50911666666667;1.23272359178667;3.52272666666667;0.27256
15.6;1.51413;1.24941015397667;3.54545666666667;0.27487
15.7;1.51911666666667;1.26620546165;3.56818;0.27718
15.8;1.52408;1.28490299166667;3.59091;0.27988
15.9;1.52902;1.30234626077667;3.61363666666667;0.282283333333333
16;1.53393;1.31935876113667;3.63636333333333;0.284566666666667
16.1;1.53882;1.33703736900333;3.65909;0.286973333333333
16.2;1.54369;1.35527345743;3.68181666666667;0.289476666666667
16.3;1.54853;1.37237249007;3.70454666666667;0.291713333333333
16.4;1.55335;1.39098250585667;3.72727;0.294246666666667
16.5;1.55814333333333;1.41076295917;3.75;0.297
16.6;1.56292;1.42802842812;3.77272666666667;0.299206666666667
16.7;1.56767;1.44783253123;3.79545666666667;0.30192
16.8;1.5724;1.46646276862333;3.81818333333333;0.30436
16.9;1.5771;1.48644626512;3.84090666666667;0.307063333333333
17;1.58179;1.50527523984333;3.86363333333333;0.309496666666667
17.1;1.58645;1.52457818122333;3.88636333333333;0.312006666666667
17.2;1.59109;1.54385103474;3.90909;0.314486666666667
17.3;1.59571;1.56325606829667;3.93182;0.316973333333333
17.4;1.60030666666667;1.58455479515667;3.95454666666667;0.319816666666667
17.5;1.60488;1.60447127695333;3.97727333333333;0.32236
17.6;1.60944;1.62317065430333;4;0.324636666666667
17.7;1.61397;1.64534343244333;4.02272333333333;0.32758
17.8;1.61849;1.66566005926333;4.04545666666667;0.33013
17.9;1.62298;1.68650686611333;4.06818;0.332763333333333
18;1.62746;1.70638839675667;4.09091;0.335183333333333
18.1;1.63191;1.72759922835667;4.11363333333333;0.33784
18.2;1.63634333333333;1.74979117615333;4.13636;0.340666666666667
18.3;1.64076;1.76990343155333;4.15909;0.343063333333333
18.4;1.64516;1.79187612733;4.18182;0.3458
18.5;1.64953;1.81406184655333;4.20455;0.348553333333333
18.6;1.65389;1.83473992391667;4.22727666666667;0.350996666666667
18.7;1.65823;1.85799969496333;4.25000333333333;0.353903333333333
18.8;1.66255;1.88021726232;4.27272333333333;0.356593333333333
18.9;1.66685;1.90219100350333;4.29545;0.359213333333333
19;1.67113;1.92550458415333;4.31818;0.36206
19.1;1.6754;1.94726959269667;4.34091;0.364596666666667
19.2;1.67964;1.97184849806333;4.36363666666667;0.367633333333333
19.3;1.68387;1.99320029699667;4.38636333333333;0.370043333333333
19.4;1.68808;2.01729404143;4.40909;0.372946666666667
19.5;1.69227;2.04153544670333;4.43181666666667;0.375846666666667
19.6;1.69645;2.06741734818;4.45454;0.379026666666667
19.7;1.70061;2.08823374252333;4.47727;0.38125
19.8;1.70475;2.11448288094;4.5;0.384453333333333
19.9;1.70887;2.13743172999;4.52272666666667;0.387023333333333
20;1.71298;2.16025525407;4.54545333333333;0.389553333333333
20.1;1.71707;2.18595398696333;4.56818;0.39258
20.2;1.72114;2.21177235131;4.59090666666667;0.3956
20.3;1.7252;2.23604161967667;4.61363666666667;0.398323333333333
20.4;1.72924;2.26107276205333;4.63636;0.401156666666667
20.5;1.73326;2.28532687976333;4.65909666666667;0.403833333333333
20.6;1.73727;2.31117297055;4.68182;0.406766666666667
20.7;1.74126;2.33690336676333;4.70454666666667;0.409656666666667
20.8;1.74524;2.36397332311667;4.72727;0.412756666666667
20.9;1.7492;2.39005286521;4.75;0.41566
21;1.75314;2.41562576950667;4.77272333333333;0.418453333333333
21.1;1.75707;2.44245053423333;4.79545666666667;0.42144
21.2;1.76099;2.46781826570333;4.81818333333333;0.424156666666667
21.3;1.76489;2.49565979858667;4.84091;0.427273333333333
21.4;1.76877;2.52217444549333;4.86364;0.430136666666667
21.5;1.77264;2.54972554941333;4.88636;0.43316
21.6;1.77649;2.57607030306333;4.90909;0.43595
21.7;1.78033;2.6046864599;4.93182;0.439103333333333
21.8;1.78415666666667;2.63328215571333;4.95454666666667;0.44223
21.9;1.78796;2.65881269361;4.97727333333333;0.44482
22;1.79176;2.68870008255;5;0.448116666666667
22.1;1.79554;2.71791493904;5.02272333333333;0.451276666666667
22.2;1.79931;2.74420057072;5.04545;0.45393
22.3;1.80306;2.77735344661333;5.06818;0.457693333333333
22.4;1.8068;2.80339617065333;5.09090666666667;0.46026
22.5;1.81052;2.83237349254667;5.11363666666667;0.463286666666667
22.6;1.81423;2.86063219165;5.13636;0.46618
22.7;1.81793;2.89113862322;5.15909;0.46941
22.8;1.82161;2.91886263556;5.18182;0.47217
22.9;1.82528;2.95059946410667;5.20454666666667;0.475553333333333
23;1.82894;2.98040523480667;5.22727333333333;0.478603333333333
23.1;1.83258;3.00942105813;5.25;0.48151
23.2;1.83621;3.04130529902333;5.27272666666667;0.484846666666667
23.3;1.83983;3.0719726727;5.29545333333333;0.487966666666667
23.4;1.84343;3.10298692306333;5.31818;0.49112
23.5;1.84702;3.13373334809333;5.34091;0.49421
23.6;1.8506;3.16447919481667;5.36363666666667;0.497276666666667
23.7;1.85416666666667;3.19903381674333;5.38636333333333;0.500916666666667
23.8;1.85772;3.22959698065667;5.40909;0.503906666666667
23.9;1.86126;3.26065569745333;5.43182;0.506956666666667
24;1.86478;3.29275716956;5.45454666666667;0.510143333333333
24.1;1.8683;3.32352079611333;5.47727;0.513106666666667
24.2;1.8718;3.35702120341667;5.49999666666667;0.516463333333333
24.3;1.87529;3.39013920814333;5.52272666666667;0.519743333333333
24.4;1.87877;3.42286214718333;5.54545666666667;0.52294
24.5;1.88224;3.45590352069667;5.56818;0.526156666666667
24.6;1.88569;3.48910382362;5.59091;0.529383333333333
24.7;1.88913;3.52138064811667;5.61363666666667;0.532443333333333
24.8;1.89256;3.55721805254333;5.63636;0.536016666666667
24.9;1.89598;3.59058075424;5.65908666666667;0.5392
25;1.89939;3.62377651445333;5.68181666666667;0.542333333333333
25.1;1.90279;3.65915011656333;5.70454666666667;0.545773333333333
25.2;1.90617;3.69245212249333;5.72727333333333;0.54888
25.3;1.90954;3.72888844151;5.75;0.55243
25.4;1.9129;3.76419030380667;5.77272666666667;0.555786666666667
25.5;1.91625;3.79888418145333;5.79545666666667;0.559033333333333
25.6;1.91959;3.83241170077333;5.81818;0.562086666666667
25.7;1.92292;3.86886148747333;5.84091;0.56555
25.8;1.92624;3.90631226317333;5.86364;0.569133333333333
25.9;1.92954;3.94359043528667;5.88636;0.572666666666667
26;1.93284;3.97970212033333;5.90909333333333;0.576006666666667
26.1;1.93612;4.01490018316333;5.93181666666667;0.5792
26.2;1.93939666666667;4.05277557278667;5.95454666666667;0.58275
26.3;1.94266;4.09025690169;5.97727;0.586226666666667
26.4;1.94591;4.12844779924667;6;0.589776666666667
26.5;1.94915;4.16505174713667;6.02273;0.59308
26.6;1.95238;4.20105971720667;6.04545666666667;0.59628
26.7;1.9556;4.24074408983;6.06818333333333;0.599976666666667
26.8;1.95881;4.2766876932;6.09090666666667;0.603126666666667
26.9;1.96201;4.31560685609;6.11363666666667;0.606666666666667
27;1.9652;4.35434048137667;6.13636;0.610163333333333
27.1;1.96838;4.39367104376333;6.15909;0.613716666666667
27.2;1.97155;4.43073568737;6.18182;0.616936666666667
27.3;1.97471;4.47214638608667;6.20454666666667;0.620736666666667
27.4;1.97786;4.51101465861667;6.22727333333333;0.624163333333333
27.5;1.981;4.55060841255;6.25;0.62767
27.6;1.98413;4.59102959048333;6.27272333333333;0.631266666666667
27.7;1.98725;4.63158567244;6.29545;0.63486
27.8;1.99036;4.67061341191;6.31818;0.63822
27.9;1.99346;4.71158613058333;6.34091;0.641826666666667
28;1.99655;4.75020209251667;6.36363666666667;0.64509
28.1;1.99963666666667;4.79216240781;6.38636333333333;0.648786666666667
28.2;2.00271;4.83366587581667;6.40909;0.652393333333333
28.3;2.00577;4.87748267104667;6.43182;0.656296666666667
28.4;2.00882;4.91866448395333;6.45454666666667;0.65982
28.5;2.01187;4.95887279368;6.47727;0.66319
28.6;2.0149;5.00004201243333;6.5;0.666673333333333
28.7;2.01793;5.04450754376667;6.52272666666667;0.67057
28.8;2.02094333333333;5.08649677297667;6.54545333333333;0.674116666666667
28.9;2.02395;5.13056151356333;6.56818;0.677913333333333
29;2.02695;5.17535179274667;6.59090666666667;0.681783333333333
29.1;2.02994;5.21576333024667;6.61364;0.685056666666667
29.2;2.03292;5.25958233939667;6.63636666666667;0.688753333333333
29.3;2.03589;5.30372118761;6.65909;0.692473333333333
29.4;2.03886;5.34613877809333;6.68182;0.695946666666667
29.5;2.04181;5.39456431240333;6.70454333333333;0.70018
29.6;2.04476;5.43870103875;6.72727;0.703833333333333
29.7;2.04769;5.48187404899;6.75;0.70734
29.8;2.05062;5.52921252878333;6.77272666666667;0.71136
29.9;2.05354;5.57348978367667;6.79545666666667;0.714966666666667
30;2.05645;5.61805526024667;6.81818333333333;0.71859
30.1;2.05935;5.66310979634333;6.84091;0.722253333333333
30.2;2.06225;5.70961300774667;6.86363333333333;0.726076666666667
30.3;2.06513666666667;5.75898349636667;6.88636;0.730246666666667
30.4;2.06801;5.80329440886333;6.90909;0.733746666666667
30.5;2.07088;5.85285235065;6.93182;0.737896666666667
30.6;2.07374;5.89648306557333;6.95454333333333;0.74127
30.7;2.0766;5.94641417099;6.97727;0.74542
30.8;2.07944;5.99386426849;7;0.749233333333333
30.9;2.08228;6.04153323202667;7.02272333333333;0.753053333333333
31;2.08511;6.08788435005667;7.04545666666667;0.756686666666667
31.1;2.08793;6.13633327265333;7.06818333333333;0.76056
31.2;2.09074;6.18509731658333;7.09090666666667;0.76445
31.3;2.09355;6.23476449248;7.11363666666667;0.76843
31.4;2.09634;6.2836721266;7.13636;0.772296666666667
31.5;2.09913;6.33464328459667;7.15909;0.77639
31.6;2.10191;6.38301314612333;7.18182;0.780146666666667
31.7;2.10469;6.43310542041667;7.20454666666667;0.78409
31.8;2.10745333333333;6.48262640522;7.22727666666667;0.78794
31.9;2.11021;6.53377558427333;7.25;0.79197
32;2.11296;6.58437945308;7.27272666666667;0.795913333333333
32.1;2.11571;6.63501615215333;7.29545;0.799836666666667
32.2;2.11844;6.68616117897667;7.31818;0.803803333333333
32.3;2.12117;6.73740238531667;7.34091;0.807753333333333
32.4;2.12389;6.79087828375333;7.36363666666667;0.81195
32.5;2.12661;6.84152523445333;7.38636333333333;0.815793333333333
32.6;2.12931;6.8912204933;7.40909;0.819496666666667
32.7;2.13201;6.94700452335;7.43182;0.823906666666667
32.8;2.1347;6.99949061566;7.45454;0.827896666666667
32.9;2.13739;7.05145717676667;7.47727;0.831806666666667
33;2.14007;7.10616260656667;7.5;0.83602
33.1;2.14274;7.15772346804333;7.52272666666667;0.83984
33.2;2.1454;7.21109330137333;7.54545666666667;0.84385
33.3;2.14806;7.26715272603333;7.56818;0.848156666666667
33.4;2.1507;7.32198994628;7.59091;0.852293333333333
33.5;2.15335;7.37668769208667;7.61363666666667;0.856396666666667
33.6;2.15598;7.42924180322333;7.63636666666667;0.860226666666667
33.7;2.15861;7.48447044297;7.65909;0.86435
33.8;2.16123;7.53778995210333;7.68182;0.868226666666667
33.9;2.16385;7.59758848138667;7.70454333333333;0.872826666666667
34;2.16645;7.65236903065333;7.72727;0.876833333333333
34.1;2.16905;7.70648697003;7.75;0.88074
34.2;2.17165;7.76570451735667;7.77272666666667;0.885213333333333
34.3;2.17423666666667;7.82106762075667;7.79545;0.889216666666667
34.4;2.17682;7.87825326811;7.81818;0.89341
34.5;2.17939;7.93651253924333;7.84091;0.897703333333333
34.6;2.18196;7.99492556946333;7.86363666666667;0.901993333333333
34.7;2.18452;8.05232750747;7.88636;0.906143333333333
34.8;2.18707;8.10845641094667;7.90909;0.910133333333333
34.9;2.18962;8.16799592939667;7.93181666666667;0.914483333333333
35;2.19216;8.22453141440333;7.95454666666667;0.918476666666666
35.1;2.1947;8.28357759014333;7.97727;0.922726666666667
35.2;2.19722;8.34597230243333;8;0.92733
35.3;2.19975;8.40301052015;8.02273;0.931316666666667
35.4;2.20226;8.46388112399334;8.04545;0.935706666666667
35.5;2.20477;8.52570006059667;8.06818;0.940176666666667
35.6;2.20727666666667;8.58211185123;8.09090666666667;0.944033333333333
35.7;2.20977;8.64402502596333;8.11363666666667;0.94847
35.8;2.21226;8.70594131761;8.13636;0.95289
35.9;2.21475;8.76683047411667;8.15909;0.957173333333333
36;2.21723;8.82775561721667;8.18182;0.96144
36.1;2.2197;8.887170534;8.20454666666667;0.96552
36.2;2.22216;8.95096706278667;8.22727333333333;0.970056666666667
36.3;2.22462;9.01176437087;8.25;0.974243333333333
36.4;2.22708;9.07603345566667;8.27272666666667;0.978786666666667
36.5;2.22953;9.13766415508333;8.29545333333333;0.983026666666667
36.6;2.23197;9.19923224834667;8.31818;0.987233333333333
36.7;2.2344;9.26526125046667;8.34091;0.9919
36.8;2.23683;9.32698982545;8.36363666666667;0.996086666666667
36.9;2.23926;9.3905220198;8.38636333333333;1.00044333333333
37;2.24168;9.45604214557;8.40909;1.00499333333333
37.1;2.24409;9.51933491899333;8.43182;1.00928
37.2;2.2465;9.58543684267667;8.45454666666667;1.01384333333333
37.3;2.2489;9.64859908442333;8.47727;1.01808
37.4;2.25129;9.71486926992334;8.49999666666667;1.02261666666667
37.5;2.25368;9.77888095895667;8.52272666666667;1.0269
37.6;2.25606;9.84291348449667;8.54545;1.03116333333333
37.7;2.25844;9.91103500026333;8.56818;1.03583333333333
37.8;2.26082;9.97534089303333;8.59091;1.04008333333333
37.9;2.26318;10.0437136045267;8.61364;1.04473333333333
38;2.26554;10.1103811950667;8.63636666666667;1.04919
38.1;2.2679;10.1754767540967;8.65909;1.05346
38.2;2.27025;10.24425362021;8.68182;1.05809
38.3;2.27259;10.31527124533;8.70454;1.06293
38.4;2.27493;10.37947286764;8.72727;1.06705
38.5;2.27727;10.4492894654;8.75;1.07172
38.6;2.2796;10.5159011637433;8.77272666666667;1.07604666666667
38.7;2.28192;10.58808069649;8.79545333333333;1.08092
38.8;2.28424;10.65410862558;8.81818;1.08514333333333
38.9;2.28655;10.7235629609833;8.84091;1.08969333333333
39;2.28885;10.7946777142933;8.86364;1.09439
39.1;2.29116;10.86261277634;8.88636;1.09874333333333
39.2;2.29345;10.93393238287;8.90909;1.10342333333333
39.3;2.29574;11.0032039004867;8.93182;1.10787333333333
39.4;2.29803;11.07331535029;8.95454333333333;1.11238666666667
39.5;2.30031;11.1450748805867;8.97727;1.11704666666667
39.6;2.30258333333333;11.2183726402567;9;1.12183666666667
39.7;2.30486;11.2921594053633;9.02273;1.12665666666667
39.8;2.30712;11.35880580116;9.04545666666667;1.13074
39.9;2.30938;11.43206743232;9.06818333333333;1.13546666666667
40;2.31163333333333;11.5006385790567;9.09091;1.13970333333333
40.1;2.31388;11.57757642197;9.11364;1.14474666666667
40.2;2.31613;11.65008933136;9.13636;1.14933333333333
40.3;2.31837;11.7253614676467;9.15909;1.15417333333333
40.4;2.3206;11.7988289363;9.18182;1.15881333333333
40.5;2.32283;11.8711647278433;9.20454666666667;1.16332
40.6;2.32506;11.9447247499467;9.22727333333333;1.16793
40.7;2.32728;12.01852975774;9.25;1.17253666666667
40.8;2.32949;12.0975379014267;9.27272333333333;1.17764
40.9;2.3317;12.1713466246267;9.29545333333333;1.18220666666667
40.10;2.33391;12.2465013202033;9.31818;1.18688333333333
40.11;2.33611;12.3203045402967;9.34091;1.19141333333333
40.12;2.3383;12.3978161589133;9.36364;1.19628
40.13;2.34049;12.4729749495967;9.38636;1.20089666666667
40.14;2.34268;12.5490014084;9.40909;1.20558
40.15;2.34486;12.6293620494467;9.43182;1.21065666666667
40.16;2.34704;12.7054601126533;9.45454;1.21530333333333
40.17;2.34921;12.78211887421;9.47727333333333;1.21998666666667
40.18;2.35137666666667;12.8621051170533;9.5;1.22496333333333
40.19;2.35354;12.9377831935;9.52272666666667;1.22950666666667
40.20;2.35569;13.01634449675;9.54545;1.23430666666667
40.21;2.35785;13.0947829585367;9.56818;1.23907666666667
40.22;2.36;13.1735541523567;9.59091;1.24385333333333
40.23;2.36214;13.2538791259133;9.61363666666667;1.24876
40.24;2.36428;13.3334478834867;9.63636666666667;1.25357
40.25;2.36641;13.41412893083;9.65909;1.25846666666667
40.26;2.36854;13.4932965989567;9.68181666666667;1.26320333333333
40.27;2.37067;13.5767792887567;9.70454;1.26832
40.28;2.37279;13.6547694132167;9.72727;1.27290333333333
40.29;2.37491;13.7382072982833;9.75;1.27797333333333
40.30;2.37702;13.8190321863833;9.77272666666667;1.28277666666667
40.31;2.37912666666667;13.89615559768;9.79545666666667;1.28722333333333
40.32;2.38123;13.9813527491233;9.81818;1.29239333333333
40.33;2.38333;14.0678880074567;9.84091;1.29766666666667
40.34;2.38542;14.1485794862333;9.86364;1.30238
40.35;2.38751;14.2310812831533;9.88636;1.30724
40.36;2.3896;14.3141369826467;9.90909;1.31213
40.37;2.39168;14.39766919161;9.93181666666667;1.31704333333333
40.38;2.39375;14.48260048523;9.95454666666667;1.32206333333333
40.39;2.39583;14.56887571948;9.97727;1.32718333333333
40.40;2.3979;14.65011128945;10;1.33183
40.41;2.39996;14.7349852487933;10.0227266666667;1.33678
40.42;2.40202;14.8190728136267;10.0454533333333;1.34164333333333
40.43;2.40407;14.9040330906267;10.06818;1.34656666666667
40.44;2.40613;14.9892953656467;10.0909066666667;1.35149333333333
40.45;2.40817;15.0777101796467;10.11364;1.35668666666667
40.46;2.41022;15.1612063088633;10.13636;1.36141333333333
40.47;2.41225;15.2506804804867;10.15909;1.36666
40.48;2.41429;15.3407482834067;10.1818166666667;1.37193666666667
40.49;2.41632;15.4269301389833;10.2045466666667;1.37684666666667
40.50;2.41835;15.5081462408233;10.22727;1.38129333333333
40.51;2.42037;15.5988519539567;10.25;1.38656333333333
40.52;2.42239;15.6907470060367;10.27273;1.39192
40.53;2.4244;15.7777194247767;10.29545;1.39682
40.54;2.42641;15.8680411819567;10.31818;1.40199333333333
40.55;2.42842;15.9537819090567;10.3409066666667;1.40674666666667
40.56;2.43042;16.04209780957;10.3636366666667;1.41170333333333
40.57;2.43242;16.13522039515;10.38636;1.41706666666667
40.58;2.43441;16.2242786380633;10.40909;1.42204666666667
40.59;2.4364;16.3159040814033;10.43182;1.42723666666667
40.60;2.43839;16.4029693518367;10.4545466666667;1.43200666666667
40.61;2.44037;16.4949922911167;10.47727;1.43719
40.62;2.44235;16.58751670235;10.5;1.44239333333333
40.63;2.44432;16.6793835913367;10.5227266666667;1.44752
40.64;2.44629;16.7702080289267;10.54545;1.45253666666667
40.65;2.44826;16.8655760039033;10.56818;1.45793
40.66;2.45022;16.95367524253;10.59091;1.46267
40.67;2.45218;17.0480702483433;10.6136366666667;1.46793333333333
40.68;2.45413666666667;17.1408619653033;10.6363633333333;1.47304333333333
40.69;2.45609;17.2336855535733;10.65909;1.47813
40.70;2.45803;17.3289151708067;10.68182;1.48341
40.71;2.45998;17.41884275808;10.7045433333333;1.48821333333333
40.72;2.46192;17.5177457938767;10.72727;1.49376
40.73;2.46385;17.6109244710667;10.75;1.4988
40.74;2.46579;17.7041412826133;10.7727266666667;1.50382666666667
40.75;2.46771;17.7972880028733;10.7954533333333;1.50882666666667
40.76;2.46964;17.89743572889;10.81818;1.5144
40.77;2.47156;17.9975010058;10.84091;1.51994
40.78;2.47348;18.0861862728633;10.86364;1.52450666666667
40.79;2.47539;18.18631268741;10.8863633333333;1.53001333333333
40.80;2.4773;18.2836187188967;10.90909;1.53527
40.81;2.47921;18.3754522288167;10.9318166666667;1.54003666666667
40.82;2.48111;18.4747191586933;10.9545433333333;1.54541333333333
40.83;2.48301;18.5780543201733;10.97727;1.55111
40.84;2.48491;18.6727932584133;11;1.55606666666667
40.85;2.4868;18.7715706474433;11.02273;1.56134333333333
40.86;2.48869;18.8680337810567;11.0454566666667;1.56640333333333
40.87;2.49057;18.9667963903233;11.06818;1.57164
40.88;2.49245;19.0678519161;11.09091;1.57704
40.89;2.49433;19.16771301159;11.1136366666667;1.58232666666667
40.90;2.49621;19.26821261165;11.13636;1.58764333333333
40.91;2.49808;19.36485570542;11.15909;1.59262333333333
40.92;2.49994;19.4693174079933;11.18182;1.59822666666667
40.93;2.50181;19.5689955718233;11.2045466666667;1.60342
40.94;2.50367;19.67021759432;11.22727;1.60871666666667
40.95;2.50553;19.7723035600267;11.25;1.61406666666667
40.96;2.50738;19.8712794315133;11.27273;1.61914
40.97;2.50923;19.97282955054;11.29545;1.62440666666667
40.98;2.51108;20.0778030979167;11.3181833333333;1.62993333333333
40.99;2.51292;20.1780705048633;11.34091;1.63505333333333
40.100;2.51476;20.2762580803433;11.3636333333333;1.63999
40.101;2.5166;20.38435632064;11.38636;1.64571
40.102;2.51843;20.48950703315;11.40909;1.65117
40.103;2.52026;20.59184378294;11.4318166666667;1.65638333333333
40.104;2.52209;20.6966210251767;11.45455;1.66177
40.105;2.52391;20.79800011536;11.4772766666667;1.66687
40.106;2.52573;20.90275967853;11.5;1.67222
40.107;2.52754333333333;21.00875508365;11.52273;1.67764666666667
40.108;2.52936;21.1160762997733;11.54545;1.68316666666667
40.109;2.53117;21.21961161602;11.56818;1.68835666666667
40.110;2.53297666666667;21.3239894777333;11.59091;1.69360333333333
40.111;2.53478;21.4297390350867;11.61364;1.69893333333333
40.112;2.53658;21.5374100761567;11.6363666666667;1.7044
40.113;2.53838;21.64428567525;11.65909;1.70978
40.114;2.54017;21.7552884194833;11.68182;1.71547
40.115;2.54196;21.86277117837;11.70454;1.72086333333333
40.116;2.54375;21.9666045360933;11.72727;1.72595
40.117;2.54553;22.0792988104767;11.75;1.73171333333333
40.118;2.54731;22.1851203363633;11.7727266666667;1.73691333333333
40.119;2.54909;22.2917334548933;11.7954533333333;1.74216333333333
40.120;2.55086;22.4038445830033;11.81818;1.74781666666667
40.121;2.55264;22.5140259164567;11.8409066666667;1.75330333333333
40.122;2.5544;22.6218383118567;11.8636366666667;1.75859
40.123;2.55617;22.73616351434;11.8863666666667;1.76436
40.124;2.55793;22.8457774968433;11.90909;1.76974333333333
40.125;2.55969;22.9527281597933;11.93182;1.77490333333333
40.126;2.56145;23.0659060298667;11.9545466666667;1.78052666666667
40.127;2.5632;23.1799957001033;11.97727;1.7862
40.128;2.56495;23.2878380857233;12;1.79137333333333
40.129;2.5667;23.40118203318;12.0227266666667;1.79694666666667
40.130;2.56844;23.5116453343;12.0454566666667;1.80228666666667
40.131;2.57018;23.6224307934067;12.06818;1.80762666666667
40.132;2.57192;23.7378680731;12.09091;1.81331
40.133;2.57365;23.8525034392133;12.1136366666667;1.81890666666667
40.134;2.57538;23.96359753518;12.13636;1.82422
40.135;2.57711;24.08077477561;12.15909;1.82997333333333
40.136;2.57884;24.19261000878;12.18182;1.83530333333333
40.137;2.58056;24.30566417776;12.2045466666667;1.84070333333333
40.138;2.58228;24.4196244018333;12.22727;1.84615666666667
40.139;2.584;24.5369167332567;12.25;1.85184
40.140;2.58571;24.6548372859733;12.27273;1.85755666666667
40.141;2.58742;24.7707498984367;12.29545;1.8631
40.142;2.58913;24.8867417872433;12.31818;1.86863
40.143;2.59083666666667;25.00294682228;12.34091;1.87415666666667
40.144;2.59254;25.118102414;12.3636366666667;1.87958666666667
40.145;2.59424;25.23751946834;12.38636;1.88531666666667
40.146;2.59593;25.3503028665267;12.40909;1.89053333333333
40.147;2.59763;25.4702344581367;12.43182;1.89626333333333
40.148;2.59932;25.5878614302533;12.4545466666667;1.9018
40.149;2.601;25.7022599755333;12.47727;1.90708333333333
40.150;2.60269;25.8215723005067;12.4999966666667;1.91271
40.151;2.60437;25.9411674492133;12.52273;1.91834
40.152;2.60605;26.06185545688;12.54545;1.92403
40.153;2.60773;26.1771663508967;12.56818;1.92930333333333
40.154;2.6094;26.2993706008567;12.59091;1.93507333333333
40.155;2.61107;26.41890517574;12.6136366666667;1.94062
40.156;2.61274;26.53660948017;12.63636;1.94602
40.157;2.61441;26.6586957806;12.65909;1.95171666666667
40.158;2.61607;26.78300725647;12.6818166666667;1.95756333333333
40.159;2.61773;26.90492433556;12.7045433333333;1.96321333333333
40.160;2.61938;27.02590375463;12.72727;1.96877666666667
40.161;2.62104;27.14003384101;12.75;1.97382333333333
40.162;2.62269;27.2656710897067;12.7727266666667;1.97968333333333
40.163;2.62434;27.3880479361267;12.79545;1.98529666666667
40.164;2.62599;27.51381968518;12.81818;1.99113333333333
40.165;2.62763;27.6315880851233;12.84091;1.99637
40.166;2.62927;27.7390135310667;12.86364;2.00084666666667
40.167;2.63091;27.86495251492;12.8863666666667;2.00664
40.168;2.63254;27.9807926735667;12.9090866666667;2.01169333333333
40.169;2.63418;28.0941055123967;12.93182;2.01654333333333
40.170;2.63580666666667;28.20127939362;12.9545433333333;2.02094
40.171;2.63743;28.3183969777533;12.97727;2.02603333333333
40.172;2.63906;28.4509779235133;13;2.03221
40.173;2.64068;28.5770319854167;13.02273;2.03791
40.174;2.6423;28.7090371756233;13.0454533333333;2.04401
40.175;2.64392;28.8398662134233;13.06818;2.05000666666667
40.176;2.64553;28.9709828490367;13.09091;2.05600333333333
40.177;2.64714;29.09860912476;13.1136366666667;2.06173666666667
40.178;2.64875;29.2068606309867;13.13636;2.06608
40.179;2.65036;29.3382029571333;13.15909;2.07204
40.180;2.65196;29.4752351483733;13.1818166666667;2.07838333333333
40.181;2.65356;29.6032347297833;13.2045433333333;2.08407
40.182;2.65516;29.7388053078733;13.22727;2.09026666666667
40.183;2.65676;29.8724532644733;13.25;2.09631
40.184;2.65835;29.99939081591;13.27273;2.10186666666667
40.185;2.65994;30.1286791925533;13.2954566666667;2.10757
40.186;2.66153;30.2606121177267;13.3181833333333;2.11344
40.187;2.66312;30.3927574425033;13.3409066666667;2.11930666666667
40.188;2.6647;30.5251292978633;13.3636333333333;2.12516666666667
40.189;2.66628;30.6519345856067;13.38636;2.13062333333333
40.190;2.66786;30.7727099113033;13.40909;2.13564666666667
40.191;2.66944;30.90234544064;13.43182;2.14126666666667
40.192;2.67101;31.0362952946333;13.4545466666667;2.14716666666667
40.193;2.67258;31.17119256344;13.47727;2.15311
40.194;2.67415;31.3029711234867;13.5;2.15882666666667
40.195;2.67571;31.43623696097;13.52273;2.16462333333333
40.196;2.67728;31.5647235978833;13.54545;2.17007333333333
40.197;2.67884;31.70264285765;13.56818;2.17615666666667
40.198;2.6804;31.8337649718667;13.59091;2.18175333333333
40.199;2.68195666666667;31.96981179337;13.6136366666667;2.18767
40.200;2.68351;32.10326277566;13.6363633333333;2.19339
40.201;2.68506;32.2383420279333;13.65909;2.19920666666667
40.202;2.68661;32.3728642499833;13.6818133333333;2.20496333333333
40.203;2.68816;32.5122674843;13.7045466666667;2.21103333333333
40.204;2.6897;32.64435320597;13.7272733333333;2.21659
40.205;2.69124;32.77889765791;13.75;2.2223
40.206;2.69278;32.9132173655233;13.7727266666667;2.22797
40.207;2.69432;33.0488193077367;13.79545;2.23371666666667
40.208;2.69585;33.18816676688;13.81818;2.23969666666667
40.209;2.69739;33.32346691624;13.84091;2.24538
40.210;2.69892;33.4623251112867;13.8636366666667;2.25128666666667
40.211;2.70045;33.5976762226133;13.8863633333333;2.25694666666667
40.212;2.70197;33.7344785357433;13.90909;2.26268
40.213;2.70349;33.87093038545;13.9318166666667;2.26837333333333
40.214;2.70502;34.0088515844;13.9545433333333;2.27414666666667
40.215;2.70653;34.1571139590633;13.97727;2.28059666666667
40.216;2.70805;34.2827271327033;14;2.28551333333333
40.217;2.70956;34.4245114190533;14.02273;2.29149333333333
40.218;2.71108;34.5679010657533;14.0454566666667;2.29756
40.219;2.71259;34.7008474112033;14.0681833333333;2.30292
40.220;2.71409;34.84628257463;14.09091;2.30909333333333
40.221;2.7156;34.9828293246067;14.1136333333333;2.31465333333333
40.222;2.7171;35.1239098097367;14.13636;2.32049666666667
40.223;2.7186;35.2685151566433;14.15909;2.32655666666667
40.224;2.7201;35.4036563324967;14.1818166666667;2.33197666666667
40.225;2.72159;35.5459306531133;14.2045466666667;2.33785
40.226;2.72309;35.68351984399;14.22727;2.34339333333333
40.227;2.72458;35.8353785011;14.25;2.34986
40.228;2.72607;35.9722139358433;14.27273;2.35532333333333
40.229;2.72756;36.1168798829;14.29545;2.36128
40.230;2.72904;36.2619195081967;14.31818;2.36725
40.231;2.73052;36.3985172866833;14.3409066666667;2.37264333333333
40.232;2.732;36.5402812735333;14.3636366666667;2.37836
40.233;2.73348;36.68531791666;14.3863633333333;2.38427333333333
40.234;2.73496;36.8274698496567;14.40909;2.38998
40.235;2.73643;36.97403396548;14.43182;2.39596
40.236;2.7379;37.1177095962733;14.4545466666667;2.40173333333333
40.237;2.73937;37.2656682124667;14.4772733333333;2.40776666666667
40.238;2.74084;37.4097948554633;14.5;2.41353666666667
40.239;2.74230666666667;37.55404877511;14.5227266666667;2.41929333333333
40.240;2.74377;37.7041280418433;14.5454533333333;2.42541333333333
40.241;2.74523;37.84646556153;14.56818;2.43101333333333
40.242;2.74669;37.9911153624933;14.59091;2.43674666666667
40.243;2.74814;38.13634699715;14.6136366666667;2.4425
40.244;2.7496;38.2852590583733;14.63636;2.44847666666667
40.245;2.75105;38.43328568521;14.65909;2.45437333333333
40.246;2.7525;38.5785176265867;14.68182;2.46007666666667
40.247;2.75395;38.7285934888567;14.70455;2.46607333333333
40.248;2.7554;38.8749846905767;14.72727;2.47182
40.249;2.75684;39.0227171704167;14.7499966666667;2.47763333333333
40.250;2.75828;39.16951093291;14.7727266666667;2.48336666666667
40.251;2.75972;39.32024168233;14.7954533333333;2.48934
40.252;2.76116;39.47079515087;14.81818;2.49528
40.253;2.7626;39.6205473961167;14.84091;2.50115333333333
40.254;2.76403;39.76788892428;14.8636366666667;2.50685666666667
40.255;2.76546;39.91445830834;14.8863633333333;2.5125
40.256;2.76689;40.0600899780333;14.90909;2.51806
40.257;2.76832;40.2111263062333;14.9318166666667;2.52395
40.258;2.76974;40.3630987687667;14.9545466666667;2.52988
40.259;2.77117;40.5165593470367;14.9772733333333;2.53588666666667
40.260;2.77259;40.6597350958167;15;2.54123333333333
40.261;2.77401;40.81257674237;15.02273;2.54716666666667
40.262;2.77543;40.9626012011133;15.0454533333333;2.55291333333333
40.263;2.77684;41.1143564045833;15.06818;2.55874333333333
40.264;2.77825;41.26299117075;15.09091;2.56436666666667
40.265;2.77967;41.41735832311;15.1136366666667;2.57033
40.266;2.78108;41.5578741506167;15.13636;2.57541666666667
40.267;2.78248;41.7075450703467;15.15909;2.58105666666667
40.268;2.78389;42.071963860335;15.181815;2.599955
40.269;2.78529;42.170913443725;15.204545;2.60241
40.270;2.78669;42.284728104575;15.22727;2.605785
40.271;2.78809;42.438378878295;15.25;2.611595
40.272;2.78949;42.599902145195;15.27273;2.61787
40.273;2.79089;42.76252358599;15.295455;2.6242
40.274;2.79228;42.928170706405;15.31818;2.630695
40.275;2.79367;43.08856632657;15.340905;2.63685
40.276;2.79506;43.25191600928;15.363635;2.643175
40.277;2.79645;43.41088918477;15.38636;2.64921
40.278;2.79784;43.576253330825;15.40909;2.655615
40.279;2.79922;43.74080832052;15.43182;2.66196
40.280;2.8006;43.89899160259;15.454545;2.667895
40.281;2.80198;44.05795609974;15.47727;2.673865
40.282;2.80336;44.221191173615;15.5;2.68007
40.283;2.80474;44.39043396777;15.522725;2.686625
40.284;2.80611;44.548052133425;15.54545;2.692465
40.285;2.80748;44.709644768615;15.56818;2.69852
40.286;2.808855;44.86757367103;15.59091;2.704345
40.287;2.81022;45.0291990692;15.613635;2.710375
40.288;2.81159;45.19065358343;15.63636;2.71638
40.289;2.81296;45.355719918645;15.65909;2.722585
40.290;2.81432;45.514749974085;15.68182;2.7284
40.291;2.81568;45.674592578075;15.70455;2.73426
40.292;2.81704;45.845282008335;15.727275;2.74075
40.293;2.8184;46.001063682345;15.75;2.746335
40.294;2.81975;46.172285121235;15.772725;2.75282
40.295;2.82111;46.32959236497;15.79545;2.75846
40.296;2.82246;46.49463166946;15.81818;2.764545
40.297;2.82381;46.65026185145;15.84091;2.770055
40.298;2.82516;46.82032769796;15.86364;2.776405
40.299;2.82651;46.98136668302;15.88636;2.78221
40.300;2.82785;47.146766860805;15.90909;2.78825
40.301;2.82919;47.31020124319;15.931815;2.79416
40.302;2.83054;47.473848124105;15.954545;2.80007
40.303;2.83188;47.642685765775;15.97727;2.80626
40.304;2.83321;47.79981933304;16;2.811755
40.305;2.83455;47.96394048878;16.022725;2.81764
40.306;2.83588;48.12504876462;16.045455;2.823335
40.307;2.83722;48.29577668242;16.06818;2.82958
40.308;2.83855;48.46177254531;16.09091;2.83553
40.309;2.83988;48.624849253135;16.11363;2.841295
40.310;2.8412;48.791607763675;16.13636;2.847255
40.311;2.84253;48.948555832035;16.159095;2.85263
40.312;2.84385;49.12134819216;16.18182;2.85891
40.313;2.84517;49.286798258895;16.204545;2.864755
40.314;2.84649;49.45566086653;16.22727;2.87078
40.315;2.84781;49.617116057455;16.25;2.876355
40.316;2.84913;49.77138017056;16.27273;2.8815
40.317;2.85044;49.89943970098;16.295455;2.88512
40.318;2.85176;50.042908473235;16.31818;2.88962
40.319;2.85307;50.15319724584;16.34091;2.89219
40.320;2.85438;50.32017863719;16.36364;2.89802
40.321;2.85569;50.47018599473;16.38636;2.90286
40.322;2.85699;50.61465375203;16.40909;2.90737
40.323;2.8583;50.75441476705;16.43182;2.9116
40.324;2.8596;50.89439449013;16.45454;2.91583
40.325;2.8609;51.05333759263;16.47727;2.92113