File: data/materialdata/Ecoflex0035FAST.csv
PARAMETER;INFO;URL;;
Specimen Thickness (mm);3;;;
Specimen Width (mm);6;;;
Specimen Length (mm);33;;;
Specimen Cross-section (cm^2);0.18;;;
Standard;ASTM D412;;;
Type of test;Pull-to-failure;;;
Speed (mm/min);450;;;
Machine;Instron  5569;;;
Load Cell;1 kN - Instron  2525-806;;;
Grippers;Instron 2710-010 ;;;
Strain Measurement;Global;;;
Strain calculation;Derived from the machine crosshead displacement readings;;;
Lab;Univ. Savoie Mont Blanc - SYMME Lab, 7400 Annecy, France;;;
Material supplier;Smooth-On;https://www.smooth-on.com/products/ecoflex-00-35/;;
Material;EcoFlex35 FAST;;;
;;;;
Time (s);True Strain;True Stress (MPa);Engineering Strain;Engineering Stress (MPa)
0.3;0.06575;0.00252378866666667;0.06796;0.00236666666666667
0.4;0.08695;0.00726588426666667;0.09084;0.00666
0.5;0.107616666666667;0.00716893603333333;0.11362;0.00644
0.6;0.12783;0.0111708305333333;0.13636;0.00983
0.7;0.147636666666667;0.0118158434333333;0.15909;0.0101933333333333
0.8;0.167056666666667;0.0141509659666667;0.18182;0.01197
0.9;0.1861;0.0155132474;0.20455;0.01288
1;0.20479;0.0180482107;0.22727;0.0147066666666667
1.1;0.223143333333333;0.0198555418;0.25;0.0158866666666667
1.2;0.24116;0.0218524296;0.27273;0.01717
1.3;0.25886;0.0235392032;0.295456666666667;0.01817
1.4;0.27625;0.0263739361333333;0.31818;0.0200066666666667
1.5;0.29335;0.0288617592333333;0.34091;0.0215233333333333
1.6;0.310153333333333;0.0307142561666667;0.363636666666667;0.0225233333333333
1.7;0.32668;0.0328207722666667;0.38636;0.0236733333333333
1.8;0.342943333333333;0.0351194225666667;0.40909;0.0249233333333333
1.9;0.358946666666667;0.0371318303;0.43182;0.0259333333333333
2;0.374693333333333;0.0392697048333333;0.45455;0.0269966666666667
2.1;0.3902;0.0425169007;0.47727;0.0287833333333333
2.2;0.40547;0.0444250268;0.5;0.0296166666666667
2.3;0.4205;0.0468026024333333;0.522726666666667;0.03074
2.4;0.43532;0.0492647111;0.545453333333333;0.0318766666666667
2.5;0.44992;0.0523174290333333;0.56818;0.0333633333333333
2.6;0.46431;0.0549052426333333;0.59091;0.0345133333333333
2.7;0.47849;0.0568452907333333;0.61364;0.0352266666666667
2.8;0.49248;0.059681336;0.636363333333333;0.0364733333333333
2.9;0.50627;0.0625626467333333;0.65909;0.03771
3;0.519873333333333;0.0655024808333333;0.681816666666667;0.03895
3.1;0.5333;0.0678948707333333;0.70455;0.0398333333333333
3.2;0.54654;0.0713132813333333;0.72727;0.0412866666666667
3.3;0.55962;0.0737990300333333;0.75;0.04217
3.4;0.57252;0.0768892108666667;0.77273;0.04337
3.5;0.58526;0.0804413697666667;0.795453333333333;0.0448033333333333
3.6;0.59784;0.0832132461;0.818183333333333;0.04577
3.7;0.61026;0.0861799609666667;0.84091;0.04681
3.8;0.62253;0.0892862360666667;0.86364;0.0479066666666667
3.9;0.63465;0.0928079424;0.886363333333333;0.0492033333333333
4;0.64663;0.0953852826;0.90909;0.0499633333333333
4.1;0.65846;0.0998676632333333;0.93182;0.0516966666666667
4.2;0.67016;0.102631381933333;0.954543333333333;0.05251
4.3;0.68172;0.1061034279;0.977273333333333;0.0536633333333333
4.4;0.69315;0.1099766846;1;0.0549866666666667
4.5;0.70445;0.113491709666667;1.02273;0.05611
4.6;0.71562;0.117505259433333;1.04545333333333;0.0574466666666667
4.7;0.72667;0.120391500766667;1.06818333333333;0.05821
4.8;0.7376;0.124277878266667;1.09091;0.0594366666666667
4.9;0.74841;0.128221447;1.11363666666667;0.0606633333333333
5;0.759103333333333;0.1322321665;1.13636333333333;0.0619
5.1;0.76969;0.136635613066667;1.15909;0.06328
5.2;0.78016;0.1405746546;1.18182;0.0644266666666667
5.3;0.79052;0.1450517605;1.20454666666667;0.0657966666666667
5.4;0.80078;0.149413111066667;1.22727333333333;0.0670833333333333
5.5;0.81093;0.1534052075;1.25;0.06818
5.6;0.82098;0.158834667233333;1.27273;0.0698866666666667
5.7;0.83093;0.162934915366667;1.29545;0.07098
5.8;0.84078;0.1673975341;1.31818;0.0722066666666667
5.9;0.85054;0.1720749258;1.34091;0.0735066666666667
6;0.8602;0.1774468617;1.36363666666667;0.0750766666666667
6.1;0.86977;0.182659124633333;1.38636333333333;0.0765466666666667
6.2;0.87925;0.1873994093;1.40909333333333;0.07779
6.3;0.88864;0.1922416852;1.43182;0.0790533333333333
6.4;0.89794;0.198196454333333;1.45455;0.0807466666666667
6.5;0.90716;0.202976732766667;1.47727333333333;0.0819366666666667
6.6;0.91629;0.2092167634;1.5;0.0836866666666666
6.7;0.92534;0.214406986366667;1.52272666666667;0.08499
6.8;0.93431;0.219995849666667;1.54545333333333;0.0864266666666667
6.9;0.9432;0.225616495033333;1.56818333333333;0.0878533333333333
7;0.95201;0.232266412233333;1.59091;0.0896466666666667
7.1;0.96074;0.2394397447;1.61364;0.09161
7.2;0.9694;0.243678668866667;1.63636333333333;0.09243
7.3;0.977983333333333;0.250221677766667;1.65909;0.0941
7.4;0.986493333333333;0.255892045233333;1.68182;0.0954133333333333
7.5;0.994933333333333;0.263341419133333;1.70454666666667;0.0973733333333333
7.6;1.0033;0.2691301982;1.72727;0.0986833333333333
7.7;1.0116;0.274934864933333;1.75;0.0999766666666667
7.8;1.01983;0.280304058133333;1.77273;0.101093333333333
7.9;1.02799666666667;0.286832452166667;1.79545666666667;0.10261
8;1.03609;0.29444584;1.81818333333333;0.10448
8.1;1.04412333333333;0.3008378106;1.84091;0.105896666666667
8.2;1.05209;0.3076150499;1.86364;0.10742
8.3;1.06;0.314541590266667;1.88636666666667;0.108976666666667
8.4;1.06784;0.3207526387;1.90909;0.11026
8.5;1.07562;0.327186543066667;1.93181666666667;0.1116
8.6;1.08334333333333;0.335509268033333;1.95454666666667;0.11356
8.7;1.09101;0.342538410933333;1.97727333333333;0.11505
8.8;1.09861;0.350040588933333;2.00000333333333;0.116683333333333
8.9;1.10616;0.357995042533333;2.02272666666667;0.118436666666667
9;1.11365;0.3654942967;2.04545333333333;0.120013333333333
9.1;1.12108333333333;0.373368679966667;2.06818;0.121693333333333
9.2;1.12846666666667;0.379520520533333;2.09090666666667;0.122783333333333
9.3;1.13579;0.388156534766667;2.11363666666667;0.124666666666667
9.4;1.14306333333333;0.396452588633333;2.13636333333333;0.126406666666667
9.5;1.15028;0.403913691033333;2.15909;0.12786
9.6;1.15745;0.414072468333333;2.18182;0.130136666666667
9.7;1.16457;0.420571854966667;2.20454666666667;0.131243333333333
9.8;1.17164;0.4302375846;2.22727;0.133313333333333
9.9;1.17865666666667;0.438202180233333;2.25;0.13483
10;1.18562;0.446789122666667;2.27273;0.13652
10.1;1.19254333333333;0.456122516466667;2.29546;0.13841
10.2;1.19942;0.464148665866667;2.31818333333333;0.139876666666667
10.3;1.20624;0.472904918333333;2.34091;0.141553333333333
10.4;1.21302;0.483003079333333;2.36363666666667;0.143596666666667
10.5;1.21975666666667;0.492262637766667;2.38636333333333;0.145366666666667
10.6;1.22644666666667;0.501289371833333;2.40909333333333;0.147046666666667
10.7;1.23309;0.510457584833333;2.43182;0.148743333333333
10.8;1.23969;0.520571959;2.45455;0.150693333333333
10.9;1.24625;0.5305153106;2.47727;0.152563333333333
11;1.25276;0.539618151533333;2.5;0.15418
11.1;1.25923666666667;0.550170901333333;2.52272666666667;0.156176666666667
11.2;1.26567;0.559764446633333;2.54545333333333;0.157883333333333
11.3;1.27206;0.5701881335;2.56818;0.159796666666667
11.4;1.27841;0.580680431466667;2.59091;0.161706666666667
11.5;1.28471666666667;0.592092838166667;2.61364;0.163853333333333
11.6;1.29098;0.6033993086;2.63636333333333;0.165933333333333
11.7;1.29721333333333;0.613468757066667;2.65909;0.167653333333333
11.8;1.30341;0.622144945833333;2.68182;0.168976666666667
11.9;1.30956;0.634395764966667;2.70454333333333;0.171246666666667
12;1.31568;0.645121910666667;2.72727333333333;0.17308
12.1;1.32176;0.657059055933333;2.75;0.175213333333333
12.2;1.3278;0.667331566033333;2.77273;0.17688
12.3;1.3338;0.679641470966667;2.79545;0.179066666666667
12.4;1.33977333333333;0.692090653366667;2.81818333333333;0.18126
12.5;1.34571;0.702908767966667;2.84091;0.183006666666667
12.6;1.35161;0.714801136266667;2.86364;0.18501
12.7;1.35747;0.726561197166667;2.88636333333333;0.18695
12.8;1.36330666666667;0.738719752866667;2.90909;0.188976666666667
12.9;1.3691;0.752297400766667;2.93182;0.191333333333333
13;1.37486666666667;0.7640257703;2.95454333333333;0.193203333333333
13.1;1.3806;0.777700018333333;2.97727333333333;0.195536666666667
13.2;1.38629;0.7898241834;3;0.197456666666667
13.3;1.39196;0.802747750633333;3.02273;0.19955
13.4;1.39759;0.8151759773;3.04545333333333;0.201506666666667
13.5;1.4032;0.829333380233333;3.06818;0.203856666666667
13.6;1.40877;0.843442705333333;3.09090666666667;0.206176666666667
13.7;1.41431;0.854810744733333;3.11363333333333;0.207803333333333
13.8;1.41982;0.8703548063;3.13636333333333;0.210416666666667
13.9;1.4253;0.884069363733333;3.15909;0.212563333333333
14;1.43075;0.897634238433333;3.18182;0.214653333333333
14.1;1.43617;0.913545278233333;3.20454666666667;0.217276666666667
14.2;1.44156;0.926080369533333;3.22727333333333;0.219076666666667
14.3;1.44692;0.940810014766667;3.25000333333333;0.221366666666667
14.4;1.45225;0.9558559038;3.27273;0.22371
14.5;1.45756;0.969603206033333;3.29545333333333;0.22573
14.6;1.46283333333333;0.985234901833333;3.31818;0.22816
14.7;1.46808;1.00015976363333;3.34091;0.230403333333333
14.8;1.47331;1.0146393776;3.36363666666667;0.232523333333333
14.9;1.4785;1.02985686906667;3.38636333333333;0.234786666666667
15;1.48367;1.04773714836667;3.40909;0.23763
15.1;1.48881;1.0609056639;3.43182;0.239383333333333
15.2;1.49392333333333;1.07747522586667;3.45455;0.241883333333333
15.3;1.49901;1.09349657163333;3.47727333333333;0.244233333333333
15.4;1.50408;1.10983790636667;3.5;0.24663
15.5;1.50911666666667;1.12720213986667;3.52272666666667;0.24923
15.6;1.51413;1.1452340739;3.54545666666667;0.25195
15.7;1.51911666666667;1.1594897158;3.56818;0.253816666666667
15.8;1.52408;1.17743227526667;3.59091;0.25647
15.9;1.52902;1.19474946046667;3.61364;0.25896
16;1.53393;1.2105496643;3.63636333333333;0.2611
16.1;1.53882;1.2291506403;3.65909;0.26382
16.2;1.54369;1.24741396386667;3.68181666666667;0.266436666666667
16.3;1.54853;1.26466138276667;3.70454666666667;0.268816666666667
16.4;1.55335;1.28206426713333;3.72727;0.271206666666667
16.5;1.55814333333333;1.3001560884;3.75;0.273716666666667
16.6;1.56292;1.32126539973333;3.77272333333333;0.276836666666667
16.7;1.56767;1.33612038503333;3.79545666666667;0.27862
16.8;1.5724;1.35569953886667;3.81818333333333;0.28137
16.9;1.5771;1.37646427423333;3.84091;0.28434
17;1.58179;1.39366944386667;3.86364;0.28655
17.1;1.58645;1.4145753853;3.88636333333333;0.289493333333333
17.2;1.59109;1.43303899126667;3.90909;0.291916666666667
17.3;1.59571;1.45295665263333;3.93182;0.29461
17.4;1.60030666666667;1.47242272146667;3.95454333333333;0.297183333333333
17.5;1.60488;1.4920950082;3.97727333333333;0.29978
17.6;1.60944;1.51287475503333;4;0.302576666666667
17.7;1.61397;1.53292338623333;4.02273;0.305193333333333
17.8;1.61849;1.55345352836667;4.04545666666667;0.307893333333333
17.9;1.62298;1.57444950953333;4.06818;0.310653333333333
18;1.62746;1.59625790073333;4.09090666666667;0.31355
18.1;1.63191;1.61774825333333;4.11364;0.31636
18.2;1.63634666666667;1.64119344676667;4.13636333333333;0.319526666666667
18.3;1.64076;1.65964413963333;4.15909;0.32169
18.4;1.64516;1.68255005033333;4.18182;0.324703333333333
18.5;1.64953;1.7051682744;4.20454333333333;0.32763
18.6;1.65389;1.72829429603333;4.22727333333333;0.33063
18.7;1.65823;1.7496608987;4.25;0.333266666666667
18.8;1.66255;1.77232931626667;4.27273;0.336133333333333
18.9;1.66685;1.795513644;4.29545666666667;0.339066666666667
19;1.67113;1.8173900061;4.31818;0.341733333333333
19.1;1.6754;1.84326910836667;4.34090666666667;0.34512
19.2;1.67964;1.8664040402;4.36363666666667;0.347973333333333
19.3;1.68387;1.88992178596667;4.38636333333333;0.35087
19.4;1.68808;1.91336126453333;4.40909333333333;0.35373
19.5;1.69227;1.93674420213333;4.43182;0.356553333333333
19.6;1.69645;1.96305509083333;4.45455;0.359893333333333
19.7;1.70061;1.98621669466667;4.47727;0.362626666666667
19.8;1.70475;2.00979572933333;4.5;0.36542
19.9;1.70887;2.03613279593333;4.52272666666667;0.368686666666667
20;1.71298;2.05925232336667;4.54545333333333;0.37134
20.1;1.71707;2.086697619;4.56818;0.37475
20.2;1.72114;2.111513156;4.59091;0.37767
20.3;1.7252;2.137623157;4.61364;0.38079
20.4;1.72924;2.165240877;4.63636;0.38416
20.5;1.73326;2.188122082;4.65909;0.38666
20.6;1.73727;2.219878736;4.68182;0.3907
20.7;1.74126;2.242751692;4.70455;0.39315
20.8;1.74524;2.269186948;4.72727;0.39621
20.9;1.7492;2.297233024;4.75;0.39952
21;1.75314;2.324940953;4.77272;0.40275
21.1;1.75707;2.355601474;4.79545;0.40646
21.2;1.76099;2.384015569;4.81818;0.40975
21.3;1.76489;2.411734875;4.84091;0.4129
21.4;1.76877;2.438226856;4.86364;0.41582
21.5;1.77264;2.464726058;4.88636;0.41872
21.6;1.77649;2.496097359;4.90909;0.42242
21.7;1.78033;2.525204437;4.93182;0.42571
21.8;1.78415;2.553562031;4.95454;0.42884
21.9;1.78796;2.5832606;4.97727;0.43218
22;1.79176;2.613238422;5;0.43554
22.1;1.79554;2.646030019;5.02273;0.43934
22.2;1.79931;2.671106023;5.04545;0.44184
22.3;1.80306;2.703027847;5.06818;0.44544
22.4;1.8068;2.734998223;5.09091;0.44903
22.5;1.81052;2.770111627;5.11363;0.4531
22.6;1.81423;2.801898356;5.13636;0.45661
22.7;1.81793;2.829369574;5.15909;0.45938
22.8;1.82161;2.85931687;5.18182;0.46254
22.9;1.82528;2.892785439;5.20454;0.46624
23;1.82894;2.929661398;5.22727;0.47046
23.1;1.83258;2.961288141;5.25;0.47381
23.2;1.83621;2.9927142;5.27273;0.4771
23.3;1.83983;3.025454981;5.29546;0.48058
23.4;1.84343;3.058299434;5.31818;0.48405
23.5;1.84702;3.094190452;5.34091;0.48797
23.6;1.8506;3.129336416;5.36363;0.49175
23.7;1.85416;3.158750985;5.38636;0.49461
23.8;1.85772;3.198262466;5.40909;0.49902
23.9;1.86126;3.230995417;5.43182;0.50235
24;1.86478;3.264158781;5.45454;0.50571
24.1;1.8683;3.302611466;5.47727;0.50988
24.2;1.8718;3.337684744;5.5;0.51349
24.3;1.87529;3.371433354;5.52272;0.51688
24.4;1.87877;3.408980776;5.54545;0.52082
24.5;1.88224;3.446038251;5.56818;0.52466
24.6;1.88569;3.481233977;5.59091;0.52819
24.7;1.88913;3.518643167;5.61363;0.53203
24.8;1.89256;3.55759983;5.63636;0.53608
24.9;1.89598;3.594316852;5.65909;0.53976
25;1.89939;3.631294137;5.68182;0.54346
25.1;1.90279;3.674090194;5.70454;0.548
25.2;1.90617;3.710741385;5.72727;0.5516
25.3;1.90954;3.747351795;5.75;0.55516
25.4;1.9129;3.787638559;5.77272;0.55925
25.5;1.91625;3.827198275;5.79545;0.5632
25.6;1.91959;3.870571197;5.81818;0.56768
25.7;1.92292;3.904291865;5.84091;0.57073
25.8;1.92624;3.943844163;5.86363;0.5746
25.9;1.92954;3.985792772;5.88636;0.5788
26;1.93284;4.026640477;5.90909;0.5828
26.1;1.93612;4.07248568;5.93182;0.58751
26.2;1.9394;4.111692963;5.95455;0.59122
26.3;1.94266;4.146276796;5.97727;0.59425
26.4;1.94591;4.190310323;6;0.59862
26.5;1.94915;4.238192755;6.02273;0.6035
26.6;1.95238;4.281039905;6.04545;0.60763
26.7;1.9556;4.318246762;6.06818;0.61094
26.8;1.95881;4.360743901;6.09091;0.61498
26.9;1.96201;4.407291554;6.11364;0.61956
27;1.9652;4.450370359;6.13636;0.62362
27.1;1.96838;4.49357223;6.15909;0.62767
27.2;1.97155;4.535121712;6.18182;0.63147
27.3;1.97471;4.573985847;6.20454;0.63488
24.4;1.97786;4.618178134;6.22727;0.63899