File: data/materialdata/Ecoflex0010.csv
PARAMETER;INFO;URL;;
Specimen Thickness (mm);3;;;
Specimen Width (mm);6;;;
Specimen Length (mm);33;;;
Specimen Cross-section (cm^2);0.18;;;
Standard;ASTM D412;;;
Type of test;Pull-to-failure;;;
Speed (mm/min);450;;;
Machine;Instron  5569;;;
Load Cell;1 kN - Instron  2525-806;;;
Grippers;Instron 2710-010 ;;;
Strain Measurement;Global;;;
Strain calculation;Derived from the machine crosshead displacement readings;;;
Lab;Univ. Savoie Mont Blanc - SYMME Lab, 7400 Annecy, France;;;
Material supplier;Smooth-On;https://www.smooth-on.com/products/ecoflex-00-10/;;
Material;EcoFlex10;;;
;;;;
Time (s);True Strain;True Stress (MPa);Engineering Strain;Engineering Stress (MPa)
0.2;0.04361;-0.00135824167666667;0.04458;-0.0013
0.3;0.06574;0.000436399656666667;0.0679466666666667;0.000406666666666667
0.4;0.08695;0.00222735280666667;0.0908433333333333;0.00204
0.5;0.107616666666667;0.00233745800666667;0.11362;0.00209666666666667
0.6;0.12783;0.00247712937;0.13636;0.00218
0.7;0.147636666666667;0.00352414089;0.15909;0.00304
0.8;0.167056666666667;0.00409595570333333;0.181816666666667;0.00346666666666667
0.9;0.186103333333333;0.00411275879333333;0.204546666666667;0.00341333333333333
1;0.204793333333333;0.00472469875333333;0.22727;0.00385
1.1;0.223143333333333;0.00513620205;0.250003333333333;0.00411
1.2;0.241163333333333;0.0062214917;0.27273;0.00488666666666667
1.3;0.25886;0.00703537782666667;0.29546;0.00543
1.4;0.276256666666667;0.00732084028;0.318186666666667;0.00555333333333333
1.5;0.29335;0.00785505554333333;0.34091;0.00585666666666667
1.6;0.310156666666667;0.00823220249666667;0.363636666666667;0.00603666666666667
1.7;0.326683333333333;0.00922804486666667;0.386363333333333;0.00665666666666667
1.8;0.342943333333333;0.00951573539;0.409093333333333;0.00675333333333333
1.9;0.35895;0.01065533349;0.43182;0.00744
2;0.3747;0.01085614436;0.45455;0.00746333333333333
2.1;0.3902;0.0113110033;0.47727;0.00765666666666667
2.2;0.405466666666667;0.01186293393;0.5;0.00791
2.3;0.4205;0.0129055477633333;0.52273;0.00847333333333333
2.4;0.43532;0.01352971873;0.545453333333333;0.00875333333333333
2.5;0.44992;0.0141487107566667;0.56818;0.00902333333333333
2.6;0.464306666666667;0.01462839995;0.59091;0.00919333333333333
2.7;0.47849;0.0152953258;0.613636666666667;0.00947666666666667
2.8;0.49248;0.0160410558933333;0.63636;0.0098
2.9;0.50627;0.0170028175633333;0.65909;0.0102466666666667
3;0.51988;0.0179788580733333;0.68182;0.01069
3.1;0.5333;0.0185080496966667;0.70455;0.01086
3.2;0.546543333333333;0.0188885456766667;0.727273333333333;0.0109366666666667
3.3;0.55962;0.02000429019;0.75;0.01143
3.4;0.57252;0.02087281917;0.77273;0.0117733333333333
3.5;0.58526;0.0211723253933333;0.795456666666667;0.0117933333333333
3.6;0.597836666666667;0.02225661714;0.818183333333333;0.01224
3.7;0.61026;0.02293877982;0.84091;0.01246
3.8;0.62253;0.0238756154866667;0.86364;0.01281
3.9;0.63465;0.02471526221;0.886366666666667;0.0131033333333333
4;0.64663;0.02564804859;0.90909;0.0134333333333333
4.1;0.65846;0.02642594084;0.93182;0.01368
4.2;0.67016;0.0279009757;0.954543333333333;0.0142766666666667
4.3;0.68172;0.02855542014;0.97727;0.01444
4.4;0.69315;0.02958203886;1;0.01479
4.5;0.70445;0.03003460424;1.02273;0.0148466666666667
4.6;0.71562;0.0308044065;1.04545333333333;0.01506
4.7;0.72667;0.03219797771;1.06818;0.01557
4.8;0.7376;0.0331227613833333;1.09091;0.01584
4.9;0.74841;0.0346898672766667;1.11363666666667;0.01641
5;0.75911;0.0354983559566667;1.13636666666667;0.0166133333333333
5.1;0.76969;0.0356435113333333;1.15909;0.0165066666666667
5.2;0.78016;0.0377379382133333;1.18182;0.0172966666666667
5.3;0.79052;0.0384269837566667;1.20455;0.01743
5.4;0.80078;0.0404354881533333;1.22727333333333;0.0181533333333333
5.5;0.81093;0.04054502675;1.25;0.01802
5.6;0.82098;0.0425809090166667;1.27273;0.0187333333333333
5.7;0.83093;0.0431524637766667;1.29545666666667;0.0188
5.8;0.840783333333333;0.0442776593933333;1.31818333333333;0.0191
5.9;0.85054;0.0456356577866667;1.34091;0.0194933333333333
6;0.8602;0.0464843403133333;1.36363666666667;0.0196666666666667
6.1;0.86977;0.0484496235033333;1.38636;0.0203033333333333
6.20000000000001;0.87925;0.04935666626;1.40909;0.0204866666666667
6.3;0.88864;0.0506684970133333;1.43182;0.0208366666666667
6.4;0.89794;0.0518933087866667;1.45454666666667;0.02114
6.50000000000001;0.90716;0.05333390979;1.47727333333333;0.0215266666666667
6.60000000000001;0.91629;0.0543931766166667;1.5;0.02176
6.70000000000001;0.92534;0.0561793626433333;1.52273;0.02227
6.8;0.93431;0.0577215703133333;1.54546;0.0226766666666667
6.90000000000001;0.9432;0.0593920078566667;1.56818333333333;0.0231266666666667
7.00000000000001;0.95201;0.0610640863666667;1.59091;0.0235666666666667
7.10000000000001;0.96074;0.0617956221633333;1.61363333333333;0.0236433333333333
7.20000000000001;0.9694;0.06354455151;1.63636666666667;0.0241033333333333
7.30000000000001;0.977983333333333;0.0651483928366667;1.65909;0.0245
7.40000000000001;0.986496666666667;0.06659147508;1.68182;0.0248333333333333
7.50000000000001;0.99493;0.0689323035666667;1.70455;0.0254866666666667
7.60000000000001;1.0033;0.0703056226166667;1.72727666666667;0.0257766666666667
7.70000000000001;1.0116;0.0722320554366667;1.75000333333333;0.0262666666666667
7.80000000000001;1.01983;0.0736603797033333;1.77273;0.0265666666666667
7.90000000000001;1.02799333333333;0.0754272961366667;1.79545333333333;0.0269833333333333
8.00000000000001;1.03609;0.0776540669833333;1.81818;0.0275533333333333
8.10000000000001;1.04412333333333;0.0787682691866667;1.84091;0.0277266666666667
8.20000000000001;1.05209;0.0806662226566667;1.86363666666667;0.02817
8.30000000000001;1.06;0.08284466351;1.88636666666667;0.0287033333333333
8.40000000000001;1.06784;0.08547471314;1.90909;0.0293833333333333
8.50000000000001;1.07562;0.08706841647;1.93182;0.0296966666666667
8.60000000000001;1.08334333333333;0.08892402572;1.95454666666667;0.0300966666666667
8.70000000000001;1.09101;0.09064831044;1.97727;0.0304466666666667
8.80000000000001;1.09861;0.0933472670033333;2;0.0311166666666667
8.90000000000001;1.10616;0.0959337483833333;2.02272666666667;0.0317366666666667
9.00000000000001;1.11365;0.0976484025266667;2.04545333333333;0.0320633333333333
9.10000000000001;1.12108666666667;0.0992075899866666;2.06818333333333;0.0323366666666667
9.20000000000001;1.12846666666667;0.10260349502;2.09091;0.0331966666666667
9.30000000000001;1.13579;0.10465805258;2.11363666666667;0.0336133333333333
9.40000000000001;1.14306333333333;0.107161639313333;2.13636333333333;0.0341666666666667
9.50000000000001;1.15028666666667;0.110069666563333;2.15909;0.0348433333333333
9.60000000000001;1.15745;0.111842098663333;2.18182;0.03515
9.70000000000001;1.16457;0.114263123523333;2.20454666666667;0.0356566666666667
9.80000000000001;1.17164;0.117010515513333;2.22727333333333;0.0362566666666667
9.90000000000001;1.17865333333333;0.11986039912;2.25000333333333;0.0368833333333333
10;1.18562;0.122390895633333;2.27273;0.0373966666666667
10.1;1.19254333333333;0.12520341512;2.29545666666667;0.03799
10.2;1.19942;0.12758794006;2.31818666666667;0.03845
10.3;1.20624;0.130263792803333;2.34091;0.03899
10.4;1.21302;0.133574701023333;2.36363666666667;0.03971
10.5;1.21976;0.136573353033333;2.38636666666667;0.04033
10.6;1.22645;0.139540994823333;2.40909;0.0409333333333333
10.7;1.23309;0.14190451544;2.43182;0.04135
10.8;1.23969;0.14546202957;2.45454666666667;0.0421066666666667
10.9;1.24625;0.148066162103333;2.47727333333333;0.0425833333333333
11;1.25276;0.15146680831;2.5;0.04328
11.1;1.25923666666667;0.15365871693;2.52273;0.0436166666666667
11.2;1.26567;0.156640928606667;2.54545666666667;0.04418
11.3;1.27206;0.15996866705;2.56818333333333;0.04483
11.4;1.27840666666667;0.16356800382;2.59091;0.0455533333333333
11.5;1.28471333333333;0.16626621661;2.61363666666667;0.04601
11.6;1.29098;0.169036620246667;2.63636333333333;0.0464833333333333
11.7;1.29721666666667;0.172250586423333;2.65909333333333;0.0470766666666667
11.8;1.30341;0.175787660693333;2.68182;0.0477433333333333
11.9;1.30956;0.178996282886667;2.70455;0.04832
12;1.31568;0.183042851453333;2.72727666666667;0.0491066666666667
12.1;1.32176;0.186521967303333;2.75;0.0497433333333333
12.2;1.3278;0.189572372786667;2.77273;0.05025
12.3;1.33380333333333;0.193813106926667;2.79545666666667;0.0510633333333333
12.4;1.33977333333333;0.196641909773333;2.81818333333333;0.0515033333333333
12.5;1.34571;0.199902780026667;2.84091;0.05205
12.6;1.35161;0.204089572666667;2.86364;0.0528233333333333
12.7;1.35747;0.206583079256667;2.88636666666667;0.0531566666666667
12.8;1.36330666666667;0.21079481561;2.90909;0.0539233333333333
12.9;1.3691;0.21473198684;2.93182;0.0546133333333333
13;1.37487;0.217772398056667;2.95454666666667;0.05507
13.1;1.3806;0.22060390009;2.97727;0.0554666666666667
13.2;1.38629666666667;0.226077449343333;3;0.05652
13.3;1.39196;0.228227679606667;3.02272666666667;0.0567366666666667
13.4;1.39759;0.23210890344;3.04545333333333;0.0573766666666667
13.5;1.4032;0.236191095243333;3.06818;0.05806
13.6;1.40877;0.239554502563333;3.09091;0.0585566666666667
13.7;1.41431;0.243853949563333;3.11363666666667;0.05928
13.8;1.41982;0.24788183824;3.13637;0.0599266666666667
13.9;1.4253;0.250468391816667;3.15909333333333;0.06022
14;1.43075;0.25567787207;3.18182;0.0611433333333333
14.1;1.43617;0.25873119298;3.20454666666667;0.0615333333333333
14.2;1.44156;0.264792965753333;3.22727333333333;0.0626366666666667
14.3;1.44692;0.26817400159;3.25;0.0631
14.4;1.45225;0.27204363525;3.27273;0.06367
14.5;1.45756;0.276088419543333;3.29545333333333;0.0642733333333333
14.6;1.46283333333333;0.279993266886667;3.31818;0.06484
14.7;1.46808;0.284204015793333;3.34091;0.06547
14.8;1.47331;0.28889220549;3.36363666666667;0.0662033333333333
14.9;1.4785;0.292829326746667;3.38636333333333;0.06676
15;1.48367;0.298194210606667;3.40909;0.06763
15.1;1.48881;0.30132815586;3.43182;0.0679933333333333
15.2;1.49392666666667;0.306708036613333;3.45454666666667;0.0688533333333333
15.3;1.49901;0.311342157743333;3.47727;0.06954
15.4;1.50408;0.315331094023333;3.5;0.0700733333333333
15.5;1.50911666666667;0.320160338393333;3.52272666666667;0.07079
15.6;1.51413;0.324102867013333;3.54545666666667;0.0713033333333333
15.7;1.51912;0.33087490853;3.56818666666667;0.07243
15.8;1.52408;0.33394840635;3.59091;0.07274
15.9;1.52902;0.339971308953333;3.61364;0.0736866666666667
16;1.53393;0.34426863353;3.63636333333333;0.0742533333333333
16.1;1.53882;0.34947693725;3.65909;0.07501
16.2;1.54369;0.354017919266667;3.68182;0.0756166666666667
16.3;1.54853;0.35927708172;3.70455;0.0763666666666667
16.4;1.55335;0.364544900546667;3.72727333333333;0.0771133333333333
16.5;1.55814333333333;0.369531645163333;3.75000333333333;0.0777933333333333
16.6;1.56292;0.375856080266667;3.77272666666667;0.07875
16.7;1.56767;0.379182613176667;3.79545666666667;0.07907
16.8;1.5724;0.385540611573333;3.81818;0.08002
16.9;1.5771;0.390683406536667;3.84091;0.0807033333333333
17;1.58179;0.39494658521;3.86364;0.0812066666666667
17.1;1.58645;0.400605929713333;3.88636333333333;0.0819866666666667
17.2;1.59109;0.40667197484;3.90909;0.0828433333333333
17.3;1.59571;0.412735343253333;3.93182;0.0836866666666667
17.4;1.60030666666667;0.417496746993333;3.95454666666667;0.0842633333333333
17.5;1.60488;0.424637539446667;3.97727333333333;0.0853166666666667
17.6;1.60944;0.42946355632;4.00000333333333;0.0858933333333333
17.7;1.61397;0.434390466696667;4.02273;0.0864833333333333
17.8;1.61849;0.441097655693333;4.04545666666667;0.0874233333333333
17.9;1.62298;0.447861196103333;4.06818333333333;0.08837
18;1.62746;0.452532691096667;4.09091;0.0888866666666667
18.1;1.63191;0.458040784343333;4.11364;0.0895733333333333
18.2;1.63634666666667;0.46514846501;4.13636666666667;0.0905566666666667
18.3;1.64076;0.470135699383333;4.15909333333333;0.0911233333333333
18.4;1.64516;0.475650926013333;4.18181666666667;0.09179
18.5;1.64953;0.483667530333333;4.20454666666667;0.09293
18.6;1.65389;0.489997121453333;4.22727333333333;0.09374
18.7;1.65823;0.495200919053333;4.25;0.0943233333333333
18.8;1.66255;0.50225827335;4.27273;0.0952566666666667
18.9;1.66685;0.508414265276667;4.29545666666667;0.09601
19;1.67113;0.514562526736667;4.31818;0.0967566666666667
19.1;1.6754;0.522094930393333;4.34091;0.0977533333333333
19.2;1.67964;0.52980984738;4.36363666666667;0.0987766666666667
19.3;1.68387;0.533693827523333;4.38636333333333;0.0990833333333333
19.4;1.68808;0.54198536824;4.40909;0.1002
19.5;1.69227;0.548405948173333;4.43182;0.10096
19.6;1.69645;0.5541274738;4.45454666666667;0.10159
19.7;1.70061;0.562964023663333;4.47727333333333;0.10278
19.8;1.70475;0.56947079676;4.5;0.10354
19.9;1.70887;0.575219997573333;4.52273;0.104153333333333
20;1.71298;0.583373420813333;4.54546;0.105196666666667
20.1;1.71707;0.589639356313333;4.56818333333333;0.105896666666667
20.2;1.72114;0.597343836156667;4.59090666666667;0.106843333333333
20.3;1.7252;0.60365862332;4.61364;0.107533333333333
20.4;1.72924;0.611469597046667;4.63636333333333;0.108486666666667
20.5;1.73326;0.618933278233333;4.65909333333333;0.10937
20.6;1.73727;0.625599950476667;4.68182;0.110103333333333
20.7;1.74126;0.63569453217;4.70455;0.111436666666667
20.8;1.74524;0.64115387023;4.72727666666667;0.111946666666667
20.9;1.7492;0.648990043133333;4.75;0.11287
21;1.75314666666667;0.656559884376667;4.77273;0.113736666666667
21.1;1.75707;0.665182903193333;4.79545666666667;0.114776666666667
21.2;1.76099;0.672805259426667;4.81818333333333;0.115636666666667
21.3;1.76489;0.67987868125;4.84091;0.116396666666667
21.4;1.76877;0.68740451358;4.86363666666667;0.117233333333333
21.5;1.77264;0.697901360506667;4.88636333333333;0.118563333333333
21.6;1.77649;0.704928854963333;4.90909;0.119296666666667
21.7;1.78033;0.714325265436667;4.93181666666667;0.120423333333333
21.8;1.78415;0.720895975626667;4.95454;0.121066666666667
21.9;1.78796;0.72792944173;4.97727666666667;0.12178
22;1.79176;0.737186553393333;5;0.122866666666667
22.1;1.79554;0.743975137046667;5.02273;0.12353
22.2;1.79931;0.75446282202;5.04545666666667;0.1248
22.3;1.80306;0.76221286121;5.06818;0.12561
22.4;1.8068;0.77021578659;5.09091;0.126453333333333
22.5;1.81052;0.78075043388;5.11364;0.127706666666667
22.6;1.81423;0.788755667163333;5.13636333333333;0.12854
22.7;1.81793;0.798088325683333;5.15909;0.12958
22.8;1.82161;0.80732590454;5.18182;0.1306
22.9;1.82528;0.816257759033333;5.20454666666667;0.131556666666667
23;1.82894;0.824254672213333;5.22727333333333;0.132363333333333
23.1;1.83258;0.832957473773333;5.25;0.133273333333333
23.2;1.83621;0.84385678899;5.27273;0.134526666666667
23.3;1.83983;0.851686965996667;5.29545666666667;0.135286666666667
23.4;1.84343;0.860623770636667;5.31818;0.136213333333333
23.5;1.84702;0.869594989593333;5.34091;0.13714
23.6;1.8506;0.881018268446667;5.36363666666667;0.138446666666667
23.7;1.85416666666667;0.888750208496667;5.38636;0.139163333333333
23.8;1.85772;0.898162990793333;5.40909;0.14014
23.9;1.86126;0.907671676;5.43182;0.141123333333333
24;1.86478333333333;0.915156165216667;5.45455;0.141786666666667
24.1;1.8683;0.926825709003333;5.47727;0.14309
24.2;1.8718;0.936196133813333;5.5;0.14403
24.3;1.87529;0.94792873905;5.52273;0.145323333333333
24.4;1.87877;0.95789161422;5.54546;0.146343333333333
24.5;1.88224;0.96781176549;5.56818333333333;0.147346666666667
24.6;1.88569;0.977643441763333;5.59091;0.148333333333333
24.7;1.88913;0.987247195556667;5.61363666666667;0.149273333333333
24.8;1.89256;0.998232038226667;5.63636333333333;0.15042
24.9;1.89598;1.00741707661;5.65909;0.151283333333333
25;1.89939;1.01885149624;5.68182;0.15248
25.1;1.90279;1.02927327081667;5.70455;0.153516666666667
25.2;1.90617;1.04048916353333;5.72727333333333;0.15467
25.3;1.90954;1.04982854584333;5.75;0.155526666666667
25.4;1.9129;1.06101867911;5.77273;0.15666
25.5;1.91625;1.07196454501667;5.79545333333333;0.157746666666667
25.6;1.91959;1.08176161431333;5.81818;0.158656666666667
25.7;1.92292;1.09116372869333;5.84091;0.159506666666667
25.8;1.92624;1.10298796080333;5.86364;0.1607
25.9;1.92954;1.11417907533667;5.88636333333333;0.161796666666667
26;1.93284;1.12644652254667;5.90909;0.163036666666667
26.1;1.93612;1.13764388438667;5.93182;0.16412
26.2;1.9394;1.14740859229;5.95454666666667;0.164986666666667
26.3;1.94266;1.15952821569;5.97727666666667;0.166186666666667
26.4;1.94591;1.17152394654;6;0.16736
26.5;1.94915;1.18105925700333;6.02273;0.168176666666667
26.6;1.95238;1.19325544068333;6.04545333333333;0.169366666666667
26.7;1.9556;1.20502693917667;6.06818;0.170486666666667
26.8;1.95881;1.21748082852333;6.09091;0.171696666666667
26.9;1.96201;1.23048693615667;6.11364;0.172976666666667
27;1.9652;1.24443242522333;6.13636333333333;0.17438
27.1;1.96838;1.25280139873333;6.15909333333333;0.174993333333333
27.2;1.97155;1.26477665532333;6.18182;0.176106666666667
27.3;1.97471;1.27561092457333;6.20454333333333;0.177056666666667
27.4;1.97786;1.28792189564;6.22727333333333;0.1782
27.5;1.981;1.30219889155333;6.25;0.179616666666667
27.6;1.98413;1.31402845731333;6.27273;0.18068
27.7;1.98725;1.32636829549667;6.29545666666667;0.181806666666667
27.8;1.99036;1.33696789855333;6.31818;0.182693333333333
27.9;1.99346;1.35207686195667;6.34091;0.184183333333333
28;1.99655;1.36170206951333;6.36363666666667;0.184923333333333
28.1;1.99964;1.37671091414;6.38636;0.186386666666667
28.2;2.00271;1.38693047241667;6.40909;0.187193333333333
28.3;2.00577;1.39857882329;6.43182333333333;0.188186666666667
28.4;2.00882;1.41280847746333;6.45454666666667;0.189523333333333
28.5;2.01187;1.42571847218667;6.47727666666667;0.190673333333333
28.6;2.0149;1.43845377504333;6.49999666666667;0.19179
28.7;2.01793;1.45165871030333;6.52273;0.19297
28.8;2.02095;1.46568215185667;6.54545666666667;0.194246666666667
28.9;2.02395;1.47650818982;6.56818333333333;0.195093333333333
29;2.02695;1.49104229701333;6.59091;0.196423333333333
29.1;2.02994;1.50545415466;6.61363666666667;0.197726666666667
29.2;2.03292;1.51825600973333;6.63636333333333;0.19882
29.3;2.03589;1.52981888514;6.65909;0.19974
29.4;2.03886;1.54550061330333;6.68182;0.20119
29.5;2.04181;1.55718506453;6.70454666666667;0.20211
29.6;2.04476;1.57210692044333;6.72727333333333;0.20345
29.7;2.04769;1.58649485961667;6.75;0.20471
29.8;2.05062;1.59916914282;6.77272666666667;0.20574
29.9;2.05354;1.61335356473667;6.79545333333333;0.20696
30;2.05645;1.62916688293333;6.81818;0.20838
30.1;2.05935666666667;1.64223628924667;6.84091;0.209446666666667
30.2;2.06225;1.65569634087667;6.86364;0.21055
30.3;2.06514;1.67074244855;6.88636333333333;0.21185
30.4;2.06801;1.68746061861;6.90909333333333;0.21336
30.5;2.07088;1.69755877820667;6.93182;0.21402
30.6;2.07374;1.71235090706;6.95455;0.215266666666667
30.7;2.0766;1.72830832437333;6.97727666666667;0.216653333333333
30.8;2.07944;1.74162090039;7.00000333333333;0.217703333333333
30.9;2.08228;1.75782399747667;7.02273;0.219106666666667
31;2.08511;1.77405009273667;7.04545666666667;0.220503333333333
31.1;2.08793;1.78519852882667;7.06818;0.221266666666667
31.2;2.09074;1.80118326893333;7.09091;0.222616666666667
31.3;2.09355;1.81810036317333;7.11364;0.224083333333333
31.4;2.09634;1.83338132128333;7.13636666666667;0.225333333333333
31.5;2.09913;1.84879563415;7.15909;0.226593333333333
31.6;2.10191;1.86265009659667;7.18182;0.22766
31.7;2.10469;1.87783423569667;7.20454666666667;0.228876666666667
31.8;2.10745333333333;1.89374216495;7.22727333333333;0.230176666666667
31.9;2.11021;1.90875332090333;7.25;0.231363333333333
32;2.11296;1.92608128783;7.27273;0.232823333333333
32.1;2.11571;1.93791248773;7.29546;0.23361
32.2;2.11844;1.95534723526;7.31818;0.235066666666667
32.3;2.12117;1.97347008527333;7.34090666666667;0.2366
32.4;2.12389;1.98723907084667;7.36363666666667;0.237603333333333
32.5;2.12661;2.00035146229333;7.38636666666667;0.238523333333333
32.6;2.12931;2.02030134024667;7.40909333333333;0.24025
32.7;2.13201;2.03339198102333;7.43182;0.24116
32.8;2.1347;2.04941004193333;7.45454333333333;0.242403333333333
32.9;2.13739;2.06598944429333;7.47727666666667;0.243706666666667
33;2.14007;2.08471024347;7.5;0.24526
33.1;2.14274;2.09761448342333;7.52273;0.24612
33.2;2.1454;2.11548262257333;7.54546;0.247556666666667
33.3;2.14806;2.13217720698667;7.56818333333333;0.248846666666667
33.4;2.1507;2.14760849670667;7.59091;0.249986666666667
33.5;2.15335;2.16679659569;7.61364;0.251553333333333
33.6;2.15598;2.18293235792;7.63636333333333;0.252763333333333
33.7;2.15861;2.20158614020667;7.65909;0.254253333333333
33.8;2.16123;2.21841682328667;7.68182;0.255523333333333
33.9;2.16385;2.23428421533333;7.70454666666667;0.256683333333333
34;2.16645;2.24935972084667;7.72727666666667;0.25774
34.1;2.16905;2.26775562728667;7.75;0.259173333333333
34.2;2.17165;2.28473045801667;7.77272666666667;0.260436666666667
34.3;2.17424;2.30386845091;7.79545333333333;0.26194
34.4;2.17682;2.31932187576;7.81818333333333;0.263013333333333
34.5;2.17939;2.33879711714333;7.84091;0.264543333333333
34.6;2.18196;2.35561969737333;7.86364;0.265763333333333
34.7;2.18452;2.37330059087333;7.88636;0.267073333333333
34.8;2.18707;2.39153918510667;7.90909333333333;0.268436666666667
34.9;2.18962;2.41021802078;7.93182;0.269846666666667
35;2.19216;2.42544657852;7.95455;0.27086
35.1;2.1947;2.44225781638333;7.97727333333333;0.272046666666667
35.2;2.19722333333333;2.45882549724667;8;0.2732
35.3;2.19975;2.47965581150667;8.02273;0.274823333333333
35.4;2.20226;2.49859014059667;8.04545333333333;0.276226666666667
35.5;2.20477;2.51777280779333;8.06818;0.27765
35.6;2.20727666666667;2.53309457055667;8.09091;0.27864
35.7;2.20977;2.55441666110333;8.11364;0.280286666666667
35.8;2.21226;2.57208651854333;8.13636333333333;0.28152
35.9;2.21475;2.59100781997333;8.15909333333333;0.28289
36;2.21723;2.60905012658333;8.18182;0.284153333333333
36.1;2.2197;2.62569058092333;8.20454666666667;0.28526
36.2;2.22216;2.64517804467667;8.22727333333333;0.286673333333333
36.3;2.22462;2.66478844736333;8.25;0.288086666666667
36.4;2.22708;2.68386260151;8.27273;0.289436666666667
36.5;2.22953;2.70130690215667;8.29545333333333;0.290603333333333
36.6;2.23197;2.7226166071;8.31818;0.292183333333333
36.7;2.2344;2.73842660737667;8.34091;0.293163333333333
36.8;2.23683;2.76083178357;8.36363666666667;0.294846666666667
36.9;2.23926;2.78224917951;8.38636666666667;0.296413333333333
37;2.24168;2.79911478390667;8.40909333333333;0.29749
37.1;2.24409;2.81726002144;8.43182;0.298696666666667
37.2;2.2465;2.8359610818;8.45454666666667;0.299956666666667
37.3;2.2489;2.85795924539667;8.47727333333333;0.30156
37.4;2.25129;2.87841248975;8.5;0.302993333333333
37.5;2.25368;2.89925255278667;8.52273;0.304456666666667
37.6;2.25606666666667;2.91646197770333;8.54545666666667;0.305533333333333
37.7;2.25844;2.93771883742;8.56818333333333;0.307026666666667
37.8;2.26082;2.95786836447333;8.59091;0.308403333333333
37.9;2.26318;2.98091146934;8.61364;0.31007
38;2.26554;2.99983121234667;8.63636333333333;0.311303333333333
38.1;2.2679;3.01802003959;8.65909;0.312453333333333
38.2;2.27025;3.04030767641667;8.68182;0.31402
38.3;2.27259;3.06168684278;8.70454666666667;0.31549
38.4;2.27493;3.07986690986333;8.72727333333333;0.31662
38.5;2.27727;3.10088874311;8.75;0.31804
38.6;2.2796;3.12028802664667;8.77273;0.319283333333333
38.7;2.28192;3.14306128892;8.79545666666667;0.32087
38.8;2.28424;3.16387949651667;8.81818;0.322246666666667
38.9;2.28655;3.18495082030667;8.84091;0.323643333333333
39;2.28885333333333;3.20439235786;8.86364;0.32487
39.1;2.29116;3.22625815755667;8.88636666666667;0.326336666666667
39.2;2.29345;3.25112119213;8.90909333333333;0.328093333333333
39.3;2.29574;3.27101042294;8.93182;0.329346666666667
39.4;2.29803;3.29367044149333;8.95454666666667;0.330873333333333
39.5;2.30031;3.31236616642;8.97727333333333;0.33199
39.6;2.30258666666667;3.33225924082333;9;0.333226666666667
39.7;2.30486;3.35676349982333;9.02273;0.334916666666667
39.8;2.30712;3.37782781538;9.04545666666667;0.336253333333333
39.9;2.30938;3.39909419483;9.06818;0.337606666666667
40;2.31163333333333;3.42160358399;9.09091;0.339076666666667
40.1;2.31388666666667;3.44156838596333;9.11364;0.34029
40.2;2.31613;3.46532685534333;9.13636333333333;0.34187
40.3;2.31837;3.48614802545;9.15909;0.343153333333333
40.4;2.3206;3.51158265948333;9.18181666666667;0.344886666666667
40.5;2.32283;3.53202135455667;9.20454666666667;0.346123333333333
40.6;2.32506;3.55529464142;9.22727;0.34763
40.7;2.32728;3.57849996832333;9.25;0.349123333333333
40.8;2.32949;3.60108854565667;9.27273;0.350546666666667
40.9;2.3317;3.62352358634;9.29545666666667;0.351953333333333
41;2.33391;3.64600946691;9.31818;0.353356666666667
41.1;2.33611;3.66739742101333;9.34091333333333;0.35465
41.2;2.3383;3.69230008689;9.36364;0.356273333333333
41.3;2.34049;3.71730486272667;9.38636666666667;0.3579
41.4;2.34268;3.73822382859333;9.40909333333333;0.35913
41.5;2.34486;3.7609273728;9.43182;0.360523333333333
41.6;2.34704;3.78292836715;9.45455;0.361843333333333
41.7;2.34921;3.80801606911;9.47727;0.363456666666667
41.8;2.35138;3.82877036322;9.5;0.364646666666667
41.9;2.35354;3.85685152199667;9.52273;0.366526666666667
42;2.35569666666667;3.88016364886333;9.54545666666667;0.367946666666667
42.1;2.35785;3.90205059559667;9.56818;0.36923
42.2;2.36;3.92979645158667;9.59091;0.371053333333333
42.3;2.36214;3.95007982244;9.61363666666667;0.372173333333333
42.4;2.36428;3.97481768012333;9.63636333333333;0.3737
42.5;2.36641;3.99690659988667;9.65909;0.374976666666667
42.6;2.36854;4.02428397241333;9.68182;0.376743333333333
42.7;2.37067;4.0484722557;9.70455;0.3782
42.8;2.37279;4.07476715935333;9.72727;0.379853333333333
42.9;2.37491;4.09807517074333;9.75;0.381216666666667
43;2.37702;4.12134131396333;9.77273;0.382573333333333
43.1;2.37913;4.145767913;9.79545666666667;0.38403
43.2;2.38123;4.17048570751667;9.81818;0.385506666666667
43.3;2.38333;4.19473424211;9.84091;0.386936666666667
43.4;2.38542;4.21937176237667;9.86364;0.388393333333333
43.5;2.38751;4.24501844469;9.88636;0.389936666666667
43.6;2.3896;4.27224908743333;9.90909;0.391623333333333
43.7;2.39168;4.29630091143333;9.93182;0.39301
43.8;2.39375;4.32239176501;9.95455;0.394573333333333
43.9;2.39583;4.34548802356333;9.97727333333333;0.395863333333333
44;2.3979;4.37073919631667;10;0.39734
44.1;2.39996;4.39694317470333;10.02273;0.398896666666667
44.2;2.40202;4.42059567877;10.0454533333333;0.40022
44.3;2.40407;4.44718706155667;10.0681833333333;0.401796666666667
44.4;2.40613;4.47175750255333;10.09091;0.403193333333333
44.5;2.40817;4.49977985827667;10.11364;0.404886666666667
44.6;2.41022;4.52497791691;10.1363633333333;0.406323333333333
44.7;2.41225;4.55072440430333;10.15909;0.407806666666667
44.8;2.41429;4.57742902553333;10.18182;0.40936
44.9;2.41632;4.60363262317667;10.2045433333333;0.410873333333333
45;2.41835;4.62823597019667;10.22727;0.41223
45.1;2.42037;4.65485542408;10.25;0.413763333333333
45.2;2.42239;4.68397296538333;10.27273;0.415513333333333
45.3;2.4244;4.71057608370667;10.2954533333333;0.417033333333333
45.4;2.42641;4.73634255535;10.31818;0.418473333333333
45.5;2.42842;4.76501956233;10.34091;0.420163333333333
45.6;2.43042;4.78908915738;10.36364;0.42144
45.7;2.43242;4.81731017180333;10.3863633333333;0.423076666666667
45.8;2.43441;4.84463800657;10.4090933333333;0.42463
45.9;2.4364;4.86994144060333;10.43182;0.426
46;2.43839;4.89951263357667;10.4545466666667;0.427733333333333
46.1;2.44037;4.92699596632333;10.4772733333333;0.429283333333333
46.2;2.44235;4.95419982972667;10.5;0.430796666666667
46.3;2.44432;4.98633961594;10.52273;0.43274
46.4;2.44629;5.00833080039;10.5454533333333;0.433793333333333
46.5;2.44826;5.03454689184;10.5681833333333;0.43521
46.6;2.45022;5.06384563006667;10.59091;0.43688
46.7;2.45218;5.09387586725333;10.6136333333333;0.43861
46.8;2.45413666666667;5.12044166171667;10.63636;0.440036666666667
46.9;2.45609;5.14622098814667;10.65909;0.441393333333333
47;2.45803;5.17323412955667;10.68182;0.442846666666667
47.1;2.45998;5.20164928032;10.7045466666667;0.444413333333333
47.2;2.46192;5.23308700407667;10.72727;0.44623
47.3;2.46385;5.26208099918;10.75;0.447836666666667
47.4;2.46579;5.28883149564667;10.77273;0.449246666666667
47.5;2.46771;5.31638551138333;10.7954566666667;0.450713333333333
47.6;2.46964;5.34698806920333;10.8181833333333;0.452436666666667
47.7;2.47156;5.37222607029;10.8409133333333;0.453703333333333
47.8;2.47348;5.40186650255333;10.8636366666667;0.455326666666667
47.9;2.47539;5.43229976284;10.8863633333333;0.45702
48;2.4773;5.45987711128667;10.90909;0.458463333333333
48.1;2.47921;5.49009920985667;10.93182;0.460123333333333
48.2;2.48111;5.52066754729;10.95455;0.461803333333333
48.3;2.48301;5.5466540231;10.9772733333333;0.463096666666667
48.4;2.48491;5.57780813641667;11;0.464816666666667
48.5;2.4868;5.60872944821667;11.0227266666667;0.46651
48.6;2.48869;5.63500034388;11.0454533333333;0.46781
48.7;2.49057;5.66575391256;11.06818;0.469476666666667
48.8;2.49245;5.69571163919;11.09091;0.471073333333333
48.9;2.49433;5.72493226876;11.1136366666667;0.4726
49;2.49621;5.75374853796333;11.1363633333333;0.474093333333333
49.1;2.49808;5.78161627916667;11.15909;0.475496666666667
49.2;2.49994;5.81415620799;11.18182;0.477283333333333
49.3;2.50181;5.84299311255333;11.2045466666667;0.478753333333333
49.4;2.50367;5.87522718971667;11.2272733333333;0.4805
49.5;2.50553;5.90631098705667;11.25;0.482146666666667
49.6;2.50738;5.92983605958333;11.27273;0.48317
49.7;2.50923;5.96470457205;11.2954566666667;0.485116666666667
49.8;2.51108;5.99240146282667;11.3181833333333;0.48647
49.9;2.51292;6.02688633349333;11.34091;0.488363333333333
50;2.51476;6.05649155677667;11.36364;0.48986
50.1;2.5166;6.08734095863;11.3863666666667;0.491453333333333
50.2;2.51843;6.11739820139333;11.40909;0.49298
50.3;2.52026;6.14722619885667;11.43182;0.494473333333333
50.4;2.52209;6.17908793617333;11.4545466666667;0.496133333333333
50.5;2.52391;6.21024363384333;11.4772733333333;0.497726666666667
50.6;2.52573;6.23827663908667;11.5;0.499063333333333
50.7;2.52754333333333;6.27248297960667;11.52273;0.500886666666667
50.8;2.52936;6.30531403508;11.5454566666667;0.5026
50.9;2.53117;6.33659947444333;11.56818;0.504176666666667
51;2.53297666666667;6.36614421985333;11.59091;0.505613333333333
51.1;2.53478;6.39754149699333;11.61364;0.50719
51.2;2.53658;6.42794259238333;11.6363633333333;0.508683333333333
51.3;2.53838;6.45957067686333;11.65909;0.510273333333333
51.4;2.54017;6.49204453473333;11.68182;0.51192
51.5;2.54196;6.52561108438667;11.70455;0.513643333333333
51.6;2.54375;6.55501697867;11.72727;0.515036666666667
51.7;2.54553;6.58894944989667;11.75;0.51678
51.8;2.54731;6.61795620556333;11.77273;0.518133333333333
51.9;2.54909;6.65357469917667;11.79546;0.519993333333333
52;2.55086;6.68578208121;11.81818;0.521586666666667
52.1;2.55264;6.71618655221333;11.84091;0.52303
52.2;2.5544;6.74946178734;11.86364;0.52469
52.3;2.55617;6.78123852334667;11.88636;0.526233333333333
52.4;2.55793;6.81132738159667;11.90909;0.527636666666667
52.5;2.55969;6.84665824688;11.93182;0.529443333333333
52.6;2.56145;6.87935610559333;11.95455;0.53104
52.7;2.5632;6.91062230837333;11.97727;0.532516666666667
52.8;2.56495;6.9484882468;12;0.534503333333333
52.9;2.5667;6.97970602442333;12.02273;0.535963333333333
53;2.56844;7.01284171947333;12.0454566666667;0.53757
53.1;2.57018;7.04369616054333;12.06818;0.539
53.2;2.57192;7.07683403105667;12.09091;0.54059
53.3;2.57365;7.10962476607333;12.11364;0.542156666666667
53.4;2.57538;7.14043010786333;12.1363666666667;0.54356
53.5;2.57711;7.17596222652333;12.15909;0.545326666666667
53.6;2.57884;7.21003190507;12.18182;0.546966666666667
53.7;2.58056;7.24443961374667;12.20455;0.548633333333333
53.8;2.58228;7.27522907096333;12.2272766666667;0.55002
53.9;2.584;7.31116139452667;12.2500033333333;0.551786666666667
54;2.58571;7.34485030651;12.27273;0.553376666666667
54.1;2.58742;7.37262898105333;12.29545;0.554523333333333
54.2;2.58913;7.40877690629667;12.31818;0.556293333333333
54.3000000000001;2.59084;7.44177950601667;12.34091;0.557816666666667
54.4;2.59254;7.47509811135;12.3636366666667;0.55936
54.5;2.59424;7.50945350073;12.3863666666667;0.560976666666667
54.6;2.59593;7.54248773387;12.40909;0.56249
54.7;2.59763;7.58016471159;12.43182;0.564343333333333
54.8000000000001;2.59932;7.61327227719333;12.4545466666667;0.565853333333333
54.9;2.601;7.64734556670667;12.47727;0.567423333333333
55;2.60269;7.67794044821;12.5;0.568733333333333
55.1;2.60437;7.71020834573333;12.52273;0.570166666666667
55.2;2.60605;7.74446247920667;12.5454533333333;0.571736666666667
55.3000000000001;2.60773;7.77963645878333;12.56818;0.573373333333333
55.4;2.6094;7.81417756084667;12.59091;0.574953333333333
55.5;2.61107;7.85057824696;12.6136333333333;0.57667
55.6;2.61274;7.88133168059333;12.63636;0.577966666666667
55.7;2.61441;7.91364272426333;12.65909;0.57937
55.8000000000001;2.61607;7.94748443141333;12.68182;0.580876666666667
55.9;2.61773;7.98181106108;12.7045466666667;0.58242
56;2.61938;8.01939860739;12.7272733333333;0.584193333333333
56.1;2.62104;8.04755601524667;12.75;0.58528
56.2;2.62269;8.08208620548333;12.77273;0.586816666666667
56.3000000000001;2.62434;8.11663186581;12.7954533333333;0.588356666666667
56.4000000000001;2.62599;8.14407434272333;12.8181833333333;0.589373333333333
56.5;2.62763;8.17462012090667;12.84091;0.590616666666667
56.6;2.62927;8.20210642455333;12.86364;0.591626666666667
56.7;2.63091;8.30439899294;12.886365;0.598025
56.8000000000001;2.63254;8.34294532293;12.90909;0.59982
56.9000000000001;2.63418;8.37309322814;12.93182;0.601005
57;2.63581;8.41264685571;12.954545;0.60286
57.1;2.63743;8.447597767115;12.977275;0.60438
57.2;2.63906;8.47981573217;13;0.6057
57.3000000000001;2.64068;8.519806131245;13.02273;0.607575
57.4000000000001;2.6423;8.55299450755;13.045455;0.60895
57.5000000000001;2.64392;8.584764695645;13.06818;0.610225
57.6;2.64553;8.621956830305;13.09091;0.61188
57.7;2.64714;8.656938200355;13.11364;0.61337
57.8000000000001;2.64875;8.692062841985;13.136365;0.614875
57.9000000000001;2.65036;8.72841267564;13.159095;0.616455
58.0000000000001;2.65196;8.759796421995;13.18182;0.617675
58.1;2.65356;8.79550313006;13.20455;0.619205
58.2;2.65516;8.829993231225;13.227275;0.62064
58.3000000000001;2.65676;8.858578300615;13.25;0.621655
58.4000000000001;2.65835;8.883328879855;13.27273;0.6224
58.5000000000001;2.65994;8.95176556533;13.29545;0.6262
58.6;2.66153;8.99439407195;13.31818;0.62818
58.7;2.66312;9.02992357719;13.34091;0.62966
58.8000000000001;2.6647;9.07866411393;13.36364;0.63206
58.9000000000001;2.66628;9.11934067966;13.38637;0.63389
59.0000000000001;2.66786;9.15031907195;13.4091;0.63504
59.1;2.66944;9.19199340808;13.43182;0.63693
59.2;2.67101;9.23506451575;13.45454;0.6389
59.3000000000001;2.67258;9.28127032603;13.47727;0.64109
59.4000000000001;2.67415;9.32077181855;13.5;0.64281
59.5000000000001;2.67572;9.35761176012;13.52273;0.64434
59.6000000000001;2.67728;9.39724874351;13.54546;0.64606
59.7;2.67884;9.43446737547;13.56818;0.64761
59.8000000000001;2.6804;9.48555054955;13.59091;0.6501
59.9000000000001;2.68195;9.52547562681;13.61363;0.65182
60.0000000000001;2.68351;9.56662614132;13.63636;0.65362
60.1000000000001;2.68506;9.60612989274;13.65909;0.6553
60.2;2.68661;9.64626240928;13.68182;0.65702
60.3000000000001;2.68816;9.68509749341;13.70455;0.65865
60.4000000000001;2.6897;9.73181694225;13.72727;0.6608
60.5000000000001;2.69124;9.76965031375;13.75;0.66235
60.6000000000001;2.69278;9.8106373541;13.77273;0.6641
60.7000000000001;2.69432;9.8583236202;13.79546;0.66631
60.8000000000001;2.69586;9.90503125775;13.81819;0.66844
60.9000000000001;2.69739;9.93264589301;13.84092;0.66927
61.0000000000001;2.69892;9.97940559431;13.86364;0.6714
61.1000000000001;2.70045;10.01826605529;13.88636;0.67298
61.2000000000001;2.70197;10.06017696994;13.90909;0.67477
61.3000000000001;2.70349;10.10543696318;13.93182;0.67677
61.4000000000001;2.70502;10.14419030208;13.95455;0.67833
61.5000000000001;2.70653;10.18266753781;13.97727;0.67987
61.6000000000001;2.70805;10.2299202958;14;0.68199
61.7000000000001;2.70956;10.26974923564;14.02273;0.68361
61.8000000000001;2.71108;10.31633405797;14.04545;0.68568
61.9000000000001;2.71259;10.36614053115;14.06818;0.68795
62.0000000000001;2.71409;10.39760839676;14.09091;0.689
62.1000000000001;2.7156;10.44121339673;14.11364;0.69085
62.2000000000001;2.7171;10.4840824773;14.13637;0.69264
62.3000000000001;2.7186;10.52591389829;14.15909;0.69436
62.4000000000001;2.7201;10.57614916283;14.18182;0.69663
62.5000000000001;2.72159;10.61798115994;14.20455;0.69834
62.6000000000001;2.72309;10.66306753083;14.22727;0.70026
62.7000000000001;2.72458;10.70795548469;14.25;0.70216
62.8000000000001;2.72607;10.75025966621;14.27273;0.70389
62.9000000000001;2.72756;10.79071996463;14.29545;0.70549
63.0000000000001;2.72904;10.83614230355;14.31818;0.7074
63.1000000000001;2.73052;10.88491094246;14.34091;0.70953
63.2000000000001;2.732;10.93229872608;14.36364;0.71157
63.3000000000001;2.73348;10.96948626012;14.38636;0.71294
63.4000000000001;2.73496;11.01763058713;14.40909;0.71501
63.5000000000001;2.73643;11.05783758363;14.43182;0.71656
63.6000000000001;2.7379;11.10517979202;14.45455;0.71857
63.7000000000001;2.73937;11.14074633132;14.47727;0.71981
63.8000000000001;2.74084;11.19510909946;14.5;0.72226
63.9000000000001;2.74231;11.23603335027;14.52273;0.72384
64.0000000000001;2.74377;11.28367228264;14.54546;0.72585
64.1000000000001;2.74523;11.33000003081;14.56818;0.72777
64.2000000000001;2.74669;11.3759300127;14.59091;0.72965
64.3000000000001;2.74814;11.41791217626;14.61364;0.73128
64.4000000000001;2.7496;11.4710406209;14.63636;0.73361
64.5000000000001;2.75105;11.51253376519;14.6591;0.7352
64.6000000000001;2.7525;11.55328096735;14.68182;0.73673
64.7000000000001;2.75395;11.60088188889;14.70455;0.7387
64.8000000000001;2.7554;11.64373859862;14.72727;0.74035
64.9000000000001;2.75684;11.69304473947;14.75;0.74242
65.0000000000001;2.75828;11.7355954637;14.77273;0.74404
65.1000000000001;2.75972;11.78680376942;14.79546;0.74621
65.2000000000001;2.76116;11.82596435553;14.81819;0.74762
65.3000000000001;2.7626;11.87897700215;14.84091;0.74989
65.4000000000001;2.76403;11.92534361971;14.86363;0.75174
65.5000000000001;2.76546;11.97148941955;14.88636;0.75357
65.6000000000001;2.76689;12.01343072875;14.90909;0.75513
65.7000000000001;2.76832;12.06100541729;14.93182;0.75704
65.8000000000001;2.76974;12.10879969161;14.95455;0.75896
65.9000000000001;2.77117;12.15408690582;14.97727;0.76071
66.0000000000001;2.77259;12.20058726365;15;0.76254
66.1000000000001;2.77401;12.24085431692;15.02273;0.76397
66.2000000000001;2.77543;12.29701169876;15.04545;0.76639
66.3000000000001;2.77684;12.34842634916;15.06818;0.7685
66.4000000000001;2.77825;12.3893888176;15.09092;0.76996
66.5000000000001;2.77967;12.4331278709;15.11364;0.77159
66.6000000000001;2.78108;12.48144434102;15.13636;0.7735
66.7000000000001;2.78248;12.52694641272;15.15909;0.77523
66.8000000000001;2.78389;12.57838789301;15.18182;0.77732
66.9000000000001;2.78529;12.62590157697;15.20455;0.77916
67.0000000000001;2.78669;12.67197783688;15.22728;0.78091
67.1000000000001;2.78809;12.71400252797;15.25;0.7824
67.2000000000001;2.78949;12.75880874041;15.27273;0.78406
67.3000000000001;2.79089;12.82044758509;15.29545;0.78675
67.4000000000001;2.79228;12.86199354919;15.31818;0.7882
67.5000000000001;2.79367;12.91068816522;15.34091;0.79008
67.6000000000001;2.79506;12.95844390465;15.36364;0.7919
67.7000000000001;2.79645;13.00592473285;15.38637;0.7937
67.8000000000001;2.79784;13.04334894404;15.40909;0.79489
67.9000000000001;2.79922;13.10278641693;15.43182;0.7974
68.0000000000001;2.8006;13.15094462417;15.45454;0.79923
68.1000000000001;2.80198;13.19869228598;15.47727;0.80102
68.2000000000001;2.80336;13.25052472251;15.5;0.80306
68.3000000000001;2.80474;13.29745543654;15.52273;0.8048
68.4000000000001;2.80611;13.33997734338;15.54546;0.80626
68.5000000000001;2.80748;13.38905946539;15.56818;0.80812
68.6000000000001;2.80885;13.43806195525;15.59091;0.80997
68.7000000000001;2.81022;13.49508601667;15.61363;0.81229
68.8000000000001;2.81159;13.54006536544;15.63637;0.81388
68.9000000000001;2.81296;13.58565232307;15.6591;0.81551
69.0000000000001;2.81432;13.63084520877;15.68182;0.81711
69.1000000000001;2.81568;13.6794676577;15.70455;0.81891
69.2000000000001;2.81704;13.7341530924;15.72727;0.82106
69.3000000000001;2.8184;13.78111660417;15.75;0.82275
69.4000000000001;2.81975;13.83141596923;15.77273;0.82464
69.5000000000001;2.82111;13.88286334046;15.79546;0.82658
69.6000000000001;2.82246;13.93082825931;15.81819;0.82832
69.7000000000001;2.82381;13.97689836162;15.84091;0.82994
69.8000000000001;2.82516;14.02304293449;15.86364;0.83156
69.9000000000001;2.82651;14.07385934083;15.88636;0.83345
70.0000000000001;2.82785;14.12734376758;15.90909;0.83549
70.1000000000001;2.82919;14.17065072055;15.93182;0.83692
70.2000000000001;2.83054;14.22647991115;15.95455;0.8391
70.3000000000001;2.83188;14.2721355579;15.97728;0.84066
70.4000000000001;2.83321;14.32774874924;16;0.84281
70.5000000000001;2.83455;14.37918163357;16.02273;0.8447
70.6000000000001;2.83588;14.42370733271;16.04546;0.84619
70.7000000000001;2.83722;14.48559334271;16.06818;0.84869
70.8000000000001;2.83855;14.52896752705;16.09091;0.8501
70.9000000000001;2.83988;14.57618469562;16.11364;0.85173
71.0000000000001;2.8412;14.63014814044;16.13637;0.85375
71.1000000000001;2.84253;14.68331784128;16.15909;0.85572
71.2000000000001;2.84385;14.72644718292;16.18182;0.85709
71.3000000000001;2.84517;14.79056786069;16.20455;0.85969
71.4000000000001;2.84649;14.83948610112;16.22728;0.86139
71.5000000000001;2.84781;14.88317065191;16.25001;0.86279
71.6000000000001;2.84913;14.92571808846;16.27273;0.86412
71.7000000000001;2.85044;14.98156173355;16.29545;0.86621
71.8000000000001;2.85176;15.02885866824;16.31818;0.86781
71.9000000000001;2.85307;15.08688274281;16.34091;0.87002
72.0000000000001;2.85438;15.13337336159;16.36364;0.87156
72.1000000000001;2.85569;15.17984430597;16.38636;0.87309
72.2000000000001;2.85699;15.23657667126;16.40909;0.87521
72.3000000000001;2.8583;15.29607179366;16.43182;0.87748
72.4000000000001;2.8596;15.33766480281;16.45455;0.87872
72.5000000000001;2.8609;15.39346892432;16.47727;0.88077
72.6000000000001;2.8622;15.43400650374;16.50001;0.88194
72.7000000000001;2.8635;15.49700144733;16.52273;0.88439
72.8000000000001;2.8648;15.54500656712;16.54546;0.88598
72.9000000000001;2.86609;15.59611170011;16.56818;0.88775
73.0000000000001;2.86738;15.64598551677;16.59091;0.88944
73.1000000000001;2.86867;15.69926708453;16.61364;0.89131
73.2000000000001;2.86996;15.74990760449;16.63637;0.89304
73.3000000000001;2.87125;15.79832558584;16.6591;0.89463
73.4000000000001;2.87254;15.85014137206;16.68182;0.89641
73.5000000000001;2.87382;15.90060685204;16.70454;0.89811
73.6000000000001;2.8751;15.94396454504;16.72727;0.8994
73.7000000000001;2.87639;15.98349504755;16.75;0.90048
73.8000000000001;2.87767;16.02869789583;16.77273;0.90187
73.9000000000001;2.87894;16.06950516552;16.79546;0.90301
74.0000000000001;2.88022;16.11550083099;16.81819;0.90444
74.1000000000001;2.88149;16.15975940373;16.84091;0.90577
74.2000000000001;2.88277;16.21924763414;16.86363;0.90795
74.3000000000001;2.88404;16.25967838515;16.88636;0.90905
74.4000000000001;2.88531;16.31667961075;16.90909;0.91108
74.5000000000001;2.88658;16.36610165959;16.93182;0.91268
74.6000000000001;2.88784;16.4099025274;16.95455;0.91397
74.7000000000001;2.88911;16.45784263192;16.97727;0.91548
74.8000000000001;2.89037;16.51602416229;17;0.91756
74.9000000000001;2.89163;16.56859608531;17.02273;0.91932
75.0000000000001;2.89289;16.61592896717;17.04546;0.92078
75.1000000000001;2.89415;16.66259221038;17.06819;0.92221
75.2000000000001;2.89541;16.69511774412;17.09091;0.92285