File: data/materialdata/Ecoflex0030.csv
PARAMETER;INFO;URL;;
Specimen Thickness (mm);3;;;
Specimen Width (mm);6;;;
Specimen Length (mm);33;;;
Specimen Cross-section (cm^2);0.18;;;
Standard;ASTM D412;;;
Type of test;Pull-to-failure;;;
Speed (mm/min);450;;;
Machine;Instron  5569;;;
Load Cell;1 kN - Instron  2525-806;;;
Grippers;Instron 2710-010 ;;;
Strain Measurement;Global;;;
Strain calculation;Derived from the machine crosshead displacement readings;;;
Lab;Univ. Savoie Mont Blanc - SYMME Lab, 7400 Annecy, France;;;
Material supplier;Smooth-On;https://www.smooth-on.com/products/ecoflex-00-30;;
Material;EcoFlex30;;;
;;;;
Time (s);True Strain;True Stress (MPa);Engineering Strain;Engineering Stress (MPa)
0.3;0.06574;0.00159510252;0.06795;0.00149
0.4;0.08695;0.00373708299;0.09084;0.00343
0.5;0.10761;0.00425609885;0.11362;0.00382
0.6;0.12783;0.00548715153;0.13636;0.00483
0.7;0.14763;0.00719867429;0.15909;0.00621
0.8;0.16705;0.00806046794;0.18181;0.00682
0.9;0.1861;0.00905619565;0.20455;0.00752
1;0.20479;0.00963664246;0.22727;0.00785
1.1;0.22314;0.01069921669;0.25;0.00856
1.2;0.24116;0.01267747105;0.27272;0.00996
1.3;0.25886;0.01390420053;0.29545;0.01073
1.4;0.27625;0.01471228108;0.31818;0.01116
1.5;0.29335;0.01631286046;0.34091;0.01217
1.6;0.31015;0.01683631171;0.36364;0.01235
1.7;0.32668;0.01792636027;0.38636;0.01293
1.8;0.34294;0.01947541624;0.40909;0.01382
1.9;0.35894;0.02118816368;0.43182;0.0148
2;0.37469;0.02217395929;0.45455;0.01524
2.1;0.3902;0.02342571942;0.47727;0.01586
2.2;0.40547;0.02534049542;0.5;0.01689
2.3;0.4205;0.02540714119;0.52273;0.01669
2.4;0.43532;0.02769224443;0.54545;0.01792
2.5;0.44991;0.02959646245;0.56818;0.01887
2.6;0.4643;0.03036411204;0.59091;0.01909
2.7;0.47849;0.03208786586;0.61364;0.01989
2.8;0.49248;0.03316823562;0.63637;0.02027
2.9;0.50627;0.03405036006;0.65909;0.02052
3;0.51988;0.03615228304;0.68182;0.0215
3.1;0.5333;0.03715101311;0.70454;0.0218
3.2;0.54654;0.0396068815;0.72727;0.02293
3.3;0.55961;0.04004692485;0.75;0.02288
3.4;0.57252;0.04310488549;0.77273;0.02432
3.5;0.58526;0.04375761611;0.79546;0.02437
3.6;0.59784;0.04516320353;0.81818;0.02484
3.7;0.61026;0.04636370009;0.84091;0.02519
3.8;0.62253;0.04838562741;0.86363;0.02596
3.9;0.63465;0.05035636325;0.88636;0.02669
4;0.64663;0.05133923669;0.90909;0.02689
4.1;0.65846;0.05322431353;0.93182;0.02755
4.2;0.67016;0.05506096501;0.95455;0.02817
4.3;0.68172;0.05582765268;0.97727;0.02823
4.4;0.69314;0.05943604995;0.99999;0.02972
4.5;0.70444;0.05973634703;1.02272;0.02953
4.6;0.71562;0.06148747941;1.04545;0.03006
4.7;0.72667;0.06447508847;1.06819;0.03117
4.8;0.7376;0.06473564872;1.09091;0.03096
4.9;0.74841;0.06664103846;1.11363;0.03153
5;0.7591;0.06854256532;1.13636;0.03208
5.1;0.76969;0.06991573844;1.15909;0.03238
5.2;0.78016;0.07278384115;1.18182;0.03336
5.3;0.79052;0.07458890876;1.20455;0.03383
5.4;0.80078;0.07608565247;1.22728;0.03416
5.5;0.81093;0.0776402252;1.25;0.03451
5.6;0.82098;0.07960582565;1.27272;0.03503
5.7;0.83093;0.08057279453;1.29545;0.0351
5.8;0.84078;0.08426222714;1.31818;0.03635
5.9;0.85054;0.08656071984;1.34091;0.03698
6;0.8602;0.08773057765;1.36364;0.03712
6.1;0.86977;0.0899101566;1.38636;0.03768
6.2;0.87925;0.09287090832;1.40909;0.03855
6.3;0.88864;0.09388938002;1.43181;0.03861
6.4;0.89794;0.09719773808;1.45454;0.0396
6.5;0.90716;0.09919470579;1.47727;0.04004
6.6;0.91629;0.10018871922;1.5;0.04008
6.7;0.92534;0.10244723057;1.52273;0.04061
6.8;0.93431;0.10561205288;1.54545;0.04149
6.9;0.9432;0.10736393441;1.56818;0.04181
7;0.95201;0.11064446908;1.5909;0.0427
7.1;0.96074;0.11322889249;1.61364;0.04332
7.2;0.9694;0.11419923352;1.63637;0.04332
7.3;0.97798;0.11739384146;1.65909;0.04415
7.4;0.98649;0.11832940195;1.68182;0.04412
7.5;0.99493;0.1229353712;1.70454;0.04546
7.6;1.0033;0.12430134443;1.72727;0.04558
7.7;1.0116;0.12831032516;1.75;0.04666
7.8;1.01983;0.13047957856;1.77273;0.04706
7.9;1.028;0.13080012175;1.79546;0.04679
8;1.03609;0.13519295494;1.81818;0.04797
8.1;1.04412;0.13837482687;1.84091;0.04871
8.2;1.05209;0.14048024099;1.86363;0.04906
8.3;1.06;0.14336487794;1.88636;0.04967
8.4;1.06784;0.14757598036;1.90909;0.05073
8.5;1.07562;0.14967115981;1.93182;0.05105
8.6;1.08335;0.1513748099;1.95455;0.05123
8.7;1.09101;0.15454253178;1.97727;0.05191
8.8;1.09861;0.15716754501;2;0.05239
8.9;1.10616;0.1605565789;2.02272;0.05312
9;1.11365;0.16309306371;2.04545;0.05355
9.1;1.12109;0.1663080667;2.06818;0.0542
9.2;1.12847;0.16868588221;2.09091;0.05457
9.3;1.13579;0.17397419675;2.11364;0.05587
9.4;1.14306;0.17544607109;2.13636;0.05594
9.5;1.15028;0.18007544115;2.15909;0.057
9.6;1.15745;0.18251337222;2.18182;0.05736
9.7;1.16457;0.18507197722;2.20454;0.05775
9.8;1.17164;0.18844735987;2.22727;0.05839
9.9;1.17865;0.19253576249;2.25;0.05924
10;1.18562;0.19455200444;2.27273;0.05945
10.1;1.19254;0.19770577668;2.29545;0.05999
10.2;1.19942;0.20244422272;2.31818;0.06101
10.3;1.20624;0.20567975216;2.34091;0.06156
10.4;1.21302;0.20914668042;2.36364;0.06218
10.5;1.21976;0.21139213588;2.38636;0.06242
10.6;1.22644;0.21471360063;2.40909;0.06298
10.7;1.23309;0.21983118821;2.43182;0.06406
10.8;1.23969;0.22296055162;2.45455;0.06454
10.9;1.24625;0.22643026472;2.47727;0.06512
11;1.25276;0.23073775477;2.5;0.06593
11.1;1.25923;0.23474888464;2.52272;0.06664
11.2;1.26567;0.23771763844;2.54545;0.06705
11.3;1.27205;0.24170528004;2.56818;0.06774
11.4;1.2784;0.24478181177;2.59091;0.06817
11.5;1.28472;0.24895960785;2.61364;0.06889
11.6;1.29098;0.25247276062;2.63637;0.06943
11.7;1.29721;0.25659163911;2.65909;0.07012
11.8;1.30341;0.26001659377;2.68181;0.07062
11.9;1.30956;0.26525421501;2.70455;0.0716
12;1.31568;0.26959894836;2.72727;0.07233
12.1;1.32176;0.27372147818;2.75;0.07299
12.2;1.3278;0.27741406759;2.77273;0.07353
12.3;1.3338;0.28259241962;2.79545;0.07446
12.4;1.33977;0.28677058291;2.81818;0.07511
12.5;1.34571;0.29070908767;2.8409;0.07569
12.6;1.35161;0.29473385139;2.86363;0.07628
12.7;1.35747;0.29953392724;2.88636;0.07707
12.8;1.36331;0.30480133432;2.90909;0.07797
12.9;1.3691;0.30713295181;2.93182;0.07811
13;1.37487;0.31051887094;2.95454;0.07852
13.1;1.3806;0.31468087582;2.97727;0.07912
13.2;1.38629;0.32060481696;3;0.08015
13.3;1.39196;0.32845353878;3.02273;0.08165
13.4;1.39759;0.3319747208;3.04546;0.08206
13.5;1.4032;0.33535858969;3.06818;0.08243
13.6;1.40877;0.34016193443;3.09091;0.08315
13.7;1.41431;0.34645411664;3.11364;0.08422
13.8;1.41982;0.35062269433;3.13636;0.08477
13.9;1.4253;0.35596909476;3.15909;0.08559
14;1.43075;0.36034878773;3.18182;0.08617
14.1;1.43617;0.36771885465;3.20455;0.08746
14.2;1.44156;0.36903067291;3.22727;0.0873
14.3;1.44692;0.37456628551;3.25;0.08813
14.4;1.45225;0.38097655744;3.27273;0.08916
14.5;1.45756;0.3867069594;3.29545;0.09003
14.6;1.46283;0.39253953368;3.31818;0.0909
14.7;1.46808;0.39727477103;3.34091;0.09152
14.8;1.47331;0.40093717042;3.36364;0.09188
14.9;1.4785;0.40638433253;3.38636;0.09265
15;1.48367;0.41396007317;3.40909;0.09389
15.1;1.48881;0.41616011154;3.43181;0.0939
15.2;1.49392;0.4256318417;3.45455;0.09555
15.3;1.49901;0.43035066339;3.47728;0.09612
15.4;1.50408;0.43406711816;3.5;0.09646
15.5;1.50912;0.44061714481;3.52273;0.09742
15.6;1.51413;0.44509513135;3.54545;0.09792
15.7;1.51911;0.45587390438;3.56818;0.09979
15.8;1.52408;0.46035082648;3.59091;0.10027
15.9;1.52902;0.4661382365;3.61364;0.10103
16;1.53393;0.46953487178;3.63637;0.10127
16.1;1.53882;0.47536290993;3.65909;0.10203
16.2;1.54369;0.48213141287;3.68182;0.10298
16.3;1.54853;0.48997123827;3.70454;0.10415
16.4;1.55335;0.49522300618;3.72727;0.10476
16.5;1.55814;0.50389303867;3.75;0.10608
16.6;1.56292;0.50670961179;3.77273;0.10617
16.7;1.56767;0.51328472917;3.79546;0.10704
16.8;1.5724;0.51851977645;3.81818;0.10762
16.9;1.5771;0.52789872299;3.84091;0.10905
17;1.58179;0.53106507314;3.86363;0.10919
17.1;1.58645;0.54014870142;3.88636;0.11054
17.2;1.59109;0.54509359112;3.90909;0.11104
17.3;1.59571;0.5534203912;3.93182;0.11221
17.4;1.60031;0.55838521647;3.95454;0.1127
17.5;1.60488;0.5671444127;3.97727;0.11395
17.6;1.60944;0.5737752233;4;0.11476
17.7;1.61397;0.58084158566;4.02273;0.11564
17.8;1.61849;0.58799978843;4.04546;0.11654
17.9;1.62298;0.59514357093;4.06818;0.11743
18;1.62746;0.59935596796;4.09091;0.11773
18.1;1.63191;0.61071549205;4.11363;0.11943
18.2;1.63634;0.61601247555;4.13636;0.11993
18.3;1.64076;0.62699672084;4.15909;0.12153
18.4;1.64516;0.63185832597;4.18182;0.12194
18.5;1.64953;0.63729559062;4.20454;0.12245
18.6;1.65389;0.64444485683;4.22727;0.12329
18.7;1.65823;0.651355811;4.25;0.12407
18.8;1.66255;0.66156261948;4.27272;0.12547
18.9;1.66685;0.66822306883;4.29545;0.12619
19;1.67113;0.67856706702;4.31818;0.12759
19.1;1.6754;0.68566906885;4.34091;0.12838
19.2;1.67964;0.69280964356;4.36364;0.12917
19.3;1.68387;0.70002084689;4.38636;0.12996
19.4;1.68808;0.70906558087;4.40909;0.13109
19.5;1.69227;0.71712112248;4.43182;0.13202
19.6;1.69645;0.72482435408;4.45455;0.13288
19.7;1.70061;0.73277132276;4.47727;0.13378
19.8;1.70475;0.73780907009;4.5;0.13415
19.9;1.70887;0.75074721565;4.52272;0.13594
20;1.71298;0.75825515534;4.54545;0.13673
20.1;1.71707;0.76610357711;4.56818;0.13759
20.2;1.72114;0.77487301349;4.59091;0.1386
20.3;1.7252;0.78339659666;4.61364;0.13955
20.4;1.72924;0.79171316701;4.63636;0.14047
20.5;1.73326;0.802491924;4.65909;0.14181
20.6;1.73727;0.81023078212;4.68182;0.1426
20.7;1.74126;0.81842518677;4.70454;0.14347
20.8;1.74524;0.82963473882;4.72727;0.14486
20.9;1.7492;0.8369340845;4.75;0.14555
21;1.75314;0.84592693517;4.77273;0.14654
21.1;1.75707;0.85344221792;4.79545;0.14726
21.2;1.76099;0.86326380344;4.81818;0.14837
21.3;1.76489;0.87364088917;4.84091;0.14957
21.4;1.76877;0.88396491016;4.86363;0.15075
21.5;1.77264;0.89377066215;4.88636;0.15184
21.6;1.77649;0.90247034599;4.90909;0.15273
21.7;1.78033;0.91224897755;4.93182;0.15379
21.8;1.78415;0.9196508491;4.95454;0.15445
21.9;1.78796;0.93042572552;4.97727;0.15566
22;1.79176;0.94005933093;5;0.15668
22.1;1.79554;0.94899115855;5.02273;0.15757
22.2;1.79931;0.96073980524;5.04546;0.15892
22.3;1.80306;0.96965812087;5.06818;0.15979
22.4;1.8068;0.9813907907;5.09091;0.16112
22.5;1.81052;0.99192031104;5.11363;0.16225
22.6;1.81423;1.00230812064;5.13636;0.16334
22.7;1.81793;1.01295995914;5.15909;0.16447
22.8;1.82161;1.02374857634;5.18182;0.16561
22.9;1.82528;1.02990953429;5.20455;0.16599
23;1.82894;1.04311845762;5.22727;0.16751
23.1;1.83258;1.05287481303;5.25;0.16846
23.2;1.83621;1.06672032257;5.27273;0.17006
23.3;1.83983;1.07556281361;5.29545;0.17085
23.4;1.84343;1.08748822495;5.31818;0.17212
23.5;1.84702;1.09455575249;5.34091;0.17262
23.6;1.8506;1.10751124369;5.36364;0.17404
23.7;1.85416;1.11698235562;5.38636;0.1749
23.8;1.85772;1.129716488;5.40909;0.17627
23.9;1.86126;1.14327468133;5.43181;0.17775
24;1.86478;1.15194542161;5.45455;0.17847
24.1;1.8683;1.16308161555;5.47727;0.17956
24.2;1.8718;1.17563473678;5.5;0.18087
24.3;1.87529;1.18770776834;5.52273;0.18209
24.4;1.87877;1.19999916955;5.54545;0.18333
24.5;1.88224;1.21416487086;5.56818;0.18486
24.6;1.88569;1.22403980774;5.59091;0.18572
24.7;1.88913;1.23597414165;5.61364;0.18688
24.8;1.89256;1.24381015539;5.63637;0.18742
24.9;1.89598;1.25833110846;5.65909;0.18896
25;1.89939;1.27115521651;5.68182;0.19024
25.1;1.90279;1.2828040512;5.70454;0.19133
25.2;1.90617;1.29704741528;5.72727;0.1928
25.3;1.90954;1.31259048165;5.75;0.19446
25.4;1.9129;1.31986737008;5.77273;0.19488
25.5;1.91625;1.33330086067;5.79546;0.1962
25.6;1.91959;1.34648794383;5.81818;0.19749
25.7;1.92292;1.3599087598;5.8409;0.19879
25.8;1.92624;1.37445302133;5.86363;0.20025
25.9;1.92954;1.38382918044;5.88636;0.20095
26;1.93284;1.39805697378;5.90909;0.20235
26.1;1.93612;1.41075036957;5.93182;0.20352
26.2;1.9394;1.42188802436;5.95454;0.20445
26.3;1.94266;1.4399742;5.97727;0.20638
26.4;1.94591;1.45093282315;6;0.20728
26.5;1.94915;1.46932080499;6.02273;0.20922
26.6;1.95238;1.48003077781;6.04546;0.21007
26.7;1.9556;1.49048825583;6.06818;0.21087
26.8;1.95881;1.50761435371;6.09091;0.21261
26.9;1.96201;1.52205001504;6.11363;0.21396
27;1.9652;1.53471982171;6.13636;0.21506
27.1;1.96838;1.54776316428;6.15909;0.2162
27.2;1.97155;1.56558343134;6.18182;0.21799
27.3;1.97471;1.57502224435;6.20455;0.21862
27.4;1.97786;1.59150285094;6.22727;0.22021
27.5;1.981;1.60820871954;6.25;0.22182
27.6;1.98413;1.62038495557;6.27272;0.2228
27.7;1.98725;1.63568177104;6.29545;0.22421
27.8;1.99036;1.6509913568;6.31818;0.2256
27.9;1.99346;1.66919467492;6.34091;0.22738
28;1.99655;1.67862017372;6.36364;0.22796
28.1;1.99964;1.69365955593;6.38636;0.2293
28.2;2.00271;1.71361046749;6.40909;0.23128
28.3;2.00577;1.7256102848;6.43182;0.23219
28.4;2.00882;1.74485905802;6.45455;0.23407
28.5;2.01187;1.75758886549;6.47728;0.23506
28.6;2.0149;1.76863187442;6.5;0.23582
28.7;2.01793;1.78920334544;6.52273;0.23784
28.8;2.02095;1.80501487879;6.54545;0.23922
28.9;2.02395;1.82294473626;6.56818;0.24087
29;2.02695;1.83865341942;6.59091;0.24222
29.1;2.02994;1.85451095972;6.61364;0.24358
29.2;2.03292;1.86816142699;6.63636;0.24464
29.3;2.03589;1.88692456713;6.65909;0.24636
29.4;2.03886;1.9051659787;6.68182;0.24801
29.5;2.04181;1.91996471686;6.70455;0.2492
29.6;2.04476;1.93929563045;6.72727;0.25097
29.7;2.04769;1.95719114551;6.75;0.25254
29.8;2.05062;1.96947760209;6.77273;0.25338
29.9;2.05354;1.98779038788;6.79545;0.25499
30;2.05645;2.00281783965;6.81818;0.25617
30.1;2.05935;2.02173107992;6.84091;0.25784
30.2;2.06225;2.04501922059;6.86364;0.26006
30.3;2.06514;2.05945362284;6.88636;0.26114
30.4;2.06801;2.07385648186;6.90909;0.26221
30.5;2.07088;2.09347654184;6.93182;0.26393
30.6;2.07374;2.11159524099;6.95454;0.26546
30.7;2.0766;2.12826728097;6.97727;0.26679
30.8;2.07944;2.14665579448;7;0.26833
30.9;2.08228;2.16741665928;7.02273;0.27016
31;2.08511;2.18021587282;7.04546;0.27099
31.1;2.08793;2.20430464728;7.06818;0.27321
31.2;2.09074;2.22029298077;7.09091;0.27442
31.3;2.09355;2.24022418109;7.11363;0.27611
31.4;2.09634;2.26225310267;7.13636;0.27804
31.5;2.09913;2.28272042349;7.15909;0.27978
31.6;2.10191;2.29612205144;7.18182;0.28064
31.7;2.10469;2.31433545999;7.20454;0.28208
31.8;2.10745;2.33294540214;7.22727;0.28356
31.9;2.11021;2.35481738669;7.25;0.28543
32;2.11296;2.37463821832;7.27272;0.28704
32.1;2.11571;2.39689587034;7.29546;0.28894
32.2;2.11844;2.4169515345;7.31818;0.29056
32.3;2.12117;2.43156120591;7.34091;0.29152
32.4;2.12389;2.45505144207;7.36364;0.29354
32.5;2.12661;2.47491220447;7.38636;0.29511
32.6;2.12931;2.49161320625;7.40909;0.2963
32.7;2.13201;2.51812247667;7.43182;0.29865
32.8;2.1347;2.5376082636;7.45455;0.30015
32.9;2.13739;2.55529097152;7.47728;0.30143
33;2.14007;2.57483977943;7.5;0.30292
33.1;2.14274;2.59739793384;7.52272;0.30476
33.2;2.1454;2.61659791339;7.54545;0.3062
33.3;2.14806;2.63861277548;7.56818;0.30795
33.4;2.15071;2.66356369958;7.59091;0.31004
33.5;2.15335;2.68495331059;7.61364;0.31171
33.6;2.15598;2.70152821069;7.63636;0.31281
33.7;2.15861;2.72341398787;7.65909;0.31452
33.8;2.16123;2.74764748588;7.68182;0.31648
33.9;2.16385;2.77284434187;7.70454;0.31855
34;2.16645;2.79416794062;7.72728;0.32016
34.1;2.16905;2.81835183472;7.75;0.3221
34.2;2.17165;2.83511333251;7.77273;0.32317
34.3;2.17423;2.86055316163;7.79545;0.32523
34.4;2.17682;2.88117096107;7.81818;0.32673
34.5;2.17939;2.90414890949;7.84091;0.32849
34.6;2.18196;2.92886790785;7.86363;0.33044
34.7;2.18452;2.94783823166;7.88637;0.33173
34.8;2.18707;2.97199006634;7.90909;0.33359
34.9;2.18962;2.99984908577;7.93182;0.33586
35;2.19216;3.01816081615;7.95454;0.33705
35.1;2.1947;3.04567312183;7.97727;0.33926
35.2;2.19722;3.06712127963;8;0.34079
35.3;2.19975;3.09446060035;8.02273;0.34296
35.4;2.20226;3.11681277917;8.04546;0.34457
35.5;2.20477;3.141598678;8.06818;0.34644
35.6;2.20727;3.16178687998;8.09091;0.3478
35.7;2.20977;3.19112198268;8.11363;0.35015
35.8;2.21226;3.21422224846;8.13636;0.35181
35.9;2.21475;3.23881689854;8.15909;0.35362
36;2.21723;3.25863906637;8.18182;0.3549
36.1;2.2197;3.28583650921;8.20455;0.35698
36.2;2.22216;3.31302155407;8.22727;0.35905
36.3;2.22462;3.34069294638;8.25;0.36116
36.4;2.22708;3.37045103895;8.27272;0.36348
36.5;2.22953;3.39393615632;8.29545;0.36512
36.6;2.23197;3.41444463466;8.31818;0.36643
36.7;2.2344;3.44446257605;8.34091;0.36875
36.8;2.23683;3.47179032536;8.36364;0.37077
36.9;2.23926;3.49951741945;8.38636;0.37283
37;2.24168;3.52441502559;8.40909;0.37458
37.1;2.24409;3.54629465703;8.43182;0.37599
37.2;2.2465;3.57715371026;8.45455;0.37835
37.3;2.2489;3.59773869712;8.47727;0.37962
37.4;2.25129;3.62541888613;8.5;0.38162
37.5;2.25368;3.65498260493;8.52273;0.38382
37.6;2.25606;3.68470251901;8.54545;0.38602
37.7;2.25844;3.71113478855;8.56818;0.38786
37.8;2.26082;3.74163917647;8.59091;0.39012
37.9;2.26318;3.76062904963;8.61364;0.39118
38;2.26554;3.79160835722;8.63636;0.39347
38.1;2.2679;3.82289239994;8.65909;0.39578
38.2;2.27025;3.84796945048;8.68182;0.39744
38.3;2.27259;3.87989661077;8.70454;0.3998
38.4;2.27493;3.90648150136;8.72727;0.4016
38.5;2.27727;3.93472671322;8.75;0.40356
38.6;2.2796;3.96105691612;8.77273;0.40532
38.7;2.28192;3.99276258181;8.79545;0.40761
38.8;2.28424;4.02333581746;8.81818;0.40978
38.9;2.28655;4.05003458579;8.84091;0.41155
39;2.28885;4.07923503803;8.86364;0.41356
39.1;2.29116;4.10583274418;8.88636;0.4153
39.2;2.29345;4.13646759286;8.90909;0.41744
39.3;2.29574;4.16760151898;8.93182;0.41962
39.4;2.29803;4.19992925007;8.95454;0.42191
39.5;2.30031;4.22919982828;8.97727;0.42388
39.6;2.30259;4.25689201215;9;0.42569
39.7;2.30486;4.29174019788;9.02273;0.4282
39.8;2.30712;4.319434147;9.04546;0.42999
39.9;2.30938;4.34685362619;9.06818;0.43174
40;2.31163;4.38061432639;9.09091;0.43412
40.1;2.31388;4.41118986179;9.11363;0.43616
40.2;2.31613;4.44252030696;9.13636;0.43828
40.3;2.31837;4.48138701853;9.15909;0.44112
40.4;2.3206;4.50655666692;9.18182;0.44261
40.5;2.32283;4.53891579827;9.20455;0.44479
40.6;2.32506;4.57408306065;9.22727;0.44724
40.7;2.32728;4.60395228402;9.25;0.44917
40.8;2.32949;4.63325746257;9.27273;0.45103
40.9;2.3317;4.67265397123;9.29546;0.45386
40.10;2.33391;4.69761805314;9.31818;0.45528
40.11;2.33611;4.72567447862;9.34091;0.45699
40.12;2.3383;4.76547302842;9.36363;0.45983
40.13;2.34049;4.80072172004;9.38636;0.46221
40.14;2.34268;4.83414530926;9.40909;0.46442
40.15;2.34486;4.86785853971;9.43182;0.46664
40.16;2.34704;4.89718558489;9.45455;0.46843
40.17;2.34921;4.93230775991;9.47727;0.47076
40.18;2.35137;4.96375952661;9.5;0.47274
40.19;2.35354;5.00332737109;9.52272;0.47548
40.20;2.35569;5.03488118768;9.54545;0.47745
40.21;2.35785;5.07145546934;9.56818;0.47988
40.22;2.36;5.10368811424;9.59091;0.48189
40.23;2.36214;5.13913476779;9.61363;0.4842
40.24;2.36428;5.16836195318;9.63636;0.48591
40.25;2.36641;5.20829005707;9.65909;0.48862
40.26;2.36854;5.24421006445;9.68182;0.49095
40.27;2.37067;5.2815078753;9.70455;0.49339
40.28;2.37279;5.31579741989;9.72727;0.49554
40.29;2.37491;5.35170150337;9.75;0.49783
40.30;2.37702;5.38550476425;9.77272;0.49992
40.31;2.37912;5.41994696068;9.79545;0.50206
40.32;2.38123;5.45734041997;9.81818;0.50446
40.33;2.38333;5.4978820945;9.84091;0.50714
40.34;2.38542;5.53388654732;9.86364;0.5094
40.35;2.38751;5.56598633601;9.88636;0.51128
40.36;2.3896;5.60482828738;9.90909;0.51378
40.37;2.39168;5.64324962858;9.93182;0.51622
40.38;2.39375;5.6812227789;9.95454;0.51862
40.39;2.39583;5.71899479913;9.97727;0.52099
40.40;2.3979;5.75442593814;10;0.52313
40.41;2.39996;5.79414242701;10.02273;0.52565
40.42;2.40202;5.82614471111;10.04546;0.52747
40.43;2.40407;5.86988157903;10.06818;0.53034
40.44;2.40613;5.90913975407;10.09091;0.53279
40.45;2.40817;5.95114123527;10.11363;0.53548
40.46;2.41022;5.9839729173;10.13637;0.53734
40.47;2.41225;6.02473990714;10.15909;0.5399
40.48;2.41429;6.05958129266;10.18182;0.54191
40.49;2.41632;6.10214186233;10.20454;0.54461
40.50;2.41835;6.1381238865;10.22727;0.54672
40.51;2.42037;6.18155957446;10.25;0.54947
40.52;2.42239;6.22366425689;10.27273;0.5521
40.53;2.4244;6.2599125467;10.29545;0.5542
40.54;2.42641;6.30054810904;10.31818;0.55667
40.55;2.42842;6.34374000374;10.34091;0.55937
40.56;2.43042;6.38542986179;10.36363;0.56192
40.57;2.43242;6.42452085527;10.38636;0.56423
40.58;2.43441;6.4721221105;10.40909;0.56728
40.59;2.4364;6.50498000101;10.43182;0.56902
40.60;2.43839;6.54667334071;10.45455;0.57153
40.61;2.44037;6.58585639005;10.47727;0.57382
40.62;2.44235;6.62908263301;10.5;0.57644
40.63;2.44432;6.67653434501;10.52273;0.57942
40.64;2.44629;6.71696371831;10.54545;0.58178
40.65;2.44826;6.75952581384;10.56818;0.58432
40.66;2.45022;6.79456018578;10.59091;0.5862
40.67;2.45218;6.83884207149;10.61364;0.58886
40.68;2.45413;6.88749150139;10.63636;0.59189
40.69;2.45609;6.93089708551;10.65909;0.59446
40.70;2.45803;6.97185577253;10.68182;0.59681
40.71;2.45998;7.01740872261;10.70454;0.59955
40.72;2.46192;7.05868439161;10.72727;0.6019
40.73;2.46385;7.10079547928;10.75;0.60432
40.74;2.46579;7.14045153888;10.77273;0.60652
40.75;2.46771;7.19282422796;10.79545;0.6098
40.76;2.46964;7.22999776513;10.81818;0.61177
40.77;2.47156;7.28228859189;10.84091;0.61501
40.78;2.47348;7.32522368486;10.86364;0.61745
40.79;2.47539;7.37057221354;10.88636;0.62009
40.80;2.4773;7.41296330337;10.90909;0.62246
40.81;2.47921;7.45923064323;10.93182;0.62515
40.82;2.48111;7.50375034868;10.95454;0.62769
40.83;2.48301;7.55163416385;10.97727;0.6305
40.84;2.48491;7.59342557394;11;0.63279
40.85;2.4868;7.64206215365;11.02273;0.63563
40.86;2.48869;7.68354949854;11.04545;0.63788
40.87;2.49057;7.73417202038;11.06818;0.64087
40.88;2.49245;7.77972052537;11.0909;0.64344
40.89;2.49433;7.82846904764;11.11363;0.64625
40.90;2.49621;7.87611319239;11.13636;0.64897
40.91;2.49808;7.9189561811;11.15909;0.65128
40.92;2.49994;7.96904716283;11.18182;0.65418
40.93;2.50181;8.01702316112;11.20455;0.65689
40.94;2.50367;8.06666841223;11.22727;0.65973
40.95;2.50553;8.11280908569;11.25;0.66227
40.96;2.50738;8.1592529502;11.27273;0.66483
40.97;2.50923;8.21035353209;11.29545;0.66776
40.98;2.51108;8.26086720859;11.31818;0.67062
40.99;2.51292;8.30608988657;11.34091;0.67305
40.100;2.51476;8.3568596462;11.36363;0.67592
40.101;2.5166;8.40530668254;11.38636;0.67859
40.102;2.51843;8.45149582724;11.40909;0.68107
40.103;2.52026;8.50493321244;11.43182;0.68413
40.104;2.52209;8.5487244321;11.45455;0.68639
40.105;2.52391;8.60555671159;11.47727;0.6897
40.106;2.52573;8.64819397602;11.5;0.69186
40.107;2.52754;8.71150268074;11.52272;0.69566
40.108;2.52936;8.75832890244;11.54545;0.69813
40.109;2.53117;8.81045896751;11.56818;0.70101
40.110;2.53298;8.856394134;11.59091;0.7034
40.111;2.53478;8.90729355733;11.61364;0.70616
40.112;2.53658;8.9623411568;11.63636;0.70925
40.113;2.53838;9.02071210411;11.65909;0.71259
40.114;2.54017;9.05921857386;11.68182;0.71435
40.115;2.54196;9.12161222608;11.70455;0.71798
40.116;2.54375;9.16789775165;11.72727;0.72033
40.117;2.54553;9.22460454284;11.75;0.7235
40.118;2.54731;9.27763993413;11.77273;0.72636
40.119;2.54909;9.33408927571;11.79545;0.72949
40.120;2.55086;9.3818913911;11.81818;0.73192
40.121;2.55264;9.4349700405;11.84091;0.73476
40.122;2.5544;9.4899439459;11.86364;0.73773
40.123;2.55617;9.54568466308;11.88636;0.74076
40.124;2.55793;9.59212216295;11.90909;0.74305
40.125;2.55969;9.64984145073;11.93182;0.74621
40.126;2.56145;9.70410977906;11.95454;0.74909
40.127;2.5632;9.76328550948;11.97727;0.75234
40.128;2.56495;9.81447473142;12;0.75496
40.129;2.5667;9.87321123891;12.02273;0.75815
40.130;2.56844;9.92505756005;12.04545;0.76081
40.131;2.57018;9.98028205114;12.06818;0.76371
40.132;2.57192;10.03462753691;12.0909;0.76653
40.133;2.57365;10.09224122553;12.11364;0.7696
40.134;2.57538;10.14982861692;12.13637;0.77265
40.135;2.57711;10.2119632775;12.15909;0.77604
40.136;2.57884;10.2619930099;12.18182;0.7785
40.137;2.58056;10.31977305884;12.20454;0.78153
40.138;2.58228;10.37395711326;12.22727;0.78429
40.139;2.584;10.42916473227;12.25;0.78711
40.140;2.58571;10.4846341087;12.27273;0.78994
40.141;2.58742;10.54361326201;12.29546;0.79302
40.142;2.58913;10.59867678859;12.31818;0.79581
40.143;2.59083;10.65942173132;12.34091;0.799
40.144;2.59254;10.72455694793;12.36363;0.80252
40.145;2.59424;10.78914127824;12.38636;0.80598
40.146;2.59593;10.83802108616;12.40909;0.80826
40.147;2.59763;10.90549523778;12.43182;0.81191
40.148;2.59932;10.95481805621;12.45455;0.81421
40.149;2.601;11.01721942435;12.47727;0.81747
40.150;2.60269;11.08010900024;12.5;0.82075
40.151;2.60437;11.13746366356;12.52272;0.82361
40.152;2.60605;11.20123216941;12.54545;0.82694
40.153;2.60773;11.25757589642;12.56819;0.8297
40.154;2.6094;11.32169314148;12.59091;0.83303
40.155;2.61107;11.37553657556;12.61363;0.8356
40.156;2.61274;11.44422135134;12.63636;0.83924
40.157;2.61441;11.49802492791;12.65909;0.84179
40.158;2.61607;11.56933573919;12.68181;0.8456
40.159;2.61773;11.62805471103;12.70455;0.84848
40.160;2.61938;11.68052452158;12.72728;0.8509
40.161;2.62104;11.7435552076;12.75;0.85408
40.162;2.62269;11.80945352804;12.77273;0.85745
40.163;2.62434;11.87552015188;12.79545;0.86083
40.164;2.62598;11.93334172922;12.81818;0.8636
40.165;2.62763;12.0010121247;12.84091;0.86707
40.166;2.62927;12.06300554919;12.86364;0.87012
40.167;2.63091;12.12817071986;12.88637;0.87339
40.168;2.63254;12.18425107182;12.90909;0.87599
40.169;2.63418;12.25118177259;12.93182;0.87937
40.170;2.6358;12.31568632162;12.95454;0.88256
40.171;2.63743;12.38159822017;12.97727;0.88584
40.172;2.63906;12.44580242729;13;0.88899
40.173;2.64068;12.5065854421;13.02273;0.89188
40.174;2.6423;12.57448246199;13.04545;0.89527
40.175;2.64392;12.64386196992;13.06818;0.89876
40.176;2.64553;12.70427142598;13.09091;0.90159
40.177;2.64714;12.77305632191;13.11363;0.90502
40.178;2.64875;12.83649562243;13.13636;0.90805
40.179;2.65036;12.90123277087;13.15909;0.91116
40.180;2.65196;12.96609737685;13.18182;0.91428
40.181;2.65356;13.03368832767;13.20454;0.91757
40.182;2.65516;13.10381055857;13.22727;0.92103
40.183;2.65676;13.17450430051;13.25;0.92453
40.184;2.65835;13.23102640407;13.27273;0.92701
40.185;2.65994;13.30499940016;13.29545;0.93072
40.186;2.66153;13.37167945555;13.31818;0.9339
40.187;2.66312;13.43974572294;13.34091;0.93716
40.188;2.6647;13.51113615832;13.36363;0.94065
40.189;2.66628;13.5734089844;13.38636;0.94349
40.190;2.66786;13.64663695486;13.40909;0.94709
40.191;2.66944;13.71171276823;13.43182;0.9501
40.192;2.67101;13.77463251495;13.45454;0.95296
40.193;2.67258;13.84918196032;13.47727;0.95662
40.194;2.67415;13.91228471443;13.5;0.95947
40.195;2.67571;13.98900105475;13.52272;0.96325
40.196;2.67728;14.06279640471;13.54545;0.96682
40.197;2.67884;14.12456608172;13.56818;0.96955
40.198;2.6804;14.1971473569;13.59091;0.97301
40.199;2.68196;14.2675046156;13.61364;0.97631
40.200;2.68351;14.34185895355;13.63636;0.97988
40.201;2.68506;14.41030992061;13.65909;0.98303
40.202;2.68661;14.48717989117;13.68182;0.98674
40.203;2.68816;14.55479299298;13.70455;0.98982
40.204;2.6897;14.62543179398;13.72727;0.99308
40.205;2.69124;14.69458753447;13.75;0.99624
40.206;2.69278;14.76673405154;13.77273;0.99959
40.207;2.69432;14.84519071658;13.79545;1.00336
40.208;2.69585;14.91405047183;13.81818;1.00647
40.209;2.69739;14.98391311466;13.84091;1.00964
40.210;2.69892;15.05320252407;13.86364;1.01275
40.211;2.70045;15.12407013885;13.88636;1.01597
40.212;2.70197;15.20565507493;13.90909;1.01989
40.213;2.70349;15.27576139755;13.93181;1.02303
40.214;2.70502;15.3529120088;13.95454;1.02664
40.215;2.70653;15.42793925811;13.97727;1.03009
40.216;2.70805;15.49748540779;14;1.03317
40.217;2.70956;15.57329708155;14.02273;1.03665
40.218;2.71108;15.65455669308;14.04545;1.04048
40.219;2.71259;15.7258990964;14.06818;1.04365
40.220;2.71409;15.79908010563;14.09091;1.04693
40.221;2.7156;15.87517835927;14.11364;1.05039
40.222;2.7171;15.95282751815;14.13637;1.05394
40.223;2.7186;16.02552939593;14.15909;1.05716
40.224;2.7201;16.10084626263;14.18182;1.06053
40.225;2.72159;16.17950118458;14.20454;1.06412
40.226;2.72309;16.25460881825;14.22727;1.06747
40.227;2.72458;16.33902844459;14.25;1.07141
40.228;2.72607;16.41354074698;14.27273;1.0747
40.229;2.72756;16.49108009094;14.29545;1.07817
40.230;2.72904;16.56207290226;14.31818;1.0812
40.231;2.73052;16.63555044541;14.3409;1.08439
40.232;2.732;16.72240716507;14.36363;1.08844
40.233;2.73348;16.79671401627;14.38636;1.09166
40.234;2.73496;16.87440067448;14.40909;1.09509
40.235;2.73643;16.9566949195;14.43182;1.09881
40.236;2.7379;17.02568624536;14.45455;1.10166
40.237;2.73937;17.11412846002;14.47727;1.10576
40.238;2.74084;17.19437609965;14.5;1.10931
40.239;2.74231;17.2720234505;14.52273;1.11269
40.240;2.74377;17.35239371547;14.54545;1.11624
40.241;2.74523;17.42562168589;14.56819;1.11931
40.242;2.74669;17.513238644;14.59091;1.1233
40.243;2.74814;17.59326279233;14.61363;1.12679
40.244;2.7496;17.6700453529;14.63636;1.13006
40.245;2.75105;17.74731303083;14.65909;1.13336
40.246;2.7525;17.83560745999;14.68182;1.13734
40.247;2.75395;17.91538814366;14.70455;1.14078
40.248;2.7554;17.98754992879;14.72727;1.14372
40.249;2.75684;18.07553690588;14.75;1.14765
40.250;2.75828;18.15906872637;14.77272;1.1513
40.251;2.75972;18.23808841512;14.79545;1.15464
40.252;2.76116;18.32105283376;14.81818;1.15823
40.253;2.7626;18.4041051784;14.84091;1.16181
40.254;2.76403;18.48385560458;14.86364;1.16517
40.255;2.76546;18.57255355451;14.88636;1.16909
40.256;2.76689;18.65964559744;14.90909;1.17289
40.257;2.76832;18.73803895566;14.93182;1.17614
40.258;2.76974;18.81662683598;14.95454;1.17939
40.259;2.77117;18.90686272789;14.97727;1.18336
40.260;2.77259;18.98595649469;15;1.18662
40.261;2.77401;19.06497732352;15.02273;1.18987
40.262;2.77543;19.14951757075;15.04545;1.19345
40.263;2.77684;19.23963312961;15.06818;1.19738
40.264;2.77825;19.32175273642;15.09091;1.20079
40.265;2.77967;19.41269556773;15.11364;1.20474
40.266;2.78108;19.49715200921;15.13636;1.20827
40.267;2.78248;19.57946439798;15.15909;1.21167
40.268;2.78389;19.6641644047;15.18182;1.2152
40.269;2.78529;19.75356527787;15.20454;1.21901
40.270;2.78669;19.84282346245;15.22727;1.22281
40.271;2.78809;19.92126234046;15.25;1.22592
40.272;2.78949;20.02121186014;15.27273;1.23035
40.273;2.79089;20.09498322557;15.29546;1.23316
40.274;2.79228;20.18522143733;15.31818;1.23698
40.275;2.79367;20.27568756425;15.34091;1.24079
40.276;2.79506;20.36517795322;15.36363;1.24454
40.277;2.79645;20.44899417661;15.38636;1.24793
40.278;2.79784;20.53876205068;15.40909;1.25167
40.279;2.79922;20.62868783995;15.43182;1.25541
40.280;2.8006;20.71236017838;15.45455;1.25876
40.281;2.80198;20.79737100208;15.47727;1.26219
40.282;2.80336;20.89553116025;15.49999;1.2664
40.283;2.80474;20.98326391572;15.52272;1.26996
40.284;2.80611;21.076691022;15.54545;1.27387
40.285;2.80748;21.15906792783;15.56818;1.27709
40.286;2.80885;21.25248154266;15.59091;1.28097
40.287;2.81022;21.34347704508;15.61364;1.2847
40.288;2.81159;21.43587275619;15.63636;1.2885
40.289;2.81296;21.53064082159;15.65909;1.29243
40.290;2.81432;21.62503344002;15.68182;1.29632
40.291;2.81568;21.70597076903;15.70455;1.2994
40.292;2.81704;21.79646286907;15.72727;1.30305
40.293;2.8184;21.88968658306;15.75;1.30685
40.294;2.81975;21.98491826093;15.77272;1.31075
40.295;2.82111;22.06816822813;15.79545;1.31394
40.296;2.82246;22.17154354917;15.81818;1.31831
40.297;2.82381;22.26617429776;15.84091;1.32215
40.298;2.82516;22.34912892415;15.86364;1.32529
40.299;2.82651;22.4441761604;15.88636;1.32913
40.300;2.82785;22.54133913921;15.90909;1.33309
40.301;2.82919;22.63143138461;15.93182;1.33662
40.302;2.83054;22.73187932709;15.95454;1.34075
40.303;2.83188;22.81883282893;15.97727;1.34408
40.304;2.83321;22.91449965192;16;1.34791
40.305;2.83455;23.01216094595;16.02272;1.35185
40.306;2.83588;23.10050560156;16.04545;1.35523
40.307;2.83722;23.20406777357;16.06818;1.35949