File: data/materialdata/SortaClear40.csv
PARAMETER;INFO;URL;;
Specimen Thickness (mm);3;;;
Specimen Width (mm);6;;;
Specimen Length (mm);33;;;
Specimen Cross-section (cm^2);0.18;;;
Standard;ASTM D412;;;
Type of test;Pull-to-failure;;;
Speed (mm/min);450;;;
Machine;Instron  5569;;;
Load Cell;1 kN - Instron  2525-806;;;
Grippers;Instron 2710-010 ;;;
Strain Measurement;Global;;;
Strain calculation;Derived from the machine crosshead displacement readings;;;
Lab;Univ. Savoie Mont Blanc - SYMME Lab, 7400 Annecy, France;;;
Material supplier;Smooth-On;https://www.smooth-on.com/products/sorta-clear-40/;;
Material;SortaClear40;;;
;;;;
Time (s);True Strain;True Stress (MPa);Engineering Strain;Engineering Stress (MPa)
0.2;0.0436366666666667;0.0315731041;0.0446;0.0302233333333333
0.3;0.0657466666666667;0.0530128612233333;0.0679566666666667;0.04964
0.4;0.08695;0.0744204061866667;0.0908433333333333;0.06822
0.5;0.107613333333333;0.0936952961133333;0.11362;0.0841366666666667
0.6;0.12783;0.113713447923333;0.13636;0.100066666666667
0.7;0.147636666666667;0.13440113335;0.15909;0.115953333333333
0.8;0.167053333333333;0.154333086043333;0.18182;0.13059
0.9;0.186103333333333;0.174302367773333;0.204546666666667;0.144706666666667
1;0.204796666666667;0.19473674155;0.227276666666667;0.158673333333333
1.1;0.223146666666667;0.215263307103333;0.25;0.17221
1.2;0.24116;0.235965802793333;0.272726666666667;0.185403333333333
1.3;0.25886;0.257016364243333;0.29545;0.1984
1.4;0.27625;0.278520100396667;0.31818;0.21129
1.5;0.29335;0.30018441516;0.34091;0.223866666666667
1.6;0.31016;0.321795577806667;0.36364;0.235983333333333
1.7;0.326686666666667;0.343912222226667;0.386366666666667;0.248066666666667
1.8;0.342943333333333;0.366636754793333;0.40909;0.260193333333333
1.9;0.358943333333333;0.389106768456667;0.431816666666667;0.271756666666667
2;0.37469;0.412814106506667;0.454546666666667;0.283806666666667
2.1;0.3902;0.436007648936667;0.47727;0.295146666666667
2.2;0.40547;0.460601741973333;0.500003333333333;0.307066666666667
2.3;0.420503333333333;0.484810201326667;0.52273;0.318383333333333
2.4;0.43532;0.510076830673333;0.545456666666667;0.33005
2.5;0.44992;0.53537140137;0.56818;0.341393333333333
2.6;0.464306666666667;0.561527810856667;0.590906666666667;0.35296
2.7;0.47849;0.587638148303333;0.61364;0.36417
2.8;0.49248;0.615020298643333;0.636366666666667;0.375843333333333
2.9;0.50627;0.641908645656667;0.659093333333333;0.3869
3;0.51988;0.669930768553333;0.68182;0.398336666666667
3.1;0.5333;0.699062146313333;0.704546666666667;0.410113333333333
3.2;0.54654;0.727783675;0.72727;0.42135
3.3;0.559616666666667;0.758212858423333;0.75;0.433266666666667
3.4;0.57252;0.78834579244;0.77273;0.444706666666667
3.5;0.58526;0.81873246712;0.79546;0.456003333333333
3.6;0.59784;0.850573936743333;0.818183333333333;0.467813333333333
3.7;0.61026;0.883019086766667;0.84091;0.479663333333333
3.8;0.62253;0.916101318326667;0.863636666666667;0.491566666666667
3.9;0.63465;0.949621971486667;0.886363333333333;0.503413333333333
4;0.64663;0.984007055676667;0.90909;0.515433333333333
4.1;0.65846;1.01896500301;0.93182;0.527463333333333
4.2;0.67016;1.05488309032667;0.95455;0.539706666666667
4.3;0.68172;1.09109855369;0.977273333333333;0.55182
4.4;0.69315;1.12868609444667;1;0.564343333333333
4.5;0.704446666666667;1.16682061173333;1.02272666666667;0.576856666666667
4.6;0.71562;1.20560560913;1.04545333333333;0.58941
4.7;0.72667;1.24522204093333;1.06818333333333;0.602083333333333
4.8;0.7376;1.2856801785;1.09091;0.61489
4.9;0.74841;1.32677683827667;1.11364;0.627723333333333
5;0.759106666666666;1.36896110680667;1.13636666666667;0.640793333333333
5.1;0.76969;1.41150567309;1.15909;0.65375
5.2;0.78016;1.45489569009333;1.18182;0.666826666666667
5.3;0.79052;1.49987266960667;1.20455;0.680353333333333
5.4;0.80078;1.54469267446333;1.22727;0.693533333333333
5.5;0.81093;1.59095875100333;1.25000333333333;0.707093333333333
5.6;0.82098;1.63836534499;1.27272666666667;0.72088
5.7;0.83093;1.68682977940667;1.29545;0.73486
5.8;0.84078;1.73531952736667;1.31818333333333;0.74857
5.9;0.85054;1.78606868208667;1.34091;0.76298
6;0.8602;1.83674593347333;1.36364;0.777083333333333
6.1;0.86977;1.88788415982333;1.38636666666667;0.791113333333333
6.2;0.87925;1.94066211852333;1.40909;0.805556666666667
6.3;0.88864;1.99407189564;1.43182;0.81999
6.4;0.89794;2.04918803468333;1.45454333333333;0.834853333333333
6.5;0.90716;2.10507723608667;1.47727333333333;0.849753333333333
6.6;0.91629;2.16134015387667;1.5;0.864536666666667
6.7;0.92534;2.21866729212;1.52273;0.87947
6.8;0.93431;2.27668723860667;1.54545333333333;0.894413333333333
6.9;0.9432;2.33566056699;1.56818;0.90946
7;0.95201;2.39646800732;1.59091;0.924956666666667
7.1;0.96074;2.45740633266667;1.61363333333333;0.940226666666667
7.2;0.9694;2.52002210198667;1.63637;0.95587
7.3;0.97798;2.58306170482667;1.65909;0.971406666666667
7.4;0.986493333333333;2.64742607884;1.68182;0.987176666666667
7.5;0.994933333333333;2.71241294367667;1.70454666666667;1.00291
7.6;1.0033;2.77820749401333;1.72727333333333;1.01867333333333
7.7;1.0116;2.84622264112333;1.75;1.03499
7.8;1.01983;2.91437411430667;1.77273;1.05108666666667
7.9;1.02799333333333;2.98374192589;1.79545333333333;1.06735666666667
8;1.03609;3.05294455131;1.81818333333333;1.0833
8.1;1.04412333333333;3.12353334829667;1.84091;1.09948333333333
8.2;1.05209;3.19638116597;1.86363666666667;1.11619666666667
8.3;1.06;3.26951929131333;1.88636333333333;1.13274666666667
8.4;1.06784;3.34401080480667;1.90909;1.14950333333333
8.5;1.07562;3.41904875981333;1.93182;1.16618666666667
8.6;1.08334333333333;3.49449025587667;1.95455;1.18275
8.7;1.09101;3.57270694190333;1.97727333333333;1.19999333333333
8.8;1.09861;3.65041670286;2.00000333333333;1.21680666666667
8.9;1.10616;3.73075694757333;2.02272666666667;1.23423333333333
9;1.11365;3.81166248040667;2.04545333333333;1.25158666666667
9.1;1.12108666666667;3.89248494826333;2.06818;1.26866333333333
9.2;1.12847;3.97463538656333;2.09091;1.28591
9.3;1.13579;4.05936698687;2.11363666666667;1.30374
9.4;1.14306333333333;4.14368506024667;2.13636333333333;1.32117666666667
9.5;1.15028333333333;4.22910471308667;2.15909;1.33870666666667
9.6;1.15745333333333;4.31664073307667;2.18182333333333;1.35665666666667
9.7;1.16457;4.40434479532;2.20455;1.37440666666667
9.8;1.17164;4.49273535632333;2.22727;1.39211666666667
9.9;1.17865333333333;4.58273231418667;2.25;1.41007333333333
10;1.18562;4.67473352873;2.27273;1.42839333333333
10.1;1.19254333333333;4.76558044465;2.29545333333333;1.44610666666667
10.2;1.19942;4.85837153234333;2.31818333333333;1.46416666666667
10.3;1.20624333333333;4.95413110443;2.34091333333333;1.48286666666667
10.4;1.21302;5.04832086802667;2.36364;1.50085333333333
10.5;1.21976;5.14421287863667;2.38636333333333;1.51909666666667
10.6;1.22644333333333;5.24058852169;2.40909;1.53724
10.7;1.23309;5.34008311331667;2.43181666666667;1.55605333333333
10.8;1.23969;5.43898666570333;2.45455;1.57444333333333
10.9;1.24625;5.53968996042;2.47727333333333;1.59311333333333
11;1.25276;5.63972427010667;2.5;1.61135
11.1;1.25923666666667;5.74358573789667;2.52273;1.63043666666667
11.2;1.26566666666667;5.84589519010333;2.54545333333333;1.64884333333333
11.3;1.27205666666667;5.95151317271;2.56818;1.66794
11.4;1.27840666666667;6.05541125433;2.59091;1.68632
11.5;1.28471666666667;6.1627557464;2.61363666666667;1.70541666666667
11.6;1.29098666666667;6.26968518678;2.63636666666667;1.72416
11.7;1.29721666666667;6.37958519838;2.65909;1.74348666666667
11.8;1.30341;6.48975487834667;2.68181666666667;1.76264666666667
11.9;1.30956;6.59953802690333;2.70454333333333;1.78147
12;1.31568;6.71241431142;2.72727;1.80089
12.1;1.32176;6.82452673749333;2.75;1.81987333333333
12.2;1.3278;6.93853741103;2.77273;1.83912666666667
12.3;1.33381;7.05352614426333;2.79546;1.85841333333333
12.4;1.33977333333333;7.16976823771667;2.81818333333333;1.87779666666667
12.5;1.34571;7.28637566082333;2.84090666666667;1.89704333333333
12.6;1.35161;7.40374361285333;2.86363666666667;1.91626333333333
12.7;1.35747;7.52336862603;2.88636666666667;1.93583666666667
12.8;1.36330666666667;7.64351680579667;2.90909333333333;1.95531666666667
12.9;1.3691;7.76472257769333;2.93182;1.97484
13;1.37487;7.88681485780667;2.95454666666667;1.99436333333333
13.1;1.3806;8.00855752438;2.97727;2.01358
13.2;1.38629;8.1328612829;2.99999666666667;2.03321333333333
13.3;1.39196;8.25854193077333;3.02272666666667;2.05297
13.4;1.39759;8.38615425519333;3.04545666666667;2.07298
13.5;1.4032;8.51277599353667;3.06818666666667;2.09252
13.6;1.40877;8.64093046631333;3.09091;2.11222666666667
13.7;1.41431;8.77147758187667;3.11364;2.13229
13.8;1.41982;8.90257350145333;3.13636;2.15227
13.9;1.4253;9.03407389519333;3.15909;2.17212666666667
14;1.43075;9.16671646124666;3.18182;2.19204
14.1;1.43617;9.29958955259;3.20455;2.21179333333333
14.2;1.44156;9.43490458949;3.22727;2.23191
14.3;1.44692;9.57069607400333;3.25;2.25193
14.4;1.45225;9.70737028110333;3.27272666666667;2.27194
14.5;1.45756;9.84483881444667;3.29545333333333;2.29192333333333
14.6;1.46283;9.98421237566;3.31818;2.31213
14.7;1.46808;10.1231877658133;3.34091;2.33204333333333
14.8;1.47331;10.26441428248;3.36364;2.35226
14.9;1.4785;10.40549447895;3.38636666666667;2.37223666666667
15;1.48367;10.54714203909;3.40909;2.39213666666667
15.1;1.48881;10.6917700662233;3.43181666666667;2.4125
15.2;1.49392333333333;10.8360097510933;3.45454666666667;2.43257666666667
15.3;1.49901;10.98171878167;3.47727333333333;2.45277
15.4;1.50408;11.1282131275933;3.5;2.47293333333333
15.5;1.50912;11.27595798039;3.52273;2.49317666666667
15.6;1.51413;11.4234706173133;3.54545333333333;2.51316333333333
15.7;1.51911666666667;11.57318757714;3.56818;2.53343333333333
15.8;1.52408;11.7242556004067;3.59091;2.55379666666667
15.9;1.52902;11.8762164685533;3.61364;2.57415666666667
16;1.53393;12.0283724972533;3.63637;2.59435333333333
16.1;1.53882;12.18054302231;3.65909333333333;2.61436
16.2;1.54369;12.3350320381867;3.68182;2.63466666666667
16.3;1.54853;12.4909743696467;3.70454666666667;2.65508666666667
16.4;1.55335;12.64875874535;3.72727333333333;2.6757
16.5;1.55814333333333;12.80600555071;3.75;2.696
16.6;1.56292;12.9643359661033;3.77272333333333;2.71633666666667
16.7;1.56767;13.1232641416;3.79546;2.73660333333333
16.8;1.5724;13.2847734927267;3.81818333333333;2.75721666666667
16.9;1.5771;13.4459400055733;3.84091;2.77756333333333
17;1.58179;13.60813989906;3.86363666666667;2.79793666666667
17.1;1.58645;13.76920115738;3.88636333333333;2.81788333333333
17.2;1.59109;13.9345987419867;3.90909;2.83853
17.3;1.59571;14.1004802573033;3.93182;2.85908
17.4;1.60031;14.24599416344;3.95455;2.875335
17.5;1.60488;14.39898436867;3.97727;2.89295
17.6;1.60944;14.56528168517;4;2.91306
17.7;1.61397;14.73503262395;4.02273;2.93367
17.8;1.61849;14.9018915484;4.04546;2.95353
17.9;1.62298;15.07040195077;4.06818;2.97353
18;1.62746;15.24170715226;4.09091;2.99391
18.1;1.63191;15.41029024738;4.11364;3.01357
18.2;1.63635;15.57960803665;4.13636;3.0332
18.3;1.64076;15.75260281042;4.1591;3.05336
18.4;1.64516;15.92642974293;4.18182;3.07352
18.5;1.64953;16.09504089861;4.20455;3.09249
18.6;1.65389;16.26613700634;4.22727;3.11178
18.7;1.65823;16.44492322344;4.25;3.13237
18.8;1.66255;16.61701601063;4.27273;3.1515
18.9;1.66685;16.79318387965;4.29546;3.17124
19;1.67113;16.97221242283;4.31819;3.19135
19.1;1.6754;17.14316353395;4.34091;3.20978
19.2;1.67964;17.32070564954;4.36364;3.22928
19.3;1.68387;17.49738669417;4.38636;3.24846
19.4;1.68808;17.67839876828;4.40909;3.26828
19.5;1.69227;17.85633544378;4.43182;3.28736
19.6;1.69645;18.03028070571;4.45455;3.30555
19.7;1.70061;18.20612961054;4.47728;3.32394
19.8;1.70475;18.38051955687;4.5;3.34191
19.9;1.70887;18.55466671482;4.52273;3.35969
20;1.71298;18.72878859372;4.54545;3.37732
20.1;1.71707;18.90144001715;4.56818;3.39454
20.2;1.72114;19.07474275604;4.59091;3.41174
20.3;1.7252;19.23867794574;4.61364;3.42713
20.4;1.72924;19.4079252655;4.63637;3.44334
20.5;1.73326;19.57382298213;4.65909;3.45883
20.6;1.73727;19.73921970807;4.68182;3.4741
20.7;1.74126;19.90515548447;4.70455;3.48935
20.8;1.74524;20.07733242356;4.72728;3.50556
20.9;1.7492;20.25109771777;4.75;3.52193
21;1.75315;20.42146587894;4.77273;3.53758
21.1;1.75707;20.59581009917;4.79546;3.55379
21.2;1.76099;20.77332230422;4.81818;3.57041
21.3;1.76489;20.95007196402;4.84091;3.58678
21.4;1.76877;21.13865226396;4.86364;3.60504
21.5;1.77264;21.32397654054;4.88637;3.6226
21.6;1.77649;21.51574955506;4.9091;3.64112
21.7;1.78033;21.71303920627;4.93182;3.66043
21.8;1.78415;21.90893533311;4.95454;3.67936
21.9;1.78796;22.10693757665;4.97727;3.6985
22;1.79176;22.30765335116;5;3.71794
22.1;1.79554;22.50378841354;5.02273;3.73648
22.2;1.79931;22.6990848411;5.04546;3.75473
22.3;1.80306;22.8995462408;5.06818;3.77371